Workbook

Sheet 사용방법
A1: 서울 무주택 진입 – 5안 시나리오 × 타깃 단지별 취득·보유·양도 3단계 시뮬레이션
A3: 작성일 | B3: 2026-10-20 (가격·규제는 2026-10월 검색 기준)
A4: 전제 | B4: 지방 2주택을 처분해 서울에서 무주택자로 진입. 자기자본 12·14·16억(세후 가용 현금으로 가정, 입력 시트에서 변경). 실거주 + 장기보유(1세대1주택) 구조.
A5: 셀 색 규칙 | B5: 파란 글씨 = 입력값(변경 가능, 노란 배경 = 핵심 입력) / 검정 = 수식 / 초록 = 다른 시트에서 가져온 값
A6: 바꿔 볼 곳 | B6: ① '입력' 시트: 자기자본, 금리, 상승률, 전세가율 등 / ② '단지' 시트 F열: 매매가(억). 12번 행은 직접 입력하는 예시 행입니다.
A7: 시트 구성 | B7: 안별요약(5안 최적) → 안별비교 → 요약 → 입력 → 세율표 → 단지(매수 단계: 대출·취득세·필요 자기자본) → 보유세_스케줄(보유 단계) → 시뮬레이션(양도 단계·손익) → 요약 → 최대매수가능액
A8: 단위 | B8: 금액은 억 원(보유세 1년차·월 원리금은 만원). 수익률은 투자금 대비 10년 누적(연환산은 단순 계산).
A9: 데이터 한계 | B9: 단지 가격은 뉴스·KB시세·시세사이트 기반 참고값이며 일부는 추정입니다. 계약 전 국토부 실거래가 공개시스템과 네이버부동산 중층 매물로 교차검증하세요(단지 시트의 '신뢰도' 열 참고).
A10: 모델 단순화 | B10: ① 종부세는 재산세 중복분 공제·고령자/장기보유 세액공제를 반영하지 않음(보수적) ② 공시가 현실화율 69%·공정시장가액비율 60% 고정 ③ 2026.8월 세제개편안(종부세·장특공 한도·중과 완화)은 국회 통과 미확인으로 미반영 ④ 지방 2주택 처분 양도세와 처분 일정은 별도 검토 대상 ⑤ 실거주로 절감되는 주거비는 미반영.
A11: 면책 | B11: 세무사 확정 계산을 대체하지 않는 의사결정 참고용 모델입니다.
A12: 5안 정의 | B12: 1안 표준형 = 대출 한도 최대(LTV 40%·구간 한도) / 2안 절충형 = 한도의 50%만 대출 / 3안 무대출형 = 자기자금 100% / 4안 임대차 승계 후 입주 = 세입자 있는 주택 승계 매수 → 임대 종료(기본 2년) 후 입주, 전세금 반환은 대출+자기자금 (법적 조건부, 공식 확인 필요) / 5안 매수 보류 = 전세 거주 + 자본 예금 운용(기준선). 선대출 후전세는 토허제(4개월 내 입주·2년 실거주)로 불가라 제외했습니다.
A13: 우위 지표 | B13: '전세 대비 우위' = 세후 순이익 − 투자금×예금대안수익률 + 전세가×거주기간 예금수익률. 같은 집을 전세로 빌려 살며 자본을 예금에 둔 경우를 0으로 둔 10년 순자산 차이(억 원)입니다. 5안이 항상 0(기준선)입니다.
A14: 핵심 원리 | B14: 대출 금리(기본 4.0%)가 잔여자금의 세후 운용수익률(기본 예금 3.0% → 세후 2.54%)보다 높으면, 시세 상승률과 무관하게 대출을 줄일수록 순자산이 늘어납니다. 잔여자금을 세후 4% 이상으로 굴릴 수 있다면 입력 시트의 '예금금리'를 올려 결과가 바뀌는지 확인하세요.
A15: 사용 순서 | B15: ① 입력 시트에서 자기자본·금리 확인 → ② 단지 시트 F열 가격 갱신 → ③ 안별요약에서 상승률·매도시점 선택 → ④ 안별비교에서 전체 행 확인.

Sheet 안별요약
A1: 5안 요약 – 자기자본별 최적 단지와 안
A2: 상승률 시나리오(1=보수 2=기준 3=낙관) | C2: 2 | E2: 상승률 | F2: =CHOOSE(SelS2,GrowLo,GrowMid,GrowHi) -> 0.04
A3: 매도 시점(5 또는 10년) | C3: 10
A4: ※ 각 안에서 해당 자기자본으로 가능한 단지 중 '전세 대비 우위'가 가장 큰 단지를 고릅니다. 가능한 단지가 없으면 '해당 없음'. 5안은 기준선(우위 0)입니다.
A6: ="자기자본 "&TEXT(CapA,"0")&"억 ("&"A)" -> 자기자본 12억 (A)
A7: 안 | B7: 최고 단지 | C7: 매수가 | D7: 대출 | E7: 투자금(피크) | F7: ① 취득세 | G7: ② 보유세 누계 | H7: ③ 양도세 | I7: 세금 합계 | J7: 세후 순이익 | K7: 전세 대비 우위 | L7: 월 원리금(만원) | M7: 필요 연소득 | N7: (행) | O7: (우위값)
A8: 1안 표준형(대출 최대) | B8: =IF(N8="","해당 없음(자본 부족)",INDEX(X_name,N8)) -> e편한세상 문래 에듀플라츠 84.99㎡ | C8: =IF(N8="","-",INDEX(X_P,N8)) -> 14.9 | D8: =IF(N8="","-",INDEX(X_L,N8)) -> 5.96 | E8: =IF(N8="","-",INDEX(X_inv,N8)) -> 9.55004 | F8: =IF(N8="","-",INDEX(X_acq,N8)) -> 0.4917 | G8: =IF(N8="","-",INDEX(X_ptax,N8)) -> 0.41157422 | H8: =IF(N8="","-",INDEX(X_ctax,N8)) -> 0.083521738 | I8: =IF(N8="","-",INDEX(X_tt,N8)) -> 0.98679595 | J8: =IF(N8="","-",INDEX(X_net,N8)) -> 3.7306773 | K8: =IF(N8="","-",INDEX(X_adv,N8)) -> 3.2173876 | L8: =IF(N8="","-",INDEX(X_pay,N8)) -> 284.53952 | M8: =IF(N8="","-",INDEX(X_inc,N8)) -> 1.1895609 | N8: =IF(O8<=-998,"",MATCH(1&"|"&SelS2&"|"&SelN2&"|"&TEXT(O8,"0.00000"),X_kA,0)) -> 34 | O8: =_xlfn.MAXIFS(X_aA,X_ak,1,X_sc,SelS2,X_N,SelN2) -> 3.2173876
A9: 2안 절충형(대출 50%) | B9: =IF(N9="","해당 없음(자본 부족)",INDEX(X_name,N9)) -> 문래건영아파트 84㎡ | C9: =IF(N9="","-",INDEX(X_P,N9)) -> 13.9 | D9: =IF(N9="","-",INDEX(X_L,N9)) -> 2.78 | E9: =IF(N9="","-",INDEX(X_inv,N9)) -> 11.69044 | F9: =IF(N9="","-",INDEX(X_acq,N9)) -> 0.4587 | G9: =IF(N9="","-",INDEX(X_ptax,N9)) -> 0.36548147 | H9: =IF(N9="","-",INDEX(X_ctax,N9)) -> 0.063801789 | I9: =IF(N9="","-",INDEX(X_tt,N9)) -> 0.88798326 | J9: =IF(N9="","-",INDEX(X_net,N9)) -> 4.5143903 | K9: =IF(N9="","-",INDEX(X_adv,N9)) -> 3.2433171 | L9: =IF(N9="","-",INDEX(X_pay,N9)) -> 132.72145 | M9: =IF(N9="","-",INDEX(X_inc,N9)) -> 0.55486228 | N9: =IF(O9<=-998,"",MATCH(2&"|"&SelS2&"|"&SelN2&"|"&TEXT(O9,"0.00000"),X_kA,0)) -> 10 | O9: =_xlfn.MAXIFS(X_aA,X_ak,2,X_sc,SelS2,X_N,SelN2) -> 3.2433171
A10: 3안 무대출형 | B10: =IF(N10="","해당 없음(자본 부족)",INDEX(X_name,N10)) -> 해당 없음(자본 부족) | C10: =IF(N10="","-",INDEX(X_P,N10)) -> - | D10: =IF(N10="","-",INDEX(X_L,N10)) -> - | E10: =IF(N10="","-",INDEX(X_inv,N10)) -> - | F10: =IF(N10="","-",INDEX(X_acq,N10)) -> - | G10: =IF(N10="","-",INDEX(X_ptax,N10)) -> - | H10: =IF(N10="","-",INDEX(X_ctax,N10)) -> - | I10: =IF(N10="","-",INDEX(X_tt,N10)) -> - | J10: =IF(N10="","-",INDEX(X_net,N10)) -> - | K10: =IF(N10="","-",INDEX(X_adv,N10)) -> - | L10: =IF(N10="","-",INDEX(X_pay,N10)) -> - | M10: =IF(N10="","-",INDEX(X_inc,N10)) -> - | N10: =IF(O10<=-998,"",MATCH(3&"|"&SelS2&"|"&SelN2&"|"&TEXT(O10,"0.00000"),X_kA,0)) | O10: =_xlfn.MAXIFS(X_aA,X_ak,3,X_sc,SelS2,X_N,SelN2) -> -999
A11: 4안 임대차 승계 후 입주 | B11: =IF(N11="","해당 없음(자본 부족)",INDEX(X_name,N11)) -> e편한세상 문래 에듀플라츠 84.99㎡ | C11: =IF(N11="","-",INDEX(X_P,N11)) -> 14.9 | D11: =IF(N11="","-",INDEX(X_L,N11)) -> 5.96 | E11: =IF(N11="","-",INDEX(X_inv,N11)) -> 9.55004 | F11: =IF(N11="","-",INDEX(X_acq,N11)) -> 0.4917 | G11: =IF(N11="","-",INDEX(X_ptax,N11)) -> 0.41157422 | H11: =IF(N11="","-",INDEX(X_ctax,N11)) -> 0.14491443 | I11: =IF(N11="","-",INDEX(X_tt,N11)) -> 1.0481887 | J11: =IF(N11="","-",INDEX(X_net,N11)) -> 4.0573671 | K11: =IF(N11="","-",INDEX(X_adv,N11)) -> 3.145798 | L11: =IF(N11="","-",INDEX(X_pay,N11)) -> 284.53952 | M11: =IF(N11="","-",INDEX(X_inc,N11)) -> 1.1895609 | N11: =IF(O11<=-998,"",MATCH(4&"|"&SelS2&"|"&SelN2&"|"&TEXT(O11,"0.00000"),X_kA,0)) -> 52 | O11: =_xlfn.MAXIFS(X_aA,X_ak,4,X_sc,SelS2,X_N,SelN2) -> 3.145798
A12: 5안 매수 보류(전세 거주) | B12: 전세 거주 + 예금 운용 (기준선) | C12: - | D12: - | E12: - | F12: - | G12: - | H12: - | I12: - | J12: - | K12: 0 | L12: - | M12: - | N12: 1 | O12: 0
A13: ★ 최적 (1~4안 중) | B13: =IF(MAX(O8:O11)<=-998,"해당 없음",INDEX(A8:A11,P13)&" – "&INDEX(B8:B11,P13)) -> 2안 절충형(대출 50%) – 문래건영아파트 84㎡ | C13: =IF(MAX(O8:O11)<=-998,"-",INDEX(C8:C11,P13)) -> 13.9 | D13: =IF(MAX(O8:O11)<=-998,"-",INDEX(D8:D11,P13)) -> 2.78 | E13: =IF(MAX(O8:O11)<=-998,"-",INDEX(E8:E11,P13)) -> 11.69044 | F13: =IF(MAX(O8:O11)<=-998,"-",INDEX(F8:F11,P13)) -> 0.4587 | G13: =IF(MAX(O8:O11)<=-998,"-",INDEX(G8:G11,P13)) -> 0.36548147 | H13: =IF(MAX(O8:O11)<=-998,"-",INDEX(H8:H11,P13)) -> 0.063801789 | I13: =IF(MAX(O8:O11)<=-998,"-",INDEX(I8:I11,P13)) -> 0.88798326 | J13: =IF(MAX(O8:O11)<=-998,"-",INDEX(J8:J11,P13)) -> 4.5143903 | K13: =IF(MAX(O8:O11)<=-998,"-",INDEX(K8:K11,P13)) -> 3.2433171 | L13: =IF(MAX(O8:O11)<=-998,"-",INDEX(L8:L11,P13)) -> 132.72145 | M13: =IF(MAX(O8:O11)<=-998,"-",INDEX(M8:M11,P13)) -> 0.55486228 | P13: =MATCH(MAX(O8:O11),O8:O11,0) -> 2
A16: ="자기자본 "&TEXT(CapB,"0")&"억 ("&"B)" -> 자기자본 14억 (B)
A17: 안 | B17: 최고 단지 | C17: 매수가 | D17: 대출 | E17: 투자금(피크) | F17: ① 취득세 | G17: ② 보유세 누계 | H17: ③ 양도세 | I17: 세금 합계 | J17: 세후 순이익 | K17: 전세 대비 우위 | L17: 월 원리금(만원) | M17: 필요 연소득 | N17: (행) | O17: (우위값)
A18: 1안 표준형(대출 최대) | B18: =IF(N18="","해당 없음(자본 부족)",INDEX(X_name,N18)) -> e편한세상 문래 에듀플라츠 84.99㎡ | C18: =IF(N18="","-",INDEX(X_P,N18)) -> 14.9 | D18: =IF(N18="","-",INDEX(X_L,N18)) -> 5.96 | E18: =IF(N18="","-",INDEX(X_inv,N18)) -> 9.55004 | F18: =IF(N18="","-",INDEX(X_acq,N18)) -> 0.4917 | G18: =IF(N18="","-",INDEX(X_ptax,N18)) -> 0.41157422 | H18: =IF(N18="","-",INDEX(X_ctax,N18)) -> 0.083521738 | I18: =IF(N18="","-",INDEX(X_tt,N18)) -> 0.98679595 | J18: =IF(N18="","-",INDEX(X_net,N18)) -> 3.7306773 | K18: =IF(N18="","-",INDEX(X_adv,N18)) -> 3.2173876 | L18: =IF(N18="","-",INDEX(X_pay,N18)) -> 284.53952 | M18: =IF(N18="","-",INDEX(X_inc,N18)) -> 1.1895609 | N18: =IF(O18<=-998,"",MATCH(1&"|"&SelS2&"|"&SelN2&"|"&TEXT(O18,"0.00000"),X_kB,0)) -> 34 | O18: =_xlfn.MAXIFS(X_aB,X_ak,1,X_sc,SelS2,X_N,SelN2) -> 3.2173876
A19: 2안 절충형(대출 50%) | B19: =IF(N19="","해당 없음(자본 부족)",INDEX(X_name,N19)) -> e편한세상 문래 에듀플라츠 84.99㎡ | C19: =IF(N19="","-",INDEX(X_P,N19)) -> 14.9 | D19: =IF(N19="","-",INDEX(X_L,N19)) -> 2.98 | E19: =IF(N19="","-",INDEX(X_inv,N19)) -> 12.53004 | F19: =IF(N19="","-",INDEX(X_acq,N19)) -> 0.4917 | G19: =IF(N19="","-",INDEX(X_ptax,N19)) -> 0.41157422 | H19: =IF(N19="","-",INDEX(X_ctax,N19)) -> 0.083521738 | I19: =IF(N19="","-",INDEX(X_tt,N19)) -> 0.98679595 | J19: =IF(N19="","-",INDEX(X_net,N19)) -> 4.8056764 | K19: =IF(N19="","-",INDEX(X_adv,N19)) -> 3.443569 | L19: =IF(N19="","-",INDEX(X_pay,N19)) -> 142.26976 | M19: =IF(N19="","-",INDEX(X_inc,N19)) -> 0.59478043 | N19: =IF(O19<=-998,"",MATCH(2&"|"&SelS2&"|"&SelN2&"|"&TEXT(O19,"0.00000"),X_kB,0)) -> 40 | O19: =_xlfn.MAXIFS(X_aB,X_ak,2,X_sc,SelS2,X_N,SelN2) -> 3.443569
A20: 3안 무대출형 | B20: =IF(N20="","해당 없음(자본 부족)",INDEX(X_name,N20)) -> 신길삼성래미안 84㎡ | C20: =IF(N20="","-",INDEX(X_P,N20)) -> 13 | D20: =IF(N20="","-",INDEX(X_L,N20)) -> 0 | E20: =IF(N20="","-",INDEX(X_inv,N20)) -> 13.5348 | F20: =IF(N20="","-",INDEX(X_acq,N20)) -> 0.429 | G20: =IF(N20="","-",INDEX(X_ptax,N20)) -> 0.3255508 | H20: =IF(N20="","-",INDEX(X_ctax,N20)) -> 0.05107982 | I20: =IF(N20="","-",INDEX(X_tt,N20)) -> 0.80563062 | J20: =IF(N20="","-",INDEX(X_net,N20)) -> 5.1835726 | K20: =IF(N20="","-",INDEX(X_adv,N20)) -> 3.2538511 | L20: =IF(N20="","-",INDEX(X_pay,N20)) -> 0 | M20: =IF(N20="","-",INDEX(X_inc,N20)) -> 0 | N20: =IF(O20<=-998,"",MATCH(3&"|"&SelS2&"|"&SelN2&"|"&TEXT(O20,"0.00000"),X_kB,0)) -> 106 | O20: =_xlfn.MAXIFS(X_aB,X_ak,3,X_sc,SelS2,X_N,SelN2) -> 3.2538511
A21: 4안 임대차 승계 후 입주 | B21: =IF(N21="","해당 없음(자본 부족)",INDEX(X_name,N21)) -> e편한세상 문래 에듀플라츠 84.99㎡ | C21: =IF(N21="","-",INDEX(X_P,N21)) -> 14.9 | D21: =IF(N21="","-",INDEX(X_L,N21)) -> 5.96 | E21: =IF(N21="","-",INDEX(X_inv,N21)) -> 9.55004 | F21: =IF(N21="","-",INDEX(X_acq,N21)) -> 0.4917 | G21: =IF(N21="","-",INDEX(X_ptax,N21)) -> 0.41157422 | H21: =IF(N21="","-",INDEX(X_ctax,N21)) -> 0.14491443 | I21: =IF(N21="","-",INDEX(X_tt,N21)) -> 1.0481887 | J21: =IF(N21="","-",INDEX(X_net,N21)) -> 4.0573671 | K21: =IF(N21="","-",INDEX(X_adv,N21)) -> 3.145798 | L21: =IF(N21="","-",INDEX(X_pay,N21)) -> 284.53952 | M21: =IF(N21="","-",INDEX(X_inc,N21)) -> 1.1895609 | N21: =IF(O21<=-998,"",MATCH(4&"|"&SelS2&"|"&SelN2&"|"&TEXT(O21,"0.00000"),X_kB,0)) -> 52 | O21: =_xlfn.MAXIFS(X_aB,X_ak,4,X_sc,SelS2,X_N,SelN2) -> 3.145798
A22: 5안 매수 보류(전세 거주) | B22: 전세 거주 + 예금 운용 (기준선) | C22: - | D22: - | E22: - | F22: - | G22: - | H22: - | I22: - | J22: - | K22: 0 | L22: - | M22: - | N22: 1 | O22: 0
A23: ★ 최적 (1~4안 중) | B23: =IF(MAX(O18:O21)<=-998,"해당 없음",INDEX(A18:A21,P23)&" – "&INDEX(B18:B21,P23)) -> 2안 절충형(대출 50%) – e편한세상 문래 에듀플라츠 84.99㎡ | C23: =IF(MAX(O18:O21)<=-998,"-",INDEX(C18:C21,P23)) -> 14.9 | D23: =IF(MAX(O18:O21)<=-998,"-",INDEX(D18:D21,P23)) -> 2.98 | E23: =IF(MAX(O18:O21)<=-998,"-",INDEX(E18:E21,P23)) -> 12.53004 | F23: =IF(MAX(O18:O21)<=-998,"-",INDEX(F18:F21,P23)) -> 0.4917 | G23: =IF(MAX(O18:O21)<=-998,"-",INDEX(G18:G21,P23)) -> 0.41157422 | H23: =IF(MAX(O18:O21)<=-998,"-",INDEX(H18:H21,P23)) -> 0.083521738 | I23: =IF(MAX(O18:O21)<=-998,"-",INDEX(I18:I21,P23)) -> 0.98679595 | J23: =IF(MAX(O18:O21)<=-998,"-",INDEX(J18:J21,P23)) -> 4.8056764 | K23: =IF(MAX(O18:O21)<=-998,"-",INDEX(K18:K21,P23)) -> 3.443569 | L23: =IF(MAX(O18:O21)<=-998,"-",INDEX(L18:L21,P23)) -> 142.26976 | M23: =IF(MAX(O18:O21)<=-998,"-",INDEX(M18:M21,P23)) -> 0.59478043 | P23: =MATCH(MAX(O18:O21),O18:O21,0) -> 2
A26: ="자기자본 "&TEXT(CapC,"0")&"억 ("&"C)" -> 자기자본 16억 (C)
A27: 안 | B27: 최고 단지 | C27: 매수가 | D27: 대출 | E27: 투자금(피크) | F27: ① 취득세 | G27: ② 보유세 누계 | H27: ③ 양도세 | I27: 세금 합계 | J27: 세후 순이익 | K27: 전세 대비 우위 | L27: 월 원리금(만원) | M27: 필요 연소득 | N27: (행) | O27: (우위값)
A28: 1안 표준형(대출 최대) | B28: =IF(N28="","해당 없음(자본 부족)",INDEX(X_name,N28)) -> 신길 래미안에스티움 84㎡ | C28: =IF(N28="","-",INDEX(X_P,N28)) -> 18.8 | D28: =IF(N28="","-",INDEX(X_L,N28)) -> 4 | E28: =IF(N28="","-",INDEX(X_inv,N28)) -> 15.58516 | F28: =IF(N28="","-",INDEX(X_acq,N28)) -> 0.6204 | G28: =IF(N28="","-",INDEX(X_ptax,N28)) -> 0.63573301 | H28: =IF(N28="","-",INDEX(X_ctax,N28)) -> 0.1721857 | I28: =IF(N28="","-",INDEX(X_tt,N28)) -> 1.4283187 | J28: =IF(N28="","-",INDEX(X_net,N28)) -> 5.7782819 | K28: =IF(N28="","-",INDEX(X_adv,N28)) -> 4.1236115 | L28: =IF(N28="","-",INDEX(X_pay,N28)) -> 190.96612 | M28: =IF(N28="","-",INDEX(X_inc,N28)) -> 0.79836299 | N28: =IF(O28<=-998,"",MATCH(1&"|"&SelS2&"|"&SelN2&"|"&TEXT(O28,"0.00000"),X_kC,0)) -> 124 | O28: =_xlfn.MAXIFS(X_aC,X_ak,1,X_sc,SelS2,X_N,SelN2) -> 4.1236115
A29: 2안 절충형(대출 50%) | B29: =IF(N29="","해당 없음(자본 부족)",INDEX(X_name,N29)) -> e편한세상 문래 에듀플라츠 84.99㎡ | C29: =IF(N29="","-",INDEX(X_P,N29)) -> 14.9 | D29: =IF(N29="","-",INDEX(X_L,N29)) -> 2.98 | E29: =IF(N29="","-",INDEX(X_inv,N29)) -> 12.53004 | F29: =IF(N29="","-",INDEX(X_acq,N29)) -> 0.4917 | G29: =IF(N29="","-",INDEX(X_ptax,N29)) -> 0.41157422 | H29: =IF(N29="","-",INDEX(X_ctax,N29)) -> 0.083521738 | I29: =IF(N29="","-",INDEX(X_tt,N29)) -> 0.98679595 | J29: =IF(N29="","-",INDEX(X_net,N29)) -> 4.8056764 | K29: =IF(N29="","-",INDEX(X_adv,N29)) -> 3.443569 | L29: =IF(N29="","-",INDEX(X_pay,N29)) -> 142.26976 | M29: =IF(N29="","-",INDEX(X_inc,N29)) -> 0.59478043 | N29: =IF(O29<=-998,"",MATCH(2&"|"&SelS2&"|"&SelN2&"|"&TEXT(O29,"0.00000"),X_kC,0)) -> 40 | O29: =_xlfn.MAXIFS(X_aC,X_ak,2,X_sc,SelS2,X_N,SelN2) -> 3.443569
A30: 3안 무대출형 | B30: =IF(N30="","해당 없음(자본 부족)",INDEX(X_name,N30)) -> e편한세상 문래 에듀플라츠 84.99㎡ | C30: =IF(N30="","-",INDEX(X_P,N30)) -> 14.9 | D30: =IF(N30="","-",INDEX(X_L,N30)) -> 0 | E30: =IF(N30="","-",INDEX(X_inv,N30)) -> 15.51004 | F30: =IF(N30="","-",INDEX(X_acq,N30)) -> 0.4917 | G30: =IF(N30="","-",INDEX(X_ptax,N30)) -> 0.41157422 | H30: =IF(N30="","-",INDEX(X_ctax,N30)) -> 0.083521738 | I30: =IF(N30="","-",INDEX(X_tt,N30)) -> 0.98679595 | J30: =IF(N30="","-",INDEX(X_net,N30)) -> 5.8806755 | K30: =IF(N30="","-",INDEX(X_adv,N30)) -> 3.6697504 | L30: =IF(N30="","-",INDEX(X_pay,N30)) -> 0 | M30: =IF(N30="","-",INDEX(X_inc,N30)) -> 0 | N30: =IF(O30<=-998,"",MATCH(3&"|"&SelS2&"|"&SelN2&"|"&TEXT(O30,"0.00000"),X_kC,0)) -> 46 | O30: =_xlfn.MAXIFS(X_aC,X_ak,3,X_sc,SelS2,X_N,SelN2) -> 3.6697504
A31: 4안 임대차 승계 후 입주 | B31: =IF(N31="","해당 없음(자본 부족)",INDEX(X_name,N31)) -> 신길 래미안에스티움 84㎡ | C31: =IF(N31="","-",INDEX(X_P,N31)) -> 18.8 | D31: =IF(N31="","-",INDEX(X_L,N31)) -> 4 | E31: =IF(N31="","-",INDEX(X_inv,N31)) -> 15.58516 | F31: =IF(N31="","-",INDEX(X_acq,N31)) -> 0.6204 | G31: =IF(N31="","-",INDEX(X_ptax,N31)) -> 0.63573301 | H31: =IF(N31="","-",INDEX(X_ctax,N31)) -> 0.31284598 | I31: =IF(N31="","-",INDEX(X_tt,N31)) -> 1.568979 | J31: =IF(N31="","-",INDEX(X_net,N31)) -> 5.8980796 | K31: =IF(N31="","-",INDEX(X_adv,N31)) -> 3.7408823 | L31: =IF(N31="","-",INDEX(X_pay,N31)) -> 190.96612 | M31: =IF(N31="","-",INDEX(X_inc,N31)) -> 0.79836299 | N31: =IF(O31<=-998,"",MATCH(4&"|"&SelS2&"|"&SelN2&"|"&TEXT(O31,"0.00000"),X_kC,0)) -> 142 | O31: =_xlfn.MAXIFS(X_aC,X_ak,4,X_sc,SelS2,X_N,SelN2) -> 3.7408823
A32: 5안 매수 보류(전세 거주) | B32: 전세 거주 + 예금 운용 (기준선) | C32: - | D32: - | E32: - | F32: - | G32: - | H32: - | I32: - | J32: - | K32: 0 | L32: - | M32: - | N32: 1 | O32: 0
A33: ★ 최적 (1~4안 중) | B33: =IF(MAX(O28:O31)<=-998,"해당 없음",INDEX(A28:A31,P33)&" – "&INDEX(B28:B31,P33)) -> 1안 표준형(대출 최대) – 신길 래미안에스티움 84㎡ | C33: =IF(MAX(O28:O31)<=-998,"-",INDEX(C28:C31,P33)) -> 18.8 | D33: =IF(MAX(O28:O31)<=-998,"-",INDEX(D28:D31,P33)) -> 4 | E33: =IF(MAX(O28:O31)<=-998,"-",INDEX(E28:E31,P33)) -> 15.58516 | F33: =IF(MAX(O28:O31)<=-998,"-",INDEX(F28:F31,P33)) -> 0.6204 | G33: =IF(MAX(O28:O31)<=-998,"-",INDEX(G28:G31,P33)) -> 0.63573301 | H33: =IF(MAX(O28:O31)<=-998,"-",INDEX(H28:H31,P33)) -> 0.1721857 | I33: =IF(MAX(O28:O31)<=-998,"-",INDEX(I28:I31,P33)) -> 1.4283187 | J33: =IF(MAX(O28:O31)<=-998,"-",INDEX(J28:J31,P33)) -> 5.7782819 | K33: =IF(MAX(O28:O31)<=-998,"-",INDEX(K28:K31,P33)) -> 4.1236115 | L33: =IF(MAX(O28:O31)<=-998,"-",INDEX(L28:L31,P33)) -> 190.96612 | M33: =IF(MAX(O28:O31)<=-998,"-",INDEX(M28:M31,P33)) -> 0.79836299 | P33: =MATCH(MAX(O28:O31),O28:O31,0) -> 1

Sheet 안별비교
A1: 5안 × 단지 × 상승률 × 매도시점 비교 (억 원)
A2: 전세 대비 우위 = 순이익 − 투자금×예금대안수익률 + 전세가×(거주기간 예금수익률). 같은 집을 전세로 빌려 살며 자본을 예금에 둔 경우(5안)를 0으로 둔 10년 순자산 차이입니다. 가능(A/B/C)=1이면 해당 자기자본으로 투자금 충당 가능.
A4: 단지번호 | B4: 단지 | C4: 안 | D4: 안 이름 | E4: 시나리오 | F4: 상승률 | G4: 매도(년) | H4: 매수가 | I4: 전세가 | J4: 대출 | K4: ① 취득세 등 | L4: 매수비용 | M4: 추가 자기자금(임대 종료 시) | N4: 투자금(피크) | O4: 임대 기간 | P4: 거주(년) | Q4: 매도가 | R4: 매도 중개 | S4: 대출이자 누계 | T4: ② 보유세 누계 | U4: 필요경비 | V4: 양도차익 | W4: 과세대상 차익 | X4: 장특공 공제율 | Y4: 과세표준 | Z4: ③ 양도세 | AA4: 세금 합계 | AB4: 세후 순이익 | AC4: 예금 대안수익 | AD4: 전세 대비 우위 | AE4: 월 원리금(만원) | AF4: 필요 연소득 | AG4: 가능 A | AH4: 가능 B | AI4: 가능 C | AJ4: 우위 A | AK4: 우위 B | AL4: 우위 C | AM4: 키 A | AN4: 키 B | AO4: 키 C
A5: 1 | B5: =INDEX(C_Name,A5) -> 문래건영아파트 84㎡ | C5: 1 | D5: =CHOOSE(C5,"1안 표준형(대출 최대)","2안 절충형(대출 50%)","3안 무대출형","4안 임대차 승계 후 입주","5안 매수 보류(전세 거주)") -> 1안 표준형(대출 최대) | E5: 1 | F5: =CHOOSE(E5,GrowLo,GrowMid,GrowHi) -> 0.02 | G5: 5 | H5: =INDEX(C_Price,A5) -> 13.9 | I5: =INDEX(C_Jeonse,A5) -> 7.228 | J5: =IF(C5=5,0,IF(C5=1,INDEX(C_Loan,A5),IF(C5=2,INDEX(C_Loan,A5)*LoanShare2,IF(C5=3,0,MIN(INDEX(C_Loan,A5),I5))))) -> 5.56 | K5: =IF(C5=5,0,INDEX(C_Acq,A5)) -> 0.4587 | L5: =IF(C5=5,0,INDEX(C_Fee,A5)) -> 0.11174 | M5: =IF(C5=4,MAX(0,I5-J5),0) -> 0 | N5: =IF(C5=5,I5,IF(C5=4,(H5-I5)+K5+L5+M5,H5-J5+K5+L5)) -> 8.91044 | O5: =IF(C5=4,RentYears,0) -> 0 | P5: =IF(C5=5,0,MAX(0,G5-O5-NonRes)) -> 5 | Q5: =IF(C5=5,0,H5*(1+F5)^G5) -> 15.346723 | R5: =IF(C5=5,0,Q5*LOOKUP(Q5,FeeLo,FeeR)*(1+VAT)) -> 0.11816977 | S5: =IF(J5>0,-CUMIPMT(Rm,LoanYears*12,J5,1,(G5-O5)*12,0),0) -> 1.0615392 | T5: =IF(C5=5,0,SUMIFS(Sch_Total,Sch_Idx,A5,Sch_Scen,E5,Sch_Year,"<="&G5)) -> 0.14787245 | U5: =K5+L5+R5 -> 0.68860977 | V5: =IF(C5=5,0,Q5-H5-U5) -> 0.7581134 | W5: =IF(C5=5,0,MAX(0,IF(P5>=2,IF(Q5>Exempt,V5*(Q5-Exempt)/Q5,0),V5))) -> 0.16532491 | X5: =IF(P5>=2,MIN(MaxDed,MIN(0.4,HoldRate*G5)+MIN(0.4,LiveRate*P5)),IF(G5>=3,MIN(0.3,0.02*G5),0)) -> 0.4 | Y5: =MAX(0,W5*(1-X5)-InitDed) -> 0.074194947 | Z5: =SUMPRODUCT((Y5>CLo)*(Y5-CLo)*CD)*(1+LocalTax) -> 0.0048968665 | AA5: =K5+T5+Z5 -> 0.61146932 | AB5: =IF(C5=5,0,(Q5-H5)-K5-L5-R5-S5-T5-Z5) -> -0.45619508 | AC5: =IF(C5=5,0,N5*((1+DepRate*(1-DepTax))^G5-1)) -> 1.1896062 | AD5: =IF(C5=5,0,AB5-AC5+I5*(((1+DepRate*(1-DepTax))^G5-1)-((1+DepRate*(1-DepTax))^O5-1))) -> -0.68081262 | AE5: =IF(J5>0,-PMT(Rm,LoanYears*12,J5)*10000,0) -> 265.4429 | AF5: =IF(J5>0,-PMT((Rate+Stress)/12,LoanYears*12,J5)*12/DSR,0) -> 1.1097246 | AG5: =IF(N5<=CapA,1,0) -> 1 | AH5: =IF(N5<=CapB,1,0) -> 1 | AI5: =IF(N5<=CapC,1,0) -> 1 | AJ5: =IF(AG5=1,AD5,-999) -> -0.68081262 | AK5: =IF(AH5=1,AD5,-999) -> -0.68081262 | AL5: =IF(AI5=1,AD5,-999) -> -0.68081262 | AM5: =C5&"|"&E5&"|"&G5&"|"&TEXT(AJ5,"0.00000") -> 1|1|5|-0.68081 | AN5: =C5&"|"&E5&"|"&G5&"|"&TEXT(AK5,"0.00000") -> 1|1|5|-0.68081 | AO5: =C5&"|"&E5&"|"&G5&"|"&TEXT(AL5,"0.00000") -> 1|1|5|-0.68081
A6: 1 | B6: =INDEX(C_Name,A6) -> 문래건영아파트 84㎡ | C6: 1 | D6: =CHOOSE(C6,"1안 표준형(대출 최대)","2안 절충형(대출 50%)","3안 무대출형","4안 임대차 승계 후 입주","5안 매수 보류(전세 거주)") -> 1안 표준형(대출 최대) | E6: 1 | F6: =CHOOSE(E6,GrowLo,GrowMid,GrowHi) -> 0.02 | G6: 10 | H6: =INDEX(C_Price,A6) -> 13.9 | I6: =INDEX(C_Jeonse,A6) -> 7.228 | J6: =IF(C6=5,0,IF(C6=1,INDEX(C_Loan,A6),IF(C6=2,INDEX(C_Loan,A6)*LoanShare2,IF(C6=3,0,MIN(INDEX(C_Loan,A6),I6))))) -> 5.56 | K6: =IF(C6=5,0,INDEX(C_Acq,A6)) -> 0.4587 | L6: =IF(C6=5,0,INDEX(C_Fee,A6)) -> 0.11174 | M6: =IF(C6=4,MAX(0,I6-J6),0) -> 0 | N6: =IF(C6=5,I6,IF(C6=4,(H6-I6)+K6+L6+M6,H6-J6+K6+L6)) -> 8.91044 | O6: =IF(C6=4,RentYears,0) -> 0 | P6: =IF(C6=5,0,MAX(0,G6-O6-NonRes)) -> 10 | Q6: =IF(C6=5,0,H6*(1+F6)^G6) -> 16.944022 | R6: =IF(C6=5,0,Q6*LOOKUP(Q6,FeeLo,FeeR)*(1+VAT)) -> 0.13046897 | S6: =IF(J6>0,-CUMIPMT(Rm,LoanYears*12,J6,1,(G6-O6)*12,0),0) -> 2.005703 | T6: =IF(C6=5,0,SUMIFS(Sch_Total,Sch_Idx,A6,Sch_Scen,E6,Sch_Year,"<="&G6)) -> 0.31506984 | U6: =K6+L6+R6 -> 0.70090897 | V6: =IF(C6=5,0,Q6-H6-U6) -> 2.3431135 | W6: =IF(C6=5,0,MAX(0,IF(P6>=2,IF(Q6>Exempt,V6*(Q6-Exempt)/Q6,0),V6))) -> 0.68368686 | X6: =IF(P6>=2,MIN(MaxDed,MIN(0.4,HoldRate*G6)+MIN(0.4,LiveRate*P6)),IF(G6>=3,MIN(0.3,0.02*G6),0)) -> 0.8 | Y6: =MAX(0,W6*(1-X6)-InitDed) -> 0.11173737 | Z6: =SUMPRODUCT((Y6>CLo)*(Y6-CLo)*CD)*(1+LocalTax) -> 0.0073746666 | AA6: =K6+T6+Z6 -> 0.78114451 | AB6: =IF(C6=5,0,(Q6-H6)-K6-L6-R6-S6-T6-Z6) -> 0.014965975 | AC6: =IF(C6=5,0,N6*((1+DepRate*(1-DepTax))^G6-1)) -> 2.5380332 | AD6: =IF(C6=5,0,AB6-AC6+I6*(((1+DepRate*(1-DepTax))^G6-1)-((1+DepRate*(1-DepTax))^O6-1))) -> -0.46425712 | AE6: =IF(J6>0,-PMT(Rm,LoanYears*12,J6)*10000,0) -> 265.4429 | AF6: =IF(J6>0,-PMT((Rate+Stress)/12,LoanYears*12,J6)*12/DSR,0) -> 1.1097246 | AG6: =IF(N6<=CapA,1,0) -> 1 | AH6: =IF(N6<=CapB,1,0) -> 1 | AI6: =IF(N6<=CapC,1,0) -> 1 | AJ6: =IF(AG6=1,AD6,-999) -> -0.46425712 | AK6: =IF(AH6=1,AD6,-999) -> -0.46425712 | AL6: =IF(AI6=1,AD6,-999) -> -0.46425712 | AM6: =C6&"|"&E6&"|"&G6&"|"&TEXT(AJ6,"0.00000") -> 1|1|10|-0.46426 | AN6: =C6&"|"&E6&"|"&G6&"|"&TEXT(AK6,"0.00000") -> 1|1|10|-0.46426 | AO6: =C6&"|"&E6&"|"&G6&"|"&TEXT(AL6,"0.00000") -> 1|1|10|-0.46426
A7: 1 | B7: =INDEX(C_Name,A7) -> 문래건영아파트 84㎡ | C7: 1 | D7: =CHOOSE(C7,"1안 표준형(대출 최대)","2안 절충형(대출 50%)","3안 무대출형","4안 임대차 승계 후 입주","5안 매수 보류(전세 거주)") -> 1안 표준형(대출 최대) | E7: 2 | F7: =CHOOSE(E7,GrowLo,GrowMid,GrowHi) -> 0.04 | G7: 5 | H7: =INDEX(C_Price,A7) -> 13.9 | I7: =INDEX(C_Jeonse,A7) -> 7.228 | J7: =IF(C7=5,0,IF(C7=1,INDEX(C_Loan,A7),IF(C7=2,INDEX(C_Loan,A7)*LoanShare2,IF(C7=3,0,MIN(INDEX(C_Loan,A7),I7))))) -> 5.56 | K7: =IF(C7=5,0,INDEX(C_Acq,A7)) -> 0.4587 | L7: =IF(C7=5,0,INDEX(C_Fee,A7)) -> 0.11174 | M7: =IF(C7=4,MAX(0,I7-J7),0) -> 0 | N7: =IF(C7=5,I7,IF(C7=4,(H7-I7)+K7+L7+M7,H7-J7+K7+L7)) -> 8.91044 | O7: =IF(C7=4,RentYears,0) -> 0 | P7: =IF(C7=5,0,MAX(0,G7-O7-NonRes)) -> 5 | Q7: =IF(C7=5,0,H7*(1+F7)^G7) -> 16.911475 | R7: =IF(C7=5,0,Q7*LOOKUP(Q7,FeeLo,FeeR)*(1+VAT)) -> 0.13021836 | S7: =IF(J7>0,-CUMIPMT(Rm,LoanYears*12,J7,1,(G7-O7)*12,0),0) -> 1.0615392 | T7: =IF(C7=5,0,SUMIFS(Sch_Total,Sch_Idx,A7,Sch_Scen,E7,Sch_Year,"<="&G7)) -> 0.15544637 | U7: =K7+L7+R7 -> 0.70065836 | V7: =IF(C7=5,0,Q7-H7-U7) -> 2.310817 | W7: =IF(C7=5,0,MAX(0,IF(P7>=2,IF(Q7>Exempt,V7*(Q7-Exempt)/Q7,0),V7))) -> 0.67111357 | X7: =IF(P7>=2,MIN(MaxDed,MIN(0.4,HoldRate*G7)+MIN(0.4,LiveRate*P7)),IF(G7>=3,MIN(0.3,0.02*G7),0)) -> 0.4 | Y7: =MAX(0,W7*(1-X7)-InitDed) -> 0.37766814 | Z7: =SUMPRODUCT((Y7>CLo)*(Y7-CLo)*CD)*(1+LocalTax) -> 0.048455244 | AA7: =K7+T7+Z7 -> 0.66260162 | AB7: =IF(C7=5,0,(Q7-H7)-K7-L7-R7-S7-T7-Z7) -> 1.0453762 | AC7: =IF(C7=5,0,N7*((1+DepRate*(1-DepTax))^G7-1)) -> 1.1896062 | AD7: =IF(C7=5,0,AB7-AC7+I7*(((1+DepRate*(1-DepTax))^G7-1)-((1+DepRate*(1-DepTax))^O7-1))) -> 0.82075867 | AE7: =IF(J7>0,-PMT(Rm,LoanYears*12,J7)*10000,0) -> 265.4429 | AF7: =IF(J7>0,-PMT((Rate+Stress)/12,LoanYears*12,J7)*12/DSR,0) -> 1.1097246 | AG7: =IF(N7<=CapA,1,0) -> 1 | AH7: =IF(N7<=CapB,1,0) -> 1 | AI7: =IF(N7<=CapC,1,0) -> 1 | AJ7: =IF(AG7=1,AD7,-999) -> 0.82075867 | AK7: =IF(AH7=1,AD7,-999) -> 0.82075867 | AL7: =IF(AI7=1,AD7,-999) -> 0.82075867 | AM7: =C7&"|"&E7&"|"&G7&"|"&TEXT(AJ7,"0.00000") -> 1|2|5|0.82076 | AN7: =C7&"|"&E7&"|"&G7&"|"&TEXT(AK7,"0.00000") -> 1|2|5|0.82076 | AO7: =C7&"|"&E7&"|"&G7&"|"&TEXT(AL7,"0.00000") -> 1|2|5|0.82076
A8: 1 | B8: =INDEX(C_Name,A8) -> 문래건영아파트 84㎡ | C8: 1 | D8: =CHOOSE(C8,"1안 표준형(대출 최대)","2안 절충형(대출 50%)","3안 무대출형","4안 임대차 승계 후 입주","5안 매수 보류(전세 거주)") -> 1안 표준형(대출 최대) | E8: 2 | F8: =CHOOSE(E8,GrowLo,GrowMid,GrowHi) -> 0.04 | G8: 10 | H8: =INDEX(C_Price,A8) -> 13.9 | I8: =INDEX(C_Jeonse,A8) -> 7.228 | J8: =IF(C8=5,0,IF(C8=1,INDEX(C_Loan,A8),IF(C8=2,INDEX(C_Loan,A8)*LoanShare2,IF(C8=3,0,MIN(INDEX(C_Loan,A8),I8))))) -> 5.56 | K8: =IF(C8=5,0,INDEX(C_Acq,A8)) -> 0.4587 | L8: =IF(C8=5,0,INDEX(C_Fee,A8)) -> 0.11174 | M8: =IF(C8=4,MAX(0,I8-J8),0) -> 0 | N8: =IF(C8=5,I8,IF(C8=4,(H8-I8)+K8+L8+M8,H8-J8+K8+L8)) -> 8.91044 | O8: =IF(C8=4,RentYears,0) -> 0 | P8: =IF(C8=5,0,MAX(0,G8-O8-NonRes)) -> 10 | Q8: =IF(C8=5,0,H8*(1+F8)^G8) -> 20.575396 | R8: =IF(C8=5,0,Q8*LOOKUP(Q8,FeeLo,FeeR)*(1+VAT)) -> 0.15843055 | S8: =IF(J8>0,-CUMIPMT(Rm,LoanYears*12,J8,1,(G8-O8)*12,0),0) -> 2.005703 | T8: =IF(C8=5,0,SUMIFS(Sch_Total,Sch_Idx,A8,Sch_Scen,E8,Sch_Year,"<="&G8)) -> 0.36548147 | U8: =K8+L8+R8 -> 0.72887055 | V8: =IF(C8=5,0,Q8-H8-U8) -> 5.946525 | W8: =IF(C8=5,0,MAX(0,IF(P8>=2,IF(Q8>Exempt,V8*(Q8-Exempt)/Q8,0),V8))) -> 2.4783876 | X8: =IF(P8>=2,MIN(MaxDed,MIN(0.4,HoldRate*G8)+MIN(0.4,LiveRate*P8)),IF(G8>=3,MIN(0.3,0.02*G8),0)) -> 0.8 | Y8: =MAX(0,W8*(1-X8)-InitDed) -> 0.47067751 | Z8: =SUMPRODUCT((Y8>CLo)*(Y8-CLo)*CD)*(1+LocalTax) -> 0.063801789 | AA8: =K8+T8+Z8 -> 0.88798326 | AB8: =IF(C8=5,0,(Q8-H8)-K8-L8-R8-S8-T8-Z8) -> 3.5115388 | AC8: =IF(C8=5,0,N8*((1+DepRate*(1-DepTax))^G8-1)) -> 2.5380332 | AD8: =IF(C8=5,0,AB8-AC8+I8*(((1+DepRate*(1-DepTax))^G8-1)-((1+DepRate*(1-DepTax))^O8-1))) -> 3.0323157 | AE8: =IF(J8>0,-PMT(Rm,LoanYears*12,J8)*10000,0) -> 265.4429 | AF8: =IF(J8>0,-PMT((Rate+Stress)/12,LoanYears*12,J8)*12/DSR,0) -> 1.1097246 | AG8: =IF(N8<=CapA,1,0) -> 1 | AH8: =IF(N8<=CapB,1,0) -> 1 | AI8: =IF(N8<=CapC,1,0) -> 1 | AJ8: =IF(AG8=1,AD8,-999) -> 3.0323157 | AK8: =IF(AH8=1,AD8,-999) -> 3.0323157 | AL8: =IF(AI8=1,AD8,-999) -> 3.0323157 | AM8: =C8&"|"&E8&"|"&G8&"|"&TEXT(AJ8,"0.00000") -> 1|2|10|3.03232 | AN8: =C8&"|"&E8&"|"&G8&"|"&TEXT(AK8,"0.00000") -> 1|2|10|3.03232 | AO8: =C8&"|"&E8&"|"&G8&"|"&TEXT(AL8,"0.00000") -> 1|2|10|3.03232
A9: 1 | B9: =INDEX(C_Name,A9) -> 문래건영아파트 84㎡ | C9: 1 | D9: =CHOOSE(C9,"1안 표준형(대출 최대)","2안 절충형(대출 50%)","3안 무대출형","4안 임대차 승계 후 입주","5안 매수 보류(전세 거주)") -> 1안 표준형(대출 최대) | E9: 3 | F9: =CHOOSE(E9,GrowLo,GrowMid,GrowHi) -> 0.06 | G9: 5 | H9: =INDEX(C_Price,A9) -> 13.9 | I9: =INDEX(C_Jeonse,A9) -> 7.228 | J9: =IF(C9=5,0,IF(C9=1,INDEX(C_Loan,A9),IF(C9=2,INDEX(C_Loan,A9)*LoanShare2,IF(C9=3,0,MIN(INDEX(C_Loan,A9),I9))))) -> 5.56 | K9: =IF(C9=5,0,INDEX(C_Acq,A9)) -> 0.4587 | L9: =IF(C9=5,0,INDEX(C_Fee,A9)) -> 0.11174 | M9: =IF(C9=4,MAX(0,I9-J9),0) -> 0 | N9: =IF(C9=5,I9,IF(C9=4,(H9-I9)+K9+L9+M9,H9-J9+K9+L9)) -> 8.91044 | O9: =IF(C9=4,RentYears,0) -> 0 | P9: =IF(C9=5,0,MAX(0,G9-O9-NonRes)) -> 5 | Q9: =IF(C9=5,0,H9*(1+F9)^G9) -> 18.601336 | R9: =IF(C9=5,0,Q9*LOOKUP(Q9,FeeLo,FeeR)*(1+VAT)) -> 0.14323028 | S9: =IF(J9>0,-CUMIPMT(Rm,LoanYears*12,J9,1,(G9-O9)*12,0),0) -> 1.0615392 | T9: =IF(C9=5,0,SUMIFS(Sch_Total,Sch_Idx,A9,Sch_Scen,E9,Sch_Year,"<="&G9)) -> 0.16371343 | U9: =K9+L9+R9 -> 0.71367028 | V9: =IF(C9=5,0,Q9-H9-U9) -> 3.9876652 | W9: =IF(C9=5,0,MAX(0,IF(P9>=2,IF(Q9>Exempt,V9*(Q9-Exempt)/Q9,0),V9))) -> 1.4151627 | X9: =IF(P9>=2,MIN(MaxDed,MIN(0.4,HoldRate*G9)+MIN(0.4,LiveRate*P9)),IF(G9>=3,MIN(0.3,0.02*G9),0)) -> 0.4 | Y9: =MAX(0,W9*(1-X9)-InitDed) -> 0.82409762 | Z9: =SUMPRODUCT((Y9>CLo)*(Y9-CLo)*CD)*(1+LocalTax) -> 0.15420177 | AA9: =K9+T9+Z9 -> 0.77661521 | AB9: =IF(C9=5,0,(Q9-H9)-K9-L9-R9-S9-T9-Z9) -> 2.6082109 | AC9: =IF(C9=5,0,N9*((1+DepRate*(1-DepTax))^G9-1)) -> 1.1896062 | AD9: =IF(C9=5,0,AB9-AC9+I9*(((1+DepRate*(1-DepTax))^G9-1)-((1+DepRate*(1-DepTax))^O9-1))) -> 2.3835933 | AE9: =IF(J9>0,-PMT(Rm,LoanYears*12,J9)*10000,0) -> 265.4429 | AF9: =IF(J9>0,-PMT((Rate+Stress)/12,LoanYears*12,J9)*12/DSR,0) -> 1.1097246 | AG9: =IF(N9<=CapA,1,0) -> 1 | AH9: =IF(N9<=CapB,1,0) -> 1 | AI9: =IF(N9<=CapC,1,0) -> 1 | AJ9: =IF(AG9=1,AD9,-999) -> 2.3835933 | AK9: =IF(AH9=1,AD9,-999) -> 2.3835933 | AL9: =IF(AI9=1,AD9,-999) -> 2.3835933 | AM9: =C9&"|"&E9&"|"&G9&"|"&TEXT(AJ9,"0.00000") -> 1|3|5|2.38359 | AN9: =C9&"|"&E9&"|"&G9&"|"&TEXT(AK9,"0.00000") -> 1|3|5|2.38359 | AO9: =C9&"|"&E9&"|"&G9&"|"&TEXT(AL9,"0.00000") -> 1|3|5|2.38359
A10: 1 | B10: =INDEX(C_Name,A10) -> 문래건영아파트 84㎡ | C10: 1 | D10: =CHOOSE(C10,"1안 표준형(대출 최대)","2안 절충형(대출 50%)","3안 무대출형","4안 임대차 승계 후 입주","5안 매수 보류(전세 거주)") -> 1안 표준형(대출 최대) | E10: 3 | F10: =CHOOSE(E10,GrowLo,GrowMid,GrowHi) -> 0.06 | G10: 10 | H10: =INDEX(C_Price,A10) -> 13.9 | I10: =INDEX(C_Jeonse,A10) -> 7.228 | J10: =IF(C10=5,0,IF(C10=1,INDEX(C_Loan,A10),IF(C10=2,INDEX(C_Loan,A10)*LoanShare2,IF(C10=3,0,MIN(INDEX(C_Loan,A10),I10))))) -> 5.56 | K10: =IF(C10=5,0,INDEX(C_Acq,A10)) -> 0.4587 | L10: =IF(C10=5,0,INDEX(C_Fee,A10)) -> 0.11174 | M10: =IF(C10=4,MAX(0,I10-J10),0) -> 0 | N10: =IF(C10=5,I10,IF(C10=4,(H10-I10)+K10+L10+M10,H10-J10+K10+L10)) -> 8.91044 | O10: =IF(C10=4,RentYears,0) -> 0 | P10: =IF(C10=5,0,MAX(0,G10-O10-NonRes)) -> 10 | Q10: =IF(C10=5,0,H10*(1+F10)^G10) -> 24.892783 | R10: =IF(C10=5,0,Q10*LOOKUP(Q10,FeeLo,FeeR)*(1+VAT)) -> 0.19167443 | S10: =IF(J10>0,-CUMIPMT(Rm,LoanYears*12,J10,1,(G10-O10)*12,0),0) -> 2.005703 | T10: =IF(C10=5,0,SUMIFS(Sch_Total,Sch_Idx,A10,Sch_Scen,E10,Sch_Year,"<="&G10)) -> 0.43952748 | U10: =K10+L10+R10 -> 0.76211443 | V10: =IF(C10=5,0,Q10-H10-U10) -> 10.230669 | W10: =IF(C10=5,0,MAX(0,IF(P10>=2,IF(Q10>Exempt,V10*(Q10-Exempt)/Q10,0),V10))) -> 5.2987964 | X10: =IF(P10>=2,MIN(MaxDed,MIN(0.4,HoldRate*G10)+MIN(0.4,LiveRate*P10)),IF(G10>=3,MIN(0.3,0.02*G10),0)) -> 0.8 | Y10: =MAX(0,W10*(1-X10)-InitDed) -> 1.0347593 | Z10: =SUMPRODUCT((Y10>CLo)*(Y10-CLo)*CD)*(1+LocalTax) -> 0.22854232 | AA10: =K10+T10+Z10 -> 1.1267698 | AB10: =IF(C10=5,0,(Q10-H10)-K10-L10-R10-S10-T10-Z10) -> 7.5568958 | AC10: =IF(C10=5,0,N10*((1+DepRate*(1-DepTax))^G10-1)) -> 2.5380332 | AD10: =IF(C10=5,0,AB10-AC10+I10*(((1+DepRate*(1-DepTax))^G10-1)-((1+DepRate*(1-DepTax))^O10-1))) -> 7.0776727 | AE10: =IF(J10>0,-PMT(Rm,LoanYears*12,J10)*10000,0) -> 265.4429 | AF10: =IF(J10>0,-PMT((Rate+Stress)/12,LoanYears*12,J10)*12/DSR,0) -> 1.1097246 | AG10: =IF(N10<=CapA,1,0) -> 1 | AH10: =IF(N10<=CapB,1,0) -> 1 | AI10: =IF(N10<=CapC,1,0) -> 1 | AJ10: =IF(AG10=1,AD10,-999) -> 7.0776727 | AK10: =IF(AH10=1,AD10,-999) -> 7.0776727 | AL10: =IF(AI10=1,AD10,-999) -> 7.0776727 | AM10: =C10&"|"&E10&"|"&G10&"|"&TEXT(AJ10,"0.00000") -> 1|3|10|7.07767 | AN10: =C10&"|"&E10&"|"&G10&"|"&TEXT(AK10,"0.00000") -> 1|3|10|7.07767 | AO10: =C10&"|"&E10&"|"&G10&"|"&TEXT(AL10,"0.00000") -> 1|3|10|7.07767
A11: 1 | B11: =INDEX(C_Name,A11) -> 문래건영아파트 84㎡ | C11: 2 | D11: =CHOOSE(C11,"1안 표준형(대출 최대)","2안 절충형(대출 50%)","3안 무대출형","4안 임대차 승계 후 입주","5안 매수 보류(전세 거주)") -> 2안 절충형(대출 50%) | E11: 1 | F11: =CHOOSE(E11,GrowLo,GrowMid,GrowHi) -> 0.02 | G11: 5 | H11: =INDEX(C_Price,A11) -> 13.9 | I11: =INDEX(C_Jeonse,A11) -> 7.228 | J11: =IF(C11=5,0,IF(C11=1,INDEX(C_Loan,A11),IF(C11=2,INDEX(C_Loan,A11)*LoanShare2,IF(C11=3,0,MIN(INDEX(C_Loan,A11),I11))))) -> 2.78 | K11: =IF(C11=5,0,INDEX(C_Acq,A11)) -> 0.4587 | L11: =IF(C11=5,0,INDEX(C_Fee,A11)) -> 0.11174 | M11: =IF(C11=4,MAX(0,I11-J11),0) -> 0 | N11: =IF(C11=5,I11,IF(C11=4,(H11-I11)+K11+L11+M11,H11-J11+K11+L11)) -> 11.69044 | O11: =IF(C11=4,RentYears,0) -> 0 | P11: =IF(C11=5,0,MAX(0,G11-O11-NonRes)) -> 5 | Q11: =IF(C11=5,0,H11*(1+F11)^G11) -> 15.346723 | R11: =IF(C11=5,0,Q11*LOOKUP(Q11,FeeLo,FeeR)*(1+VAT)) -> 0.11816977 | S11: =IF(J11>0,-CUMIPMT(Rm,LoanYears*12,J11,1,(G11-O11)*12,0),0) -> 0.53076958 | T11: =IF(C11=5,0,SUMIFS(Sch_Total,Sch_Idx,A11,Sch_Scen,E11,Sch_Year,"<="&G11)) -> 0.14787245 | U11: =K11+L11+R11 -> 0.68860977 | V11: =IF(C11=5,0,Q11-H11-U11) -> 0.7581134 | W11: =IF(C11=5,0,MAX(0,IF(P11>=2,IF(Q11>Exempt,V11*(Q11-Exempt)/Q11,0),V11))) -> 0.16532491 | X11: =IF(P11>=2,MIN(MaxDed,MIN(0.4,HoldRate*G11)+MIN(0.4,LiveRate*P11)),IF(G11>=3,MIN(0.3,0.02*G11),0)) -> 0.4 | Y11: =MAX(0,W11*(1-X11)-InitDed) -> 0.074194947 | Z11: =SUMPRODUCT((Y11>CLo)*(Y11-CLo)*CD)*(1+LocalTax) -> 0.0048968665 | AA11: =K11+T11+Z11 -> 0.61146932 | AB11: =IF(C11=5,0,(Q11-H11)-K11-L11-R11-S11-T11-Z11) -> 0.074574501 | AC11: =IF(C11=5,0,N11*((1+DepRate*(1-DepTax))^G11-1)) -> 1.5607557 | AD11: =IF(C11=5,0,AB11-AC11+I11*(((1+DepRate*(1-DepTax))^G11-1)-((1+DepRate*(1-DepTax))^O11-1))) -> -0.52119253 | AE11: =IF(J11>0,-PMT(Rm,LoanYears*12,J11)*10000,0) -> 132.72145 | AF11: =IF(J11>0,-PMT((Rate+Stress)/12,LoanYears*12,J11)*12/DSR,0) -> 0.55486228 | AG11: =IF(N11<=CapA,1,0) -> 1 | AH11: =IF(N11<=CapB,1,0) -> 1 | AI11: =IF(N11<=CapC,1,0) -> 1 | AJ11: =IF(AG11=1,AD11,-999) -> -0.52119253 | AK11: =IF(AH11=1,AD11,-999) -> -0.52119253 | AL11: =IF(AI11=1,AD11,-999) -> -0.52119253 | AM11: =C11&"|"&E11&"|"&G11&"|"&TEXT(AJ11,"0.00000") -> 2|1|5|-0.52119 | AN11: =C11&"|"&E11&"|"&G11&"|"&TEXT(AK11,"0.00000") -> 2|1|5|-0.52119 | AO11: =C11&"|"&E11&"|"&G11&"|"&TEXT(AL11,"0.00000") -> 2|1|5|-0.52119
A12: 1 | B12: =INDEX(C_Name,A12) -> 문래건영아파트 84㎡ | C12: 2 | D12: =CHOOSE(C12,"1안 표준형(대출 최대)","2안 절충형(대출 50%)","3안 무대출형","4안 임대차 승계 후 입주","5안 매수 보류(전세 거주)") -> 2안 절충형(대출 50%) | E12: 1 | F12: =CHOOSE(E12,GrowLo,GrowMid,GrowHi) -> 0.02 | G12: 10 | H12: =INDEX(C_Price,A12) -> 13.9 | I12: =INDEX(C_Jeonse,A12) -> 7.228 | J12: =IF(C12=5,0,IF(C12=1,INDEX(C_Loan,A12),IF(C12=2,INDEX(C_Loan,A12)*LoanShare2,IF(C12=3,0,MIN(INDEX(C_Loan,A12),I12))))) -> 2.78 | K12: =IF(C12=5,0,INDEX(C_Acq,A12)) -> 0.4587 | L12: =IF(C12=5,0,INDEX(C_Fee,A12)) -> 0.11174 | M12: =IF(C12=4,MAX(0,I12-J12),0) -> 0 | N12: =IF(C12=5,I12,IF(C12=4,(H12-I12)+K12+L12+M12,H12-J12+K12+L12)) -> 11.69044 | O12: =IF(C12=4,RentYears,0) -> 0 | P12: =IF(C12=5,0,MAX(0,G12-O12-NonRes)) -> 10 | Q12: =IF(C12=5,0,H12*(1+F12)^G12) -> 16.944022 | R12: =IF(C12=5,0,Q12*LOOKUP(Q12,FeeLo,FeeR)*(1+VAT)) -> 0.13046897 | S12: =IF(J12>0,-CUMIPMT(Rm,LoanYears*12,J12,1,(G12-O12)*12,0),0) -> 1.0028515 | T12: =IF(C12=5,0,SUMIFS(Sch_Total,Sch_Idx,A12,Sch_Scen,E12,Sch_Year,"<="&G12)) -> 0.31506984 | U12: =K12+L12+R12 -> 0.70090897 | V12: =IF(C12=5,0,Q12-H12-U12) -> 2.3431135 | W12: =IF(C12=5,0,MAX(0,IF(P12>=2,IF(Q12>Exempt,V12*(Q12-Exempt)/Q12,0),V12))) -> 0.68368686 | X12: =IF(P12>=2,MIN(MaxDed,MIN(0.4,HoldRate*G12)+MIN(0.4,LiveRate*P12)),IF(G12>=3,MIN(0.3,0.02*G12),0)) -> 0.8 | Y12: =MAX(0,W12*(1-X12)-InitDed) -> 0.11173737 | Z12: =SUMPRODUCT((Y12>CLo)*(Y12-CLo)*CD)*(1+LocalTax) -> 0.0073746666 | AA12: =K12+T12+Z12 -> 0.78114451 | AB12: =IF(C12=5,0,(Q12-H12)-K12-L12-R12-S12-T12-Z12) -> 1.0178175 | AC12: =IF(C12=5,0,N12*((1+DepRate*(1-DepTax))^G12-1)) -> 3.3298833 | AD12: =IF(C12=5,0,AB12-AC12+I12*(((1+DepRate*(1-DepTax))^G12-1)-((1+DepRate*(1-DepTax))^O12-1))) -> -0.25325568 | AE12: =IF(J12>0,-PMT(Rm,LoanYears*12,J12)*10000,0) -> 132.72145 | AF12: =IF(J12>0,-PMT((Rate+Stress)/12,LoanYears*12,J12)*12/DSR,0) -> 0.55486228 | AG12: =IF(N12<=CapA,1,0) -> 1 | AH12: =IF(N12<=CapB,1,0) -> 1 | AI12: =IF(N12<=CapC,1,0) -> 1 | AJ12: =IF(AG12=1,AD12,-999) -> -0.25325568 | AK12: =IF(AH12=1,AD12,-999) -> -0.25325568 | AL12: =IF(AI12=1,AD12,-999) -> -0.25325568 | AM12: =C12&"|"&E12&"|"&G12&"|"&TEXT(AJ12,"0.00000") -> 2|1|10|-0.25326 | AN12: =C12&"|"&E12&"|"&G12&"|"&TEXT(AK12,"0.00000") -> 2|1|10|-0.25326 | AO12: =C12&"|"&E12&"|"&G12&"|"&TEXT(AL12,"0.00000") -> 2|1|10|-0.25326
A13: 1 | B13: =INDEX(C_Name,A13) -> 문래건영아파트 84㎡ | C13: 2 | D13: =CHOOSE(C13,"1안 표준형(대출 최대)","2안 절충형(대출 50%)","3안 무대출형","4안 임대차 승계 후 입주","5안 매수 보류(전세 거주)") -> 2안 절충형(대출 50%) | E13: 2 | F13: =CHOOSE(E13,GrowLo,GrowMid,GrowHi) -> 0.04 | G13: 5 | H13: =INDEX(C_Price,A13) -> 13.9 | I13: =INDEX(C_Jeonse,A13) -> 7.228 | J13: =IF(C13=5,0,IF(C13=1,INDEX(C_Loan,A13),IF(C13=2,INDEX(C_Loan,A13)*LoanShare2,IF(C13=3,0,MIN(INDEX(C_Loan,A13),I13))))) -> 2.78 | K13: =IF(C13=5,0,INDEX(C_Acq,A13)) -> 0.4587 | L13: =IF(C13=5,0,INDEX(C_Fee,A13)) -> 0.11174 | M13: =IF(C13=4,MAX(0,I13-J13),0) -> 0 | N13: =IF(C13=5,I13,IF(C13=4,(H13-I13)+K13+L13+M13,H13-J13+K13+L13)) -> 11.69044 | O13: =IF(C13=4,RentYears,0) -> 0 | P13: =IF(C13=5,0,MAX(0,G13-O13-NonRes)) -> 5 | Q13: =IF(C13=5,0,H13*(1+F13)^G13) -> 16.911475 | R13: =IF(C13=5,0,Q13*LOOKUP(Q13,FeeLo,FeeR)*(1+VAT)) -> 0.13021836 | S13: =IF(J13>0,-CUMIPMT(Rm,LoanYears*12,J13,1,(G13-O13)*12,0),0) -> 0.53076958 | T13: =IF(C13=5,0,SUMIFS(Sch_Total,Sch_Idx,A13,Sch_Scen,E13,Sch_Year,"<="&G13)) -> 0.15544637 | U13: =K13+L13+R13 -> 0.70065836 | V13: =IF(C13=5,0,Q13-H13-U13) -> 2.310817 | W13: =IF(C13=5,0,MAX(0,IF(P13>=2,IF(Q13>Exempt,V13*(Q13-Exempt)/Q13,0),V13))) -> 0.67111357 | X13: =IF(P13>=2,MIN(MaxDed,MIN(0.4,HoldRate*G13)+MIN(0.4,LiveRate*P13)),IF(G13>=3,MIN(0.3,0.02*G13),0)) -> 0.4 | Y13: =MAX(0,W13*(1-X13)-InitDed) -> 0.37766814 | Z13: =SUMPRODUCT((Y13>CLo)*(Y13-CLo)*CD)*(1+LocalTax) -> 0.048455244 | AA13: =K13+T13+Z13 -> 0.66260162 | AB13: =IF(C13=5,0,(Q13-H13)-K13-L13-R13-S13-T13-Z13) -> 1.5761458 | AC13: =IF(C13=5,0,N13*((1+DepRate*(1-DepTax))^G13-1)) -> 1.5607557 | AD13: =IF(C13=5,0,AB13-AC13+I13*(((1+DepRate*(1-DepTax))^G13-1)-((1+DepRate*(1-DepTax))^O13-1))) -> 0.98037875 | AE13: =IF(J13>0,-PMT(Rm,LoanYears*12,J13)*10000,0) -> 132.72145 | AF13: =IF(J13>0,-PMT((Rate+Stress)/12,LoanYears*12,J13)*12/DSR,0) -> 0.55486228 | AG13: =IF(N13<=CapA,1,0) -> 1 | AH13: =IF(N13<=CapB,1,0) -> 1 | AI13: =IF(N13<=CapC,1,0) -> 1 | AJ13: =IF(AG13=1,AD13,-999) -> 0.98037875 | AK13: =IF(AH13=1,AD13,-999) -> 0.98037875 | AL13: =IF(AI13=1,AD13,-999) -> 0.98037875 | AM13: =C13&"|"&E13&"|"&G13&"|"&TEXT(AJ13,"0.00000") -> 2|2|5|0.98038 | AN13: =C13&"|"&E13&"|"&G13&"|"&TEXT(AK13,"0.00000") -> 2|2|5|0.98038 | AO13: =C13&"|"&E13&"|"&G13&"|"&TEXT(AL13,"0.00000") -> 2|2|5|0.98038
A14: 1 | B14: =INDEX(C_Name,A14) -> 문래건영아파트 84㎡ | C14: 2 | D14: =CHOOSE(C14,"1안 표준형(대출 최대)","2안 절충형(대출 50%)","3안 무대출형","4안 임대차 승계 후 입주","5안 매수 보류(전세 거주)") -> 2안 절충형(대출 50%) | E14: 2 | F14: =CHOOSE(E14,GrowLo,GrowMid,GrowHi) -> 0.04 | G14: 10 | H14: =INDEX(C_Price,A14) -> 13.9 | I14: =INDEX(C_Jeonse,A14) -> 7.228 | J14: =IF(C14=5,0,IF(C14=1,INDEX(C_Loan,A14),IF(C14=2,INDEX(C_Loan,A14)*LoanShare2,IF(C14=3,0,MIN(INDEX(C_Loan,A14),I14))))) -> 2.78 | K14: =IF(C14=5,0,INDEX(C_Acq,A14)) -> 0.4587 | L14: =IF(C14=5,0,INDEX(C_Fee,A14)) -> 0.11174 | M14: =IF(C14=4,MAX(0,I14-J14),0) -> 0 | N14: =IF(C14=5,I14,IF(C14=4,(H14-I14)+K14+L14+M14,H14-J14+K14+L14)) -> 11.69044 | O14: =IF(C14=4,RentYears,0) -> 0 | P14: =IF(C14=5,0,MAX(0,G14-O14-NonRes)) -> 10 | Q14: =IF(C14=5,0,H14*(1+F14)^G14) -> 20.575396 | R14: =IF(C14=5,0,Q14*LOOKUP(Q14,FeeLo,FeeR)*(1+VAT)) -> 0.15843055 | S14: =IF(J14>0,-CUMIPMT(Rm,LoanYears*12,J14,1,(G14-O14)*12,0),0) -> 1.0028515 | T14: =IF(C14=5,0,SUMIFS(Sch_Total,Sch_Idx,A14,Sch_Scen,E14,Sch_Year,"<="&G14)) -> 0.36548147 | U14: =K14+L14+R14 -> 0.72887055 | V14: =IF(C14=5,0,Q14-H14-U14) -> 5.946525 | W14: =IF(C14=5,0,MAX(0,IF(P14>=2,IF(Q14>Exempt,V14*(Q14-Exempt)/Q14,0),V14))) -> 2.4783876 | X14: =IF(P14>=2,MIN(MaxDed,MIN(0.4,HoldRate*G14)+MIN(0.4,LiveRate*P14)),IF(G14>=3,MIN(0.3,0.02*G14),0)) -> 0.8 | Y14: =MAX(0,W14*(1-X14)-InitDed) -> 0.47067751 | Z14: =SUMPRODUCT((Y14>CLo)*(Y14-CLo)*CD)*(1+LocalTax) -> 0.063801789 | AA14: =K14+T14+Z14 -> 0.88798326 | AB14: =IF(C14=5,0,(Q14-H14)-K14-L14-R14-S14-T14-Z14) -> 4.5143903 | AC14: =IF(C14=5,0,N14*((1+DepRate*(1-DepTax))^G14-1)) -> 3.3298833 | AD14: =IF(C14=5,0,AB14-AC14+I14*(((1+DepRate*(1-DepTax))^G14-1)-((1+DepRate*(1-DepTax))^O14-1))) -> 3.2433171 | AE14: =IF(J14>0,-PMT(Rm,LoanYears*12,J14)*10000,0) -> 132.72145 | AF14: =IF(J14>0,-PMT((Rate+Stress)/12,LoanYears*12,J14)*12/DSR,0) -> 0.55486228 | AG14: =IF(N14<=CapA,1,0) -> 1 | AH14: =IF(N14<=CapB,1,0) -> 1 | AI14: =IF(N14<=CapC,1,0) -> 1 | AJ14: =IF(AG14=1,AD14,-999) -> 3.2433171 | AK14: =IF(AH14=1,AD14,-999) -> 3.2433171 | AL14: =IF(AI14=1,AD14,-999) -> 3.2433171 | AM14: =C14&"|"&E14&"|"&G14&"|"&TEXT(AJ14,"0.00000") -> 2|2|10|3.24332 | AN14: =C14&"|"&E14&"|"&G14&"|"&TEXT(AK14,"0.00000") -> 2|2|10|3.24332 | AO14: =C14&"|"&E14&"|"&G14&"|"&TEXT(AL14,"0.00000") -> 2|2|10|3.24332
A15: 1 | B15: =INDEX(C_Name,A15) -> 문래건영아파트 84㎡ | C15: 2 | D15: =CHOOSE(C15,"1안 표준형(대출 최대)","2안 절충형(대출 50%)","3안 무대출형","4안 임대차 승계 후 입주","5안 매수 보류(전세 거주)") -> 2안 절충형(대출 50%) | E15: 3 | F15: =CHOOSE(E15,GrowLo,GrowMid,GrowHi) -> 0.06 | G15: 5 | H15: =INDEX(C_Price,A15) -> 13.9 | I15: =INDEX(C_Jeonse,A15) -> 7.228 | J15: =IF(C15=5,0,IF(C15=1,INDEX(C_Loan,A15),IF(C15=2,INDEX(C_Loan,A15)*LoanShare2,IF(C15=3,0,MIN(INDEX(C_Loan,A15),I15))))) -> 2.78 | K15: =IF(C15=5,0,INDEX(C_Acq,A15)) -> 0.4587 | L15: =IF(C15=5,0,INDEX(C_Fee,A15)) -> 0.11174 | M15: =IF(C15=4,MAX(0,I15-J15),0) -> 0 | N15: =IF(C15=5,I15,IF(C15=4,(H15-I15)+K15+L15+M15,H15-J15+K15+L15)) -> 11.69044 | O15: =IF(C15=4,RentYears,0) -> 0 | P15: =IF(C15=5,0,MAX(0,G15-O15-NonRes)) -> 5 | Q15: =IF(C15=5,0,H15*(1+F15)^G15) -> 18.601336 | R15: =IF(C15=5,0,Q15*LOOKUP(Q15,FeeLo,FeeR)*(1+VAT)) -> 0.14323028 | S15: =IF(J15>0,-CUMIPMT(Rm,LoanYears*12,J15,1,(G15-O15)*12,0),0) -> 0.53076958 | T15: =IF(C15=5,0,SUMIFS(Sch_Total,Sch_Idx,A15,Sch_Scen,E15,Sch_Year,"<="&G15)) -> 0.16371343 | U15: =K15+L15+R15 -> 0.71367028 | V15: =IF(C15=5,0,Q15-H15-U15) -> 3.9876652 | W15: =IF(C15=5,0,MAX(0,IF(P15>=2,IF(Q15>Exempt,V15*(Q15-Exempt)/Q15,0),V15))) -> 1.4151627 | X15: =IF(P15>=2,MIN(MaxDed,MIN(0.4,HoldRate*G15)+MIN(0.4,LiveRate*P15)),IF(G15>=3,MIN(0.3,0.02*G15),0)) -> 0.4 | Y15: =MAX(0,W15*(1-X15)-InitDed) -> 0.82409762 | Z15: =SUMPRODUCT((Y15>CLo)*(Y15-CLo)*CD)*(1+LocalTax) -> 0.15420177 | AA15: =K15+T15+Z15 -> 0.77661521 | AB15: =IF(C15=5,0,(Q15-H15)-K15-L15-R15-S15-T15-Z15) -> 3.1389805 | AC15: =IF(C15=5,0,N15*((1+DepRate*(1-DepTax))^G15-1)) -> 1.5607557 | AD15: =IF(C15=5,0,AB15-AC15+I15*(((1+DepRate*(1-DepTax))^G15-1)-((1+DepRate*(1-DepTax))^O15-1))) -> 2.5432134 | AE15: =IF(J15>0,-PMT(Rm,LoanYears*12,J15)*10000,0) -> 132.72145 | AF15: =IF(J15>0,-PMT((Rate+Stress)/12,LoanYears*12,J15)*12/DSR,0) -> 0.55486228 | AG15: =IF(N15<=CapA,1,0) -> 1 | AH15: =IF(N15<=CapB,1,0) -> 1 | AI15: =IF(N15<=CapC,1,0) -> 1 | AJ15: =IF(AG15=1,AD15,-999) -> 2.5432134 | AK15: =IF(AH15=1,AD15,-999) -> 2.5432134 | AL15: =IF(AI15=1,AD15,-999) -> 2.5432134 | AM15: =C15&"|"&E15&"|"&G15&"|"&TEXT(AJ15,"0.00000") -> 2|3|5|2.54321 | AN15: =C15&"|"&E15&"|"&G15&"|"&TEXT(AK15,"0.00000") -> 2|3|5|2.54321 | AO15: =C15&"|"&E15&"|"&G15&"|"&TEXT(AL15,"0.00000") -> 2|3|5|2.54321
A16: 1 | B16: =INDEX(C_Name,A16) -> 문래건영아파트 84㎡ | C16: 2 | D16: =CHOOSE(C16,"1안 표준형(대출 최대)","2안 절충형(대출 50%)","3안 무대출형","4안 임대차 승계 후 입주","5안 매수 보류(전세 거주)") -> 2안 절충형(대출 50%) | E16: 3 | F16: =CHOOSE(E16,GrowLo,GrowMid,GrowHi) -> 0.06 | G16: 10 | H16: =INDEX(C_Price,A16) -> 13.9 | I16: =INDEX(C_Jeonse,A16) -> 7.228 | J16: =IF(C16=5,0,IF(C16=1,INDEX(C_Loan,A16),IF(C16=2,INDEX(C_Loan,A16)*LoanShare2,IF(C16=3,0,MIN(INDEX(C_Loan,A16),I16))))) -> 2.78 | K16: =IF(C16=5,0,INDEX(C_Acq,A16)) -> 0.4587 | L16: =IF(C16=5,0,INDEX(C_Fee,A16)) -> 0.11174 | M16: =IF(C16=4,MAX(0,I16-J16),0) -> 0 | N16: =IF(C16=5,I16,IF(C16=4,(H16-I16)+K16+L16+M16,H16-J16+K16+L16)) -> 11.69044 | O16: =IF(C16=4,RentYears,0) -> 0 | P16: =IF(C16=5,0,MAX(0,G16-O16-NonRes)) -> 10 | Q16: =IF(C16=5,0,H16*(1+F16)^G16) -> 24.892783 | R16: =IF(C16=5,0,Q16*LOOKUP(Q16,FeeLo,FeeR)*(1+VAT)) -> 0.19167443 | S16: =IF(J16>0,-CUMIPMT(Rm,LoanYears*12,J16,1,(G16-O16)*12,0),0) -> 1.0028515 | T16: =IF(C16=5,0,SUMIFS(Sch_Total,Sch_Idx,A16,Sch_Scen,E16,Sch_Year,"<="&G16)) -> 0.43952748 | U16: =K16+L16+R16 -> 0.76211443 | V16: =IF(C16=5,0,Q16-H16-U16) -> 10.230669 | W16: =IF(C16=5,0,MAX(0,IF(P16>=2,IF(Q16>Exempt,V16*(Q16-Exempt)/Q16,0),V16))) -> 5.2987964 | X16: =IF(P16>=2,MIN(MaxDed,MIN(0.4,HoldRate*G16)+MIN(0.4,LiveRate*P16)),IF(G16>=3,MIN(0.3,0.02*G16),0)) -> 0.8 | Y16: =MAX(0,W16*(1-X16)-InitDed) -> 1.0347593 | Z16: =SUMPRODUCT((Y16>CLo)*(Y16-CLo)*CD)*(1+LocalTax) -> 0.22854232 | AA16: =K16+T16+Z16 -> 1.1267698 | AB16: =IF(C16=5,0,(Q16-H16)-K16-L16-R16-S16-T16-Z16) -> 8.5597473 | AC16: =IF(C16=5,0,N16*((1+DepRate*(1-DepTax))^G16-1)) -> 3.3298833 | AD16: =IF(C16=5,0,AB16-AC16+I16*(((1+DepRate*(1-DepTax))^G16-1)-((1+DepRate*(1-DepTax))^O16-1))) -> 7.2886741 | AE16: =IF(J16>0,-PMT(Rm,LoanYears*12,J16)*10000,0) -> 132.72145 | AF16: =IF(J16>0,-PMT((Rate+Stress)/12,LoanYears*12,J16)*12/DSR,0) -> 0.55486228 | AG16: =IF(N16<=CapA,1,0) -> 1 | AH16: =IF(N16<=CapB,1,0) -> 1 | AI16: =IF(N16<=CapC,1,0) -> 1 | AJ16: =IF(AG16=1,AD16,-999) -> 7.2886741 | AK16: =IF(AH16=1,AD16,-999) -> 7.2886741 | AL16: =IF(AI16=1,AD16,-999) -> 7.2886741 | AM16: =C16&"|"&E16&"|"&G16&"|"&TEXT(AJ16,"0.00000") -> 2|3|10|7.28867 | AN16: =C16&"|"&E16&"|"&G16&"|"&TEXT(AK16,"0.00000") -> 2|3|10|7.28867 | AO16: =C16&"|"&E16&"|"&G16&"|"&TEXT(AL16,"0.00000") -> 2|3|10|7.28867
... A334: 11 | B334: =INDEX(C_Name,A334) -> 흑석 아크로리버하임 84.75㎡ | C334: 5 | D334: =CHOOSE(C334,"1안 표준형(대출 최대)","2안 절충형(대출 50%)","3안 무대출형","4안 임대차 승계 후 입주","5안 매수 보류(전세 거주)") -> 5안 매수 보류(전세 거주) | E334: 3 | F334: =CHOOSE(E334,GrowLo,GrowMid,GrowHi) -> 0.06 | G334: 10 | H334: =INDEX(C_Price,A334) -> 28.75 | I334: =INDEX(C_Jeonse,A334) -> 14.95 | J334: =IF(C334=5,0,IF(C334=1,INDEX(C_Loan,A334),IF(C334=2,INDEX(C_Loan,A334)*LoanShare2,IF(C334=3,0,MIN(INDEX(C_Loan,A334),I334))))) -> 0 | K334: =IF(C334=5,0,INDEX(C_Acq,A334)) -> 0 | L334: =IF(C334=5,0,INDEX(C_Fee,A334)) -> 0 | M334: =IF(C334=4,MAX(0,I334-J334),0) -> 0 | N334: =IF(C334=5,I334,IF(C334=4,(H334-I334)+K334+L334+M334,H334-J334+K334+L334)) -> 14.95 | O334: =IF(C334=4,RentYears,0) -> 0 | P334: =IF(C334=5,0,MAX(0,G334-O334-NonRes)) -> 0 | Q334: =IF(C334=5,0,H334*(1+F334)^G334) -> 0 | R334: =IF(C334=5,0,Q334*LOOKUP(Q334,FeeLo,FeeR)*(1+VAT)) -> 0 | S334: =IF(J334>0,-CUMIPMT(Rm,LoanYears*12,J334,1,(G334-O334)*12,0),0) -> 0 | T334: =IF(C334=5,0,SUMIFS(Sch_Total,Sch_Idx,A334,Sch_Scen,E334,Sch_Year,"<="&G334)) -> 0 | U334: =K334+L334+R334 -> 0 | V334: =IF(C334=5,0,Q334-H334-U334) -> 0 | W334: =IF(C334=5,0,MAX(0,IF(P334>=2,IF(Q334>Exempt,V334*(Q334-Exempt)/Q334,0),V334))) -> 0 | X334: =IF(P334>=2,MIN(MaxDed,MIN(0.4,HoldRate*G334)+MIN(0.4,LiveRate*P334)),IF(G334>=3,MIN(0.3,0.02*G334),0)) -> 0.2 | Y334: =MAX(0,W334*(1-X334)-InitDed) -> 0 | Z334: =SUMPRODUCT((Y334>CLo)*(Y334-CLo)*CD)*(1+LocalTax) -> 0 | AA334: =K334+T334+Z334 -> 0 | AB334: =IF(C334=5,0,(Q334-H334)-K334-L334-R334-S334-T334-Z334) -> 0 | AC334: =IF(C334=5,0,N334*((1+DepRate*(1-DepTax))^G334-1)) -> 0 | AD334: =IF(C334=5,0,AB334-AC334+I334*(((1+DepRate*(1-DepTax))^G334-1)-((1+DepRate*(1-DepTax))^O334-1))) -> 0 | AE334: =IF(J334>0,-PMT(Rm,LoanYears*12,J334)*10000,0) -> 0 | AF334: =IF(J334>0,-PMT((Rate+Stress)/12,LoanYears*12,J334)*12/DSR,0) -> 0 | AG334: =IF(N334<=CapA,1,0) -> 0 | AH334: =IF(N334<=CapB,1,0) -> 0 | AI334: =IF(N334<=CapC,1,0) -> 1 | AJ334: =IF(AG334=1,AD334,-999) -> -999 | AK334: =IF(AH334=1,AD334,-999) -> -999 | AL334: =IF(AI334=1,AD334,-999) -> 0 | AM334: =C334&"|"&E334&"|"&G334&"|"&TEXT(AJ334,"0.00000") -> 5|3|10|-999.00000 | AN334: =C334&"|"&E334&"|"&G334&"|"&TEXT(AK334,"0.00000") -> 5|3|10|-999.00000 | AO334: =C334&"|"&E334&"|"&G334&"|"&TEXT(AL334,"0.00000") -> 5|3|10|0.00000

Sheet 요약
A1: 요약 – 타깃 단지별 3단계 세금과 손익
A2: 기준 시나리오(1=보수 2=기준 3=낙관) | C2: 2 | E2: 상승률 | F2: =CHOOSE(SelScen,GrowLo,GrowMid,GrowHi) -> 0.04
A3: 매도 시점(년: 3·5·7·10 중 선택) | C3: 10
A5: 단지 | B5: 매매가 | C5: 대출 | D5: 필요 자기자본 | E5: A(12억) | F5: B(14억) | G5: C(16억) | H5: ① 취득세 등 | I5: 보유세 1년차(만원) | J5: ② 보유세 누계 | K5: ③ 양도세 | L5: 세금 합계 | M5: 세금/시세차익 | N5: 시세차익 | O5: 세후 순이익 | P5: 수익률 | Q5: 연환산 | R5: 회수율(배) | S5: 예금 대비 초과수익
A6: =INDEX(C_Name,1) -> 문래건영아파트 84㎡ | B6: =INDEX(C_Price,1) -> 13.9 | C6: =INDEX(C_Loan,1) -> 5.56 | D6: =INDEX(C_Equity,1) -> 8.91044 | E6: =INDEX(단지!$Q$6:$Q$17,1) -> 가능 | F6: =INDEX(단지!$R$6:$R$17,1) -> 가능 | G6: =INDEX(단지!$S$6:$S$17,1) -> 가능 | H6: =SUMIFS(Sim_acq,Sim_Idx,1,Sim_Scen,SelScen,Sim_N,SelN) -> 0.4587 | I6: =INDEX(단지!$V$6:$V$17,1) -> 281.1852 | J6: =SUMIFS(Sim_ptax,Sim_Idx,1,Sim_Scen,SelScen,Sim_N,SelN) -> 0.36548147 | K6: =SUMIFS(Sim_ctax,Sim_Idx,1,Sim_Scen,SelScen,Sim_N,SelN) -> 0.063801789 | L6: =H6+J6+K6 -> 0.88798326 | M6: =IF(N6>0,L6/N6,0) -> 0.13302332 | N6: =SUMIFS(Sim_S,Sim_Idx,1,Sim_Scen,SelScen,Sim_N,SelN)-B6 -> 6.6753956 | O6: =SUMIFS(Sim_net,Sim_Idx,1,Sim_Scen,SelScen,Sim_N,SelN) -> 3.5115388 | P6: =SUMIFS(Sim_roi,Sim_Idx,1,Sim_Scen,SelScen,Sim_N,SelN) -> 0.39409263 | Q6: =SUMIFS(Sim_cagr,Sim_Idx,1,Sim_Scen,SelScen,Sim_N,SelN) -> 0.033782469 | R6: =SUMIFS(Sim_recr,Sim_Idx,1,Sim_Scen,SelScen,Sim_N,SelN) -> 1.7925911 | S6: =SUMIFS(Sim_exc,Sim_Idx,1,Sim_Scen,SelScen,Sim_N,SelN) -> 0.97350554
A7: =INDEX(C_Name,2) -> e편한세상 문래 에듀플라츠 84.99㎡ | B7: =INDEX(C_Price,2) -> 14.9 | C7: =INDEX(C_Loan,2) -> 5.96 | D7: =INDEX(C_Equity,2) -> 9.55004 | E7: =INDEX(단지!$Q$6:$Q$17,2) -> 가능 | F7: =INDEX(단지!$R$6:$R$17,2) -> 가능 | G7: =INDEX(단지!$S$6:$S$17,2) -> 가능 | H7: =SUMIFS(Sim_acq,Sim_Idx,2,Sim_Scen,SelScen,Sim_N,SelN) -> 0.4917 | I7: =INDEX(단지!$V$6:$V$17,2) -> 306.8532 | J7: =SUMIFS(Sim_ptax,Sim_Idx,2,Sim_Scen,SelScen,Sim_N,SelN) -> 0.41157422 | K7: =SUMIFS(Sim_ctax,Sim_Idx,2,Sim_Scen,SelScen,Sim_N,SelN) -> 0.083521738 | L7: =H7+J7+K7 -> 0.98679595 | M7: =IF(N7>0,L7/N7,0) -> 0.13790464 | N7: =SUMIFS(Sim_S,Sim_Idx,2,Sim_Scen,SelScen,Sim_N,SelN)-B7 -> 7.1556398 | O7: =SUMIFS(Sim_net,Sim_Idx,2,Sim_Scen,SelScen,Sim_N,SelN) -> 3.7306773 | P7: =SUMIFS(Sim_roi,Sim_Idx,2,Sim_Scen,SelScen,Sim_N,SelN) -> 0.3906452 | Q7: =SUMIFS(Sim_cagr,Sim_Idx,2,Sim_Scen,SelScen,Sim_N,SelN) -> 0.033526542 | R7: =SUMIFS(Sim_recr,Sim_Idx,2,Sim_Scen,SelScen,Sim_N,SelN) -> 1.7912769 | S7: =SUMIFS(Sim_exc,Sim_Idx,2,Sim_Scen,SelScen,Sim_N,SelN) -> 1.0104616
A8: =INDEX(C_Name,3) -> 문래자이 84㎡ | B8: =INDEX(C_Price,3) -> 19.5 | C8: =INDEX(C_Loan,3) -> 4 | D8: =INDEX(C_Equity,3) -> 16.31365 | E8: =INDEX(단지!$Q$6:$Q$17,3) -> 부족 4.3억 | F8: =INDEX(단지!$R$6:$R$17,3) -> 부족 2.3억 | G8: =INDEX(단지!$S$6:$S$17,3) -> 부족 0.3억 | H8: =SUMIFS(Sim_acq,Sim_Idx,3,Sim_Scen,SelScen,Sim_N,SelN) -> 0.6435 | I8: =INDEX(단지!$V$6:$V$17,3) -> 477.306 | J8: =SUMIFS(Sim_ptax,Sim_Idx,3,Sim_Scen,SelScen,Sim_N,SelN) -> 0.68107419 | K8: =SUMIFS(Sim_ctax,Sim_Idx,3,Sim_Scen,SelScen,Sim_N,SelN) -> 0.19523895 | L8: =H8+J8+K8 -> 1.5198131 | M8: =IF(N8>0,L8/N8,0) -> 0.16229061 | N8: =SUMIFS(Sim_S,Sim_Idx,3,Sim_Scen,SelScen,Sim_N,SelN)-B8 -> 9.3647636 | O8: =SUMIFS(Sim_net,Sim_Idx,3,Sim_Scen,SelScen,Sim_N,SelN) -> 6.0095899 | P8: =SUMIFS(Sim_roi,Sim_Idx,3,Sim_Scen,SelScen,Sim_N,SelN) -> 0.36837801 | Q8: =SUMIFS(Sim_cagr,Sim_Idx,3,Sim_Scen,SelScen,Sim_N,SelN) -> 0.031859599 | R8: =SUMIFS(Sim_recr,Sim_Idx,3,Sim_Scen,SelScen,Sim_N,SelN) -> 1.5505977 | S8: =SUMIFS(Sim_exc,Sim_Idx,3,Sim_Scen,SelScen,Sim_N,SelN) -> 1.3628401
A9: =INDEX(C_Name,4) -> 신길삼성래미안 84㎡ | B9: =INDEX(C_Price,4) -> 13 | C9: =INDEX(C_Loan,4) -> 5.2 | D9: =INDEX(C_Equity,4) -> 8.3348 | E9: =INDEX(단지!$Q$6:$Q$17,4) -> 가능 | F9: =INDEX(단지!$R$6:$R$17,4) -> 가능 | G9: =INDEX(단지!$S$6:$S$17,4) -> 가능 | H9: =SUMIFS(Sim_acq,Sim_Idx,4,Sim_Scen,SelScen,Sim_N,SelN) -> 0.429 | I9: =INDEX(단지!$V$6:$V$17,4) -> 225.792 | J9: =SUMIFS(Sim_ptax,Sim_Idx,4,Sim_Scen,SelScen,Sim_N,SelN) -> 0.3255508 | K9: =SUMIFS(Sim_ctax,Sim_Idx,4,Sim_Scen,SelScen,Sim_N,SelN) -> 0.05107982 | L9: =H9+J9+K9 -> 0.80563062 | M9: =IF(N9>0,L9/N9,0) -> 0.1290418 | N9: =SUMIFS(Sim_S,Sim_Idx,4,Sim_Scen,SelScen,Sim_N,SelN)-B9 -> 6.2431757 | O9: =SUMIFS(Sim_net,Sim_Idx,4,Sim_Scen,SelScen,Sim_N,SelN) -> 3.3077353 | P9: =SUMIFS(Sim_roi,Sim_Idx,4,Sim_Scen,SelScen,Sim_N,SelN) -> 0.39685839 | Q9: =SUMIFS(Sim_cagr,Sim_Idx,4,Sim_Scen,SelScen,Sim_N,SelN) -> 0.03398738 | R9: =SUMIFS(Sim_recr,Sim_Idx,4,Sim_Scen,SelScen,Sim_N,SelN) -> 1.7933433 | S9: =SUMIFS(Sim_exc,Sim_Idx,4,Sim_Scen,SelScen,Sim_N,SelN) -> 0.93366631
A10: =INDEX(C_Name,5) -> 신길 래미안에스티움 84㎡ | B10: =INDEX(C_Price,5) -> 18.8 | C10: =INDEX(C_Loan,5) -> 4 | D10: =INDEX(C_Equity,5) -> 15.58516 | E10: =INDEX(단지!$Q$6:$Q$17,5) -> 부족 3.6억 | F10: =INDEX(단지!$R$6:$R$17,5) -> 부족 1.6억 | G10: =INDEX(단지!$S$6:$S$17,5) -> 가능 | H10: =SUMIFS(Sim_acq,Sim_Idx,5,Sim_Scen,SelScen,Sim_N,SelN) -> 0.6204 | I10: =INDEX(단지!$V$6:$V$17,5) -> 441.9504 | J10: =SUMIFS(Sim_ptax,Sim_Idx,5,Sim_Scen,SelScen,Sim_N,SelN) -> 0.63573301 | K10: =SUMIFS(Sim_ctax,Sim_Idx,5,Sim_Scen,SelScen,Sim_N,SelN) -> 0.1721857 | L10: =H10+J10+K10 -> 1.4283187 | M10: =IF(N10>0,L10/N10,0) -> 0.15819949 | N10: =SUMIFS(Sim_S,Sim_Idx,5,Sim_Scen,SelScen,Sim_N,SelN)-B10 -> 9.0285926 | O10: =SUMIFS(Sim_net,Sim_Idx,5,Sim_Scen,SelScen,Sim_N,SelN) -> 5.7782819 | P10: =SUMIFS(Sim_roi,Sim_Idx,5,Sim_Scen,SelScen,Sim_N,SelN) -> 0.37075538 | Q10: =SUMIFS(Sim_cagr,Sim_Idx,5,Sim_Scen,SelScen,Sim_N,SelN) -> 0.032038731 | R10: =SUMIFS(Sim_recr,Sim_Idx,5,Sim_Scen,SelScen,Sim_N,SelN) -> 1.5585832 | S10: =SUMIFS(Sim_exc,Sim_Idx,5,Sim_Scen,SelScen,Sim_N,SelN) -> 1.3390338
A11: =INDEX(C_Name,6) -> 신길 보라매SK뷰 84.98㎡ | B11: =INDEX(C_Price,6) -> 20.4 | C11: =INDEX(C_Loan,6) -> 4 | D11: =INDEX(C_Equity,6) -> 17.25028 | E11: =INDEX(단지!$Q$6:$Q$17,6) -> 부족 5.3억 | F11: =INDEX(단지!$R$6:$R$17,6) -> 부족 3.3억 | G11: =INDEX(단지!$S$6:$S$17,6) -> 부족 1.3억 | H11: =SUMIFS(Sim_acq,Sim_Idx,6,Sim_Scen,SelScen,Sim_N,SelN) -> 0.6732 | I11: =INDEX(단지!$V$6:$V$17,6) -> 522.7632 | J11: =SUMIFS(Sim_ptax,Sim_Idx,6,Sim_Scen,SelScen,Sim_N,SelN) -> 0.74063634 | K11: =SUMIFS(Sim_ctax,Sim_Idx,6,Sim_Scen,SelScen,Sim_N,SelN) -> 0.22488125 | L11: =H11+J11+K11 -> 1.6387176 | M11: =IF(N11>0,L11/N11,0) -> 0.16726757 | N11: =SUMIFS(Sim_S,Sim_Idx,6,Sim_Scen,SelScen,Sim_N,SelN)-B11 -> 9.7969834 | O11: =SUMIFS(Sim_net,Sim_Idx,6,Sim_Scen,SelScen,Sim_N,SelN) -> 6.3057173 | P11: =SUMIFS(Sim_roi,Sim_Idx,6,Sim_Scen,SelScen,Sim_N,SelN) -> 0.36554289 | Q11: =SUMIFS(Sim_cagr,Sim_Idx,6,Sim_Scen,SelScen,Sim_N,SelN) -> 0.03164561 | R11: =SUMIFS(Sim_recr,Sim_Idx,6,Sim_Scen,SelScen,Sim_N,SelN) -> 1.5413215 | S11: =SUMIFS(Sim_exc,Sim_Idx,6,Sim_Scen,SelScen,Sim_N,SelN) -> 1.3921794
A12: =INDEX(C_Name,7) -> 노량진동 쌍용예가 85㎡ | B12: =INDEX(C_Price,7) -> 14.5 | C12: =INDEX(C_Loan,7) -> 5.8 | D12: =INDEX(C_Equity,7) -> 9.2942 | E12: =INDEX(단지!$Q$6:$Q$17,7) -> 가능 | F12: =INDEX(단지!$R$6:$R$17,7) -> 가능 | G12: =INDEX(단지!$S$6:$S$17,7) -> 가능 | H12: =SUMIFS(Sim_acq,Sim_Idx,7,Sim_Scen,SelScen,Sim_N,SelN) -> 0.4785 | I12: =INDEX(단지!$V$6:$V$17,7) -> 296.586 | J12: =SUMIFS(Sim_ptax,Sim_Idx,7,Sim_Scen,SelScen,Sim_N,SelN) -> 0.39260136 | K12: =SUMIFS(Sim_ctax,Sim_Idx,7,Sim_Scen,SelScen,Sim_N,SelN) -> 0.074471904 | L12: =H12+J12+K12 -> 0.94557326 | M12: =IF(N12>0,L12/N12,0) -> 0.13578912 | N12: =SUMIFS(Sim_S,Sim_Idx,7,Sim_Scen,SelScen,Sim_N,SelN)-B12 -> 6.9635421 | O12: =SUMIFS(Sim_net,Sim_Idx,7,Sim_Scen,SelScen,Sim_N,SelN) -> 3.6447195 | P12: =SUMIFS(Sim_roi,Sim_Idx,7,Sim_Scen,SelScen,Sim_N,SelN) -> 0.39214989 | Q12: =SUMIFS(Sim_cagr,Sim_Idx,7,Sim_Scen,SelScen,Sim_N,SelN) -> 0.033638316 | R12: =SUMIFS(Sim_recr,Sim_Idx,7,Sim_Scen,SelScen,Sim_N,SelN) -> 1.7919058 | S12: =SUMIFS(Sim_exc,Sim_Idx,7,Sim_Scen,SelScen,Sim_N,SelN) -> 0.99737678
A13: =INDEX(C_Name,8) -> 본동 래미안트윈파크 (32평형) | B13: =INDEX(C_Price,8) -> 24.2 | C13: =INDEX(C_Loan,8) -> 4 | D13: =INDEX(C_Equity,8) -> 21.20494 | E13: =INDEX(단지!$Q$6:$Q$17,8) -> 부족 9.2억 | F13: =INDEX(단지!$R$6:$R$17,8) -> 부족 7.2억 | G13: =INDEX(단지!$S$6:$S$17,8) -> 부족 5.2억 | H13: =SUMIFS(Sim_acq,Sim_Idx,8,Sim_Scen,SelScen,Sim_N,SelN) -> 0.7986 | I13: =INDEX(단지!$V$6:$V$17,8) -> 714.6936 | J13: =SUMIFS(Sim_ptax,Sim_Idx,8,Sim_Scen,SelScen,Sim_N,SelN) -> 1.0098786 | K13: =SUMIFS(Sim_ctax,Sim_Idx,8,Sim_Scen,SelScen,Sim_N,SelN) -> 0.35006079 | L13: =H13+J13+K13 -> 2.1585394 | M13: =IF(N13>0,L13/N13,0) -> 0.18573015 | N13: =SUMIFS(Sim_S,Sim_Idx,8,Sim_Scen,SelScen,Sim_N,SelN)-B13 -> 11.621912 | O13: =SUMIFS(Sim_net,Sim_Idx,8,Sim_Scen,SelScen,Sim_N,SelN) -> 7.5382518 | P13: =SUMIFS(Sim_roi,Sim_Idx,8,Sim_Scen,SelScen,Sim_N,SelN) -> 0.35549508 | Q13: =SUMIFS(Sim_cagr,Sim_Idx,8,Sim_Scen,SelScen,Sim_N,SelN) -> 0.030883989 | R13: =SUMIFS(Sim_recr,Sim_Idx,8,Sim_Scen,SelScen,Sim_N,SelN) -> 1.5111886 | S13: =SUMIFS(Sim_exc,Sim_Idx,8,Sim_Scen,SelScen,Sim_N,SelN) -> 1.4982759
A14: =INDEX(C_Name,9) -> 흑석한강푸르지오 84.98㎡ | B14: =INDEX(C_Price,9) -> 20 | C14: =INDEX(C_Loan,9) -> 4 | D14: =INDEX(C_Equity,9) -> 16.834 | E14: =INDEX(단지!$Q$6:$Q$17,9) -> 부족 4.8억 | F14: =INDEX(단지!$R$6:$R$17,9) -> 부족 2.8억 | G14: =INDEX(단지!$S$6:$S$17,9) -> 부족 0.8억 | H14: =SUMIFS(Sim_acq,Sim_Idx,9,Sim_Scen,SelScen,Sim_N,SelN) -> 0.66 | I14: =INDEX(단지!$V$6:$V$17,9) -> 502.56 | J14: =SUMIFS(Sim_ptax,Sim_Idx,9,Sim_Scen,SelScen,Sim_N,SelN) -> 0.71406379 | K14: =SUMIFS(Sim_ctax,Sim_Idx,9,Sim_Scen,SelScen,Sim_N,SelN) -> 0.21170658 | L14: =H14+J14+K14 -> 1.5857704 | M14: =IF(N14>0,L14/N14,0) -> 0.16510039 | N14: =SUMIFS(Sim_S,Sim_Idx,9,Sim_Scen,SelScen,Sim_N,SelN)-B14 -> 9.6048857 | O14: =SUMIFS(Sim_net,Sim_Idx,9,Sim_Scen,SelScen,Sim_N,SelN) -> 6.1742059 | P14: =SUMIFS(Sim_roi,Sim_Idx,9,Sim_Scen,SelScen,Sim_N,SelN) -> 0.36676998 | Q14: =SUMIFS(Sim_cagr,Sim_Idx,9,Sim_Scen,SelScen,Sim_N,SelN) -> 0.031738278 | R14: =SUMIFS(Sim_recr,Sim_Idx,9,Sim_Scen,SelScen,Sim_N,SelN) -> 1.5453168 | S14: =SUMIFS(Sim_exc,Sim_Idx,9,Sim_Scen,SelScen,Sim_N,SelN) -> 1.3792405
A15: =INDEX(C_Name,10) -> 흑석리버파크자이 85㎡ | B15: =INDEX(C_Price,10) -> 23.07 | C15: =INDEX(C_Loan,10) -> 4 | D15: =INDEX(C_Equity,10) -> 20.028949 | E15: =INDEX(단지!$Q$6:$Q$17,10) -> 부족 8.0억 | F15: =INDEX(단지!$R$6:$R$17,10) -> 부족 6.0억 | G15: =INDEX(단지!$S$6:$S$17,10) -> 부족 4.0억 | H15: =SUMIFS(Sim_acq,Sim_Idx,10,Sim_Scen,SelScen,Sim_N,SelN) -> 0.76131 | I15: =INDEX(단지!$V$6:$V$17,10) -> 657.61956 | J15: =SUMIFS(Sim_ptax,Sim_Idx,10,Sim_Scen,SelScen,Sim_N,SelN) -> 0.92540018 | K15: =SUMIFS(Sim_ctax,Sim_Idx,10,Sim_Scen,SelScen,Sim_N,SelN) -> 0.31283304 | L15: =H15+J15+K15 -> 1.9995432 | M15: =IF(N15>0,L15/N15,0) -> 0.18047664 | N15: =SUMIFS(Sim_S,Sim_Idx,10,Sim_Scen,SelScen,Sim_N,SelN)-B15 -> 11.079236 | O15: =SUMIFS(Sim_net,Sim_Idx,10,Sim_Scen,SelScen,Sim_N,SelN) -> 7.1761525 | P15: =SUMIFS(Sim_roi,Sim_Idx,10,Sim_Scen,SelScen,Sim_N,SelN) -> 0.35828902 | Q15: =SUMIFS(Sim_cagr,Sim_Idx,10,Sim_Scen,SelScen,Sim_N,SelN) -> 0.031096278 | R15: =SUMIFS(Sim_recr,Sim_Idx,10,Sim_Scen,SelScen,Sim_N,SelN) -> 1.5189062 | S15: =SUMIFS(Sim_exc,Sim_Idx,10,Sim_Scen,SelScen,Sim_N,SelN) -> 1.4711438
A16: =INDEX(C_Name,11) -> 흑석 아크로리버하임 84.75㎡ | B16: =INDEX(C_Price,11) -> 28.75 | C16: =INDEX(C_Loan,11) -> 2 | D16: =INDEX(C_Equity,11) -> 27.940125 | E16: =INDEX(단지!$Q$6:$Q$17,11) -> 부족 15.9억 | F16: =INDEX(단지!$R$6:$R$17,11) -> 부족 13.9억 | G16: =INDEX(단지!$S$6:$S$17,11) -> 부족 11.9억 | H16: =SUMIFS(Sim_acq,Sim_Idx,11,Sim_Scen,SelScen,Sim_N,SelN) -> 0.94875 | I16: =INDEX(단지!$V$6:$V$17,11) -> 985.365 | J16: =SUMIFS(Sim_ptax,Sim_Idx,11,Sim_Scen,SelScen,Sim_N,SelN) -> 1.3820315 | K16: =SUMIFS(Sim_ctax,Sim_Idx,11,Sim_Scen,SelScen,Sim_N,SelN) -> 0.5078934 | L16: =H16+J16+K16 -> 2.8386749 | M16: =IF(N16>0,L16/N16,0) -> 0.20559645 | N16: =SUMIFS(Sim_S,Sim_Idx,11,Sim_Scen,SelScen,Sim_N,SelN)-B16 -> 13.807023 | O16: =SUMIFS(Sim_net,Sim_Idx,11,Sim_Scen,SelScen,Sim_N,SelN) -> 9.6778083 | P16: =SUMIFS(Sim_roi,Sim_Idx,11,Sim_Scen,SelScen,Sim_N,SelN) -> 0.3463767 | Q16: =SUMIFS(Sim_cagr,Sim_Idx,11,Sim_Scen,SelScen,Sim_N,SelN) -> 0.030188408 | R16: =SUMIFS(Sim_recr,Sim_Idx,11,Sim_Scen,SelScen,Sim_N,SelN) -> 1.4368497 | S16: =SUMIFS(Sim_exc,Sim_Idx,11,Sim_Scen,SelScen,Sim_N,SelN) -> 1.7193948
A17: =INDEX(C_Name,12) -> 예시 행: 직접 입력 (비교 시트 제외) | B17: =INDEX(C_Price,12) -> 14 | C17: =INDEX(C_Loan,12) -> 5.6 | D17: =INDEX(C_Equity,12) -> 8.9744 | E17: =INDEX(단지!$Q$6:$Q$17,12) -> 가능 | F17: =INDEX(단지!$R$6:$R$17,12) -> 가능 | G17: =INDEX(단지!$S$6:$S$17,12) -> 가능 | H17: =SUMIFS(Sim_acq,Sim_Idx,12,Sim_Scen,SelScen,Sim_N,SelN) -> 0.462 | I17: =INDEX(단지!$V$6:$V$17,12) -> 283.752 | J17: =SUMIFS(Sim_ptax,Sim_Idx,12,Sim_Scen,SelScen,Sim_N,SelN) -> 0.36989789 | K17: =SUMIFS(Sim_ctax,Sim_Idx,12,Sim_Scen,SelScen,Sim_N,SelN) -> 0.065215553 | L17: =H17+J17+K17 -> 0.89711344 | M17: =IF(N17>0,L17/N17,0) -> 0.13343112 | N17: =SUMIFS(Sim_S,Sim_Idx,12,Sim_Scen,SelScen,Sim_N,SelN)-B17 -> 6.72342 | O17: =SUMIFS(Sim_net,Sim_Idx,12,Sim_Scen,SelScen,Sim_N,SelN) -> 3.5342037 | P17: =SUMIFS(Sim_roi,Sim_Idx,12,Sim_Scen,SelScen,Sim_N,SelN) -> 0.39380947 | Q17: =SUMIFS(Sim_cagr,Sim_Idx,12,Sim_Scen,SelScen,Sim_N,SelN) -> 0.03376147 | R17: =SUMIFS(Sim_recr,Sim_Idx,12,Sim_Scen,SelScen,Sim_N,SelN) -> 1.7925134 | S17: =SUMIFS(Sim_exc,Sim_Idx,12,Sim_Scen,SelScen,Sim_N,SelN) -> 0.97795223
A20: 민감도 ① 세후 순이익(억) – 상승률 시나리오별 (매도 시점 = C3)
A21: 단지 | B21: 보수 | C21: 기준 | D21: 낙관
A22: =INDEX(C_Name,1) -> 문래건영아파트 84㎡ | B22: =SUMIFS(Sim_net,Sim_Idx,1,Sim_Scen,1,Sim_N,SelN) -> 0.014965975 | C22: =SUMIFS(Sim_net,Sim_Idx,1,Sim_Scen,2,Sim_N,SelN) -> 3.5115388 | D22: =SUMIFS(Sim_net,Sim_Idx,1,Sim_Scen,3,Sim_N,SelN) -> 7.5568958
A23: =INDEX(C_Name,2) -> e편한세상 문래 에듀플라츠 84.99㎡ | B23: =SUMIFS(Sim_net,Sim_Idx,2,Sim_Scen,1,Sim_N,SelN) -> 0.0085950406 | C23: =SUMIFS(Sim_net,Sim_Idx,2,Sim_Scen,2,Sim_N,SelN) -> 3.7306773 | D23: =SUMIFS(Sim_net,Sim_Idx,2,Sim_Scen,3,Sim_N,SelN) -> 8.0362038
A24: =INDEX(C_Name,3) -> 문래자이 84㎡ | B24: =SUMIFS(Sim_net,Sim_Idx,3,Sim_Scen,1,Sim_N,SelN) -> 1.2244034 | C24: =SUMIFS(Sim_net,Sim_Idx,3,Sim_Scen,2,Sim_N,SelN) -> 6.0095899 | D24: =SUMIFS(Sim_net,Sim_Idx,3,Sim_Scen,3,Sim_N,SelN) -> 11.523077
A25: =INDEX(C_Name,4) -> 신길삼성래미안 84㎡ | B25: =SUMIFS(Sim_net,Sim_Idx,4,Sim_Scen,1,Sim_N,SelN) -> 0.022355412 | C25: =SUMIFS(Sim_net,Sim_Idx,4,Sim_Scen,2,Sim_N,SelN) -> 3.3077353 | D25: =SUMIFS(Sim_net,Sim_Idx,4,Sim_Scen,3,Sim_N,SelN) -> 7.1250369
A26: =INDEX(C_Name,5) -> 신길 래미안에스티움 84㎡ | B26: =SUMIFS(Sim_net,Sim_Idx,5,Sim_Scen,1,Sim_N,SelN) -> 1.1487704 | C26: =SUMIFS(Sim_net,Sim_Idx,5,Sim_Scen,2,Sim_N,SelN) -> 5.7782819 | D26: =SUMIFS(Sim_net,Sim_Idx,5,Sim_Scen,3,Sim_N,SelN) -> 11.104126
