Workbook

Sheet 사용방법
A1: 서울 무주택 진입 – 타깃 단지별 취득·보유·양도 3단계 세금 시뮬레이션
A3: 작성일 | B3: 2026-10-20 (가격·규제는 2026-10월 검색 기준)
A4: 전제 | B4: 지방 2주택을 처분해 서울에서 무주택자로 진입. 자기자본 12·14·16억(세후 가용 현금으로 가정, 입력 시트에서 변경). 실거주 + 장기보유(1세대1주택) 구조.
A5: 셀 색 규칙 | B5: 파란 글씨 = 입력값(변경 가능, 노란 배경 = 핵심 입력) / 검정 = 수식 / 초록 = 다른 시트에서 가져온 값
A6: 바꿔 볼 곳 | B6: ① '입력' 시트: 자기자본, 금리, 상승률, 전세가율 등 / ② '단지' 시트 F열: 매매가(억). 7번 행은 직접 입력하는 예시 행입니다.
A7: 시트 구성 | B7: 입력 → 세율표 → 단지(매수 단계: 대출·취득세·필요 자기자본) → 보유세_스케줄(보유 단계) → 시뮬레이션(양도 단계·손익) → 요약 → 최대매수가능액
A8: 단위 | B8: 금액은 억 원(보유세 1년차·월 원리금은 만원). 수익률은 투자금 대비 10년 누적(연환산은 단순 계산).
A9: 데이터 한계 | B9: 단지 가격은 뉴스·KB시세·시세사이트 기반 참고값이며 일부는 추정입니다. 계약 전 국토부 실거래가 공개시스템과 네이버부동산 중층 매물로 교차검증하세요(단지 시트의 '신뢰도' 열 참고).
A10: 모델 단순화 | B10: ① 종부세는 재산세 중복분 공제·고령자/장기보유 세액공제를 반영하지 않음(보수적) ② 공시가 현실화율 69%·공정시장가액비율 60% 고정 ③ 2026.8월 세제개편안(종부세·장특공 한도·중과 완화)은 국회 통과 미확인으로 미반영 ④ 지방 2주택 처분 양도세와 처분 일정은 별도 검토 대상 ⑤ 실거주로 절감되는 주거비는 미반영.
A11: 면책 | B11: 세무사 확정 계산을 대체하지 않는 의사결정 참고용 모델입니다.

Sheet 요약
A1: 요약 – 타깃 단지별 3단계 세금과 손익
A2: 기준 시나리오(1=보수 2=기준 3=낙관) | C2: 2 | E2: 상승률 | F2: =CHOOSE(SelScen,G1,G2,G3) -> 0.04
A3: 매도 시점(년: 3·5·7·10 중 선택) | C3: 10
A5: 단지 | B5: 매매가 | C5: 대출 | D5: 필요 자기자본 | E5: A(12억) | F5: B(14억) | G5: C(16억) | H5: ① 취득세 등 | I5: 보유세 1년차(만원) | J5: ② 보유세 누계 | K5: ③ 양도세 | L5: 세금 합계 | M5: 세금/시세차익 | N5: 시세차익 | O5: 세후 순이익 | P5: 수익률 | Q5: 연환산 | R5: 회수율(배) | S5: 예금 대비 초과수익
A6: =INDEX(C_Name,1) -> 문래동 대단지 (단지 미특정, 입력 필요) | B6: =INDEX(C_Price,1) -> 12.5 | C6: =INDEX(C_Loan,1) -> 5 | D6: =INDEX(C_Equity,1) -> 8.015 | E6: =INDEX(단지!$Q$6:$Q$12,1) -> 가능 | F6: =INDEX(단지!$R$6:$R$12,1) -> 가능 | G6: =INDEX(단지!$S$6:$S$12,1) -> 가능 | H6: =SUMIFS(Sim_acq,Sim_Idx,1,Sim_Scen,SelScen,Sim_N,SelN) -> 0.4125 | I6: =INDEX(단지!$V$6:$V$12,1) -> 214.2 | J6: =SUMIFS(Sim_ptax,Sim_Idx,1,Sim_Scen,SelScen,Sim_N,SelN) -> 0.30427558 | K6: =SUMIFS(Sim_ctax,Sim_Idx,1,Sim_Scen,SelScen,Sim_N,SelN) -> 0.044013717 | L6: =H6+J6+K6 -> 0.7607893 | M6: =IF(N6>0,L6/N6,0) -> 0.12673372 | N6: =SUMIFS(Sim_S,Sim_Idx,1,Sim_Scen,SelScen,Sim_N,SelN)-B6 -> 6.0030536 | O6: =SUMIFS(Sim_net,Sim_Idx,1,Sim_Scen,SelScen,Sim_N,SelN) -> 3.193601 | P6: =SUMIFS(Sim_roi,Sim_Idx,1,Sim_Scen,SelScen,Sim_N,SelN) -> 0.39845303 | Q6: =SUMIFS(Sim_cagr,Sim_Idx,1,Sim_Scen,SelScen,Sim_N,SelN) -> 0.034105358 | R6: =SUMIFS(Sim_recr,Sim_Idx,1,Sim_Scen,SelScen,Sim_N,SelN) -> 1.7938077 | S6: =SUMIFS(Sim_exc,Sim_Idx,1,Sim_Scen,SelScen,Sim_N,SelN) -> 0.91062326
A7: =INDEX(C_Name,2) -> 신길삼성래미안 84㎡ | B7: =INDEX(C_Price,2) -> 13 | C7: =INDEX(C_Loan,2) -> 5.2 | D7: =INDEX(C_Equity,2) -> 8.3348 | E7: =INDEX(단지!$Q$6:$Q$12,2) -> 가능 | F7: =INDEX(단지!$R$6:$R$12,2) -> 가능 | G7: =INDEX(단지!$S$6:$S$12,2) -> 가능 | H7: =SUMIFS(Sim_acq,Sim_Idx,2,Sim_Scen,SelScen,Sim_N,SelN) -> 0.429 | I7: =INDEX(단지!$V$6:$V$12,2) -> 225.792 | J7: =SUMIFS(Sim_ptax,Sim_Idx,2,Sim_Scen,SelScen,Sim_N,SelN) -> 0.3255508 | K7: =SUMIFS(Sim_ctax,Sim_Idx,2,Sim_Scen,SelScen,Sim_N,SelN) -> 0.05107982 | L7: =H7+J7+K7 -> 0.80563062 | M7: =IF(N7>0,L7/N7,0) -> 0.1290418 | N7: =SUMIFS(Sim_S,Sim_Idx,2,Sim_Scen,SelScen,Sim_N,SelN)-B7 -> 6.2431757 | O7: =SUMIFS(Sim_net,Sim_Idx,2,Sim_Scen,SelScen,Sim_N,SelN) -> 3.3077353 | P7: =SUMIFS(Sim_roi,Sim_Idx,2,Sim_Scen,SelScen,Sim_N,SelN) -> 0.39685839 | Q7: =SUMIFS(Sim_cagr,Sim_Idx,2,Sim_Scen,SelScen,Sim_N,SelN) -> 0.03398738 | R7: =SUMIFS(Sim_recr,Sim_Idx,2,Sim_Scen,SelScen,Sim_N,SelN) -> 1.7933433 | S7: =SUMIFS(Sim_exc,Sim_Idx,2,Sim_Scen,SelScen,Sim_N,SelN) -> 0.93366631
A8: =INDEX(C_Name,3) -> 신길 래미안에스티움 84㎡ | B8: =INDEX(C_Price,3) -> 18.8 | C8: =INDEX(C_Loan,3) -> 4 | D8: =INDEX(C_Equity,3) -> 15.58516 | E8: =INDEX(단지!$Q$6:$Q$12,3) -> 부족 3.6억 | F8: =INDEX(단지!$R$6:$R$12,3) -> 부족 1.6억 | G8: =INDEX(단지!$S$6:$S$12,3) -> 가능 | H8: =SUMIFS(Sim_acq,Sim_Idx,3,Sim_Scen,SelScen,Sim_N,SelN) -> 0.6204 | I8: =INDEX(단지!$V$6:$V$12,3) -> 441.9504 | J8: =SUMIFS(Sim_ptax,Sim_Idx,3,Sim_Scen,SelScen,Sim_N,SelN) -> 0.63573301 | K8: =SUMIFS(Sim_ctax,Sim_Idx,3,Sim_Scen,SelScen,Sim_N,SelN) -> 0.1721857 | L8: =H8+J8+K8 -> 1.4283187 | M8: =IF(N8>0,L8/N8,0) -> 0.15819949 | N8: =SUMIFS(Sim_S,Sim_Idx,3,Sim_Scen,SelScen,Sim_N,SelN)-B8 -> 9.0285926 | O8: =SUMIFS(Sim_net,Sim_Idx,3,Sim_Scen,SelScen,Sim_N,SelN) -> 5.7782819 | P8: =SUMIFS(Sim_roi,Sim_Idx,3,Sim_Scen,SelScen,Sim_N,SelN) -> 0.37075538 | Q8: =SUMIFS(Sim_cagr,Sim_Idx,3,Sim_Scen,SelScen,Sim_N,SelN) -> 0.032038731 | R8: =SUMIFS(Sim_recr,Sim_Idx,3,Sim_Scen,SelScen,Sim_N,SelN) -> 1.5585832 | S8: =SUMIFS(Sim_exc,Sim_Idx,3,Sim_Scen,SelScen,Sim_N,SelN) -> 1.3390338
A9: =INDEX(C_Name,4) -> 신길 보라매SK뷰 84.98㎡ | B9: =INDEX(C_Price,4) -> 20.4 | C9: =INDEX(C_Loan,4) -> 4 | D9: =INDEX(C_Equity,4) -> 17.25028 | E9: =INDEX(단지!$Q$6:$Q$12,4) -> 부족 5.3억 | F9: =INDEX(단지!$R$6:$R$12,4) -> 부족 3.3억 | G9: =INDEX(단지!$S$6:$S$12,4) -> 부족 1.3억 | H9: =SUMIFS(Sim_acq,Sim_Idx,4,Sim_Scen,SelScen,Sim_N,SelN) -> 0.6732 | I9: =INDEX(단지!$V$6:$V$12,4) -> 522.7632 | J9: =SUMIFS(Sim_ptax,Sim_Idx,4,Sim_Scen,SelScen,Sim_N,SelN) -> 0.74063634 | K9: =SUMIFS(Sim_ctax,Sim_Idx,4,Sim_Scen,SelScen,Sim_N,SelN) -> 0.22488125 | L9: =H9+J9+K9 -> 1.6387176 | M9: =IF(N9>0,L9/N9,0) -> 0.16726757 | N9: =SUMIFS(Sim_S,Sim_Idx,4,Sim_Scen,SelScen,Sim_N,SelN)-B9 -> 9.7969834 | O9: =SUMIFS(Sim_net,Sim_Idx,4,Sim_Scen,SelScen,Sim_N,SelN) -> 6.3057173 | P9: =SUMIFS(Sim_roi,Sim_Idx,4,Sim_Scen,SelScen,Sim_N,SelN) -> 0.36554289 | Q9: =SUMIFS(Sim_cagr,Sim_Idx,4,Sim_Scen,SelScen,Sim_N,SelN) -> 0.03164561 | R9: =SUMIFS(Sim_recr,Sim_Idx,4,Sim_Scen,SelScen,Sim_N,SelN) -> 1.5413215 | S9: =SUMIFS(Sim_exc,Sim_Idx,4,Sim_Scen,SelScen,Sim_N,SelN) -> 1.3921794
A10: =INDEX(C_Name,5) -> 본동 래미안트윈파크 (32평형) | B10: =INDEX(C_Price,5) -> 24.2 | C10: =INDEX(C_Loan,5) -> 4 | D10: =INDEX(C_Equity,5) -> 21.20494 | E10: =INDEX(단지!$Q$6:$Q$12,5) -> 부족 9.2억 | F10: =INDEX(단지!$R$6:$R$12,5) -> 부족 7.2억 | G10: =INDEX(단지!$S$6:$S$12,5) -> 부족 5.2억 | H10: =SUMIFS(Sim_acq,Sim_Idx,5,Sim_Scen,SelScen,Sim_N,SelN) -> 0.7986 | I10: =INDEX(단지!$V$6:$V$12,5) -> 714.6936 | J10: =SUMIFS(Sim_ptax,Sim_Idx,5,Sim_Scen,SelScen,Sim_N,SelN) -> 1.0098786 | K10: =SUMIFS(Sim_ctax,Sim_Idx,5,Sim_Scen,SelScen,Sim_N,SelN) -> 0.35006079 | L10: =H10+J10+K10 -> 2.1585394 | M10: =IF(N10>0,L10/N10,0) -> 0.18573015 | N10: =SUMIFS(Sim_S,Sim_Idx,5,Sim_Scen,SelScen,Sim_N,SelN)-B10 -> 11.621912 | O10: =SUMIFS(Sim_net,Sim_Idx,5,Sim_Scen,SelScen,Sim_N,SelN) -> 7.5382518 | P10: =SUMIFS(Sim_roi,Sim_Idx,5,Sim_Scen,SelScen,Sim_N,SelN) -> 0.35549508 | Q10: =SUMIFS(Sim_cagr,Sim_Idx,5,Sim_Scen,SelScen,Sim_N,SelN) -> 0.030883989 | R10: =SUMIFS(Sim_recr,Sim_Idx,5,Sim_Scen,SelScen,Sim_N,SelN) -> 1.5111886 | S10: =SUMIFS(Sim_exc,Sim_Idx,5,Sim_Scen,SelScen,Sim_N,SelN) -> 1.4982759
A11: =INDEX(C_Name,6) -> 흑석 아크로리버하임 84.75㎡ | B11: =INDEX(C_Price,6) -> 28.75 | C11: =INDEX(C_Loan,6) -> 2 | D11: =INDEX(C_Equity,6) -> 27.940125 | E11: =INDEX(단지!$Q$6:$Q$12,6) -> 부족 15.9억 | F11: =INDEX(단지!$R$6:$R$12,6) -> 부족 13.9억 | G11: =INDEX(단지!$S$6:$S$12,6) -> 부족 11.9억 | H11: =SUMIFS(Sim_acq,Sim_Idx,6,Sim_Scen,SelScen,Sim_N,SelN) -> 0.94875 | I11: =INDEX(단지!$V$6:$V$12,6) -> 985.365 | J11: =SUMIFS(Sim_ptax,Sim_Idx,6,Sim_Scen,SelScen,Sim_N,SelN) -> 1.3820315 | K11: =SUMIFS(Sim_ctax,Sim_Idx,6,Sim_Scen,SelScen,Sim_N,SelN) -> 0.5078934 | L11: =H11+J11+K11 -> 2.8386749 | M11: =IF(N11>0,L11/N11,0) -> 0.20559645 | N11: =SUMIFS(Sim_S,Sim_Idx,6,Sim_Scen,SelScen,Sim_N,SelN)-B11 -> 13.807023 | O11: =SUMIFS(Sim_net,Sim_Idx,6,Sim_Scen,SelScen,Sim_N,SelN) -> 9.6778083 | P11: =SUMIFS(Sim_roi,Sim_Idx,6,Sim_Scen,SelScen,Sim_N,SelN) -> 0.3463767 | Q11: =SUMIFS(Sim_cagr,Sim_Idx,6,Sim_Scen,SelScen,Sim_N,SelN) -> 0.030188408 | R11: =SUMIFS(Sim_recr,Sim_Idx,6,Sim_Scen,SelScen,Sim_N,SelN) -> 1.4368497 | S11: =SUMIFS(Sim_exc,Sim_Idx,6,Sim_Scen,SelScen,Sim_N,SelN) -> 1.7193948
A12: =INDEX(C_Name,7) -> 예시 행: 직접 입력 | B12: =INDEX(C_Price,7) -> 14 | C12: =INDEX(C_Loan,7) -> 5.6 | D12: =INDEX(C_Equity,7) -> 8.9744 | E12: =INDEX(단지!$Q$6:$Q$12,7) -> 가능 | F12: =INDEX(단지!$R$6:$R$12,7) -> 가능 | G12: =INDEX(단지!$S$6:$S$12,7) -> 가능 | H12: =SUMIFS(Sim_acq,Sim_Idx,7,Sim_Scen,SelScen,Sim_N,SelN) -> 0.462 | I12: =INDEX(단지!$V$6:$V$12,7) -> 283.752 | J12: =SUMIFS(Sim_ptax,Sim_Idx,7,Sim_Scen,SelScen,Sim_N,SelN) -> 0.36989789 | K12: =SUMIFS(Sim_ctax,Sim_Idx,7,Sim_Scen,SelScen,Sim_N,SelN) -> 0.065215553 | L12: =H12+J12+K12 -> 0.89711344 | M12: =IF(N12>0,L12/N12,0) -> 0.13343112 | N12: =SUMIFS(Sim_S,Sim_Idx,7,Sim_Scen,SelScen,Sim_N,SelN)-B12 -> 6.72342 | O12: =SUMIFS(Sim_net,Sim_Idx,7,Sim_Scen,SelScen,Sim_N,SelN) -> 3.5342037 | P12: =SUMIFS(Sim_roi,Sim_Idx,7,Sim_Scen,SelScen,Sim_N,SelN) -> 0.39380947 | Q12: =SUMIFS(Sim_cagr,Sim_Idx,7,Sim_Scen,SelScen,Sim_N,SelN) -> 0.03376147 | R12: =SUMIFS(Sim_recr,Sim_Idx,7,Sim_Scen,SelScen,Sim_N,SelN) -> 1.7925134 | S12: =SUMIFS(Sim_exc,Sim_Idx,7,Sim_Scen,SelScen,Sim_N,SelN) -> 0.97795223
A15: 민감도 ① 세후 순이익(억) – 상승률 시나리오별 (매도 시점 = C3)
A16: 단지 | B16: 보수 | C16: 기준 | D16: 낙관
A17: =INDEX(C_Name,1) -> 문래동 대단지 (단지 미특정, 입력 필요) | B17: =SUMIFS(Sim_net,Sim_Idx,1,Sim_Scen,1,Sim_N,SelN) -> 0.030939191 | C17: =SUMIFS(Sim_net,Sim_Idx,1,Sim_Scen,2,Sim_N,SelN) -> 3.193601 | D17: =SUMIFS(Sim_net,Sim_Idx,1,Sim_Scen,3,Sim_N,SelN) -> 6.875096
A18: =INDEX(C_Name,2) -> 신길삼성래미안 84㎡ | B18: =SUMIFS(Sim_net,Sim_Idx,2,Sim_Scen,1,Sim_N,SelN) -> 0.022355412 | C18: =SUMIFS(Sim_net,Sim_Idx,2,Sim_Scen,2,Sim_N,SelN) -> 3.3077353 | D18: =SUMIFS(Sim_net,Sim_Idx,2,Sim_Scen,3,Sim_N,SelN) -> 7.1250369
A19: =INDEX(C_Name,3) -> 신길 래미안에스티움 84㎡ | B19: =SUMIFS(Sim_net,Sim_Idx,3,Sim_Scen,1,Sim_N,SelN) -> 1.1487704 | C19: =SUMIFS(Sim_net,Sim_Idx,3,Sim_Scen,2,Sim_N,SelN) -> 5.7782819 | D19: =SUMIFS(Sim_net,Sim_Idx,3,Sim_Scen,3,Sim_N,SelN) -> 11.104126
A20: =INDEX(C_Name,4) -> 신길 보라매SK뷰 84.98㎡ | B20: =SUMIFS(Sim_net,Sim_Idx,4,Sim_Scen,1,Sim_N,SelN) -> 1.3216445 | C20: =SUMIFS(Sim_net,Sim_Idx,4,Sim_Scen,2,Sim_N,SelN) -> 6.3057173 | D20: =SUMIFS(Sim_net,Sim_Idx,4,Sim_Scen,3,Sim_N,SelN) -> 12.059444
A21: =INDEX(C_Name,5) -> 본동 래미안트윈파크 (32평형) | B21: =SUMIFS(Sim_net,Sim_Idx,5,Sim_Scen,1,Sim_N,SelN) -> 1.7132838 | C21: =SUMIFS(Sim_net,Sim_Idx,5,Sim_Scen,2,Sim_N,SelN) -> 7.5382518 | D21: =SUMIFS(Sim_net,Sim_Idx,5,Sim_Scen,3,Sim_N,SelN) -> 14.300136
A22: =INDEX(C_Name,6) -> 흑석 아크로리버하임 84.75㎡ | B22: =SUMIFS(Sim_net,Sim_Idx,6,Sim_Scen,1,Sim_N,SelN) -> 2.8574674 | C22: =SUMIFS(Sim_net,Sim_Idx,6,Sim_Scen,2,Sim_N,SelN) -> 9.6778083 | D22: =SUMIFS(Sim_net,Sim_Idx,6,Sim_Scen,3,Sim_N,SelN) -> 17.65999
A23: =INDEX(C_Name,7) -> 예시 행: 직접 입력 | B23: =SUMIFS(Sim_net,Sim_Idx,7,Sim_Scen,1,Sim_N,SelN) -> 0.014503624 | C23: =SUMIFS(Sim_net,Sim_Idx,7,Sim_Scen,2,Sim_N,SelN) -> 3.5342037 | D23: =SUMIFS(Sim_net,Sim_Idx,7,Sim_Scen,3,Sim_N,SelN) -> 7.6049682
A26: 민감도 ② 세후 순이익(억) – 매도 시점별 (상승률 시나리오 = C2)
A27: 단지 | B27: 3년 | C27: 5년 | D27: 7년 | E27: 10년
A28: =INDEX(C_Name,1) -> 문래동 대단지 (단지 미특정, 입력 필요) | B28: =SUMIFS(Sim_net,Sim_Idx,1,Sim_Scen,SelScen,Sim_N,3) -> 0.29221648 | C28: =SUMIFS(Sim_net,Sim_Idx,1,Sim_Scen,SelScen,Sim_N,5) -> 0.96641688 | D28: =SUMIFS(Sim_net,Sim_Idx,1,Sim_Scen,SelScen,Sim_N,7) -> 1.7582451 | E28: =SUMIFS(Sim_net,Sim_Idx,1,Sim_Scen,SelScen,Sim_N,10) -> 3.193601
A29: =INDEX(C_Name,2) -> 신길삼성래미안 84㎡ | B29: =SUMIFS(Sim_net,Sim_Idx,2,Sim_Scen,SelScen,Sim_N,3) -> 0.29873452 | C29: =SUMIFS(Sim_net,Sim_Idx,2,Sim_Scen,SelScen,Sim_N,5) -> 0.99377775 | D29: =SUMIFS(Sim_net,Sim_Idx,2,Sim_Scen,SelScen,Sim_N,7) -> 1.8161559 | E29: =SUMIFS(Sim_net,Sim_Idx,2,Sim_Scen,SelScen,Sim_N,10) -> 3.3077353
A30: =INDEX(C_Name,3) -> 신길 래미안에스티움 84㎡ | B30: =SUMIFS(Sim_net,Sim_Idx,3,Sim_Scen,SelScen,Sim_N,3) -> 0.72996469 | C30: =SUMIFS(Sim_net,Sim_Idx,3,Sim_Scen,SelScen,Sim_N,5) -> 1.9232361 | D30: =SUMIFS(Sim_net,Sim_Idx,3,Sim_Scen,SelScen,Sim_N,7) -> 3.269164 | E30: =SUMIFS(Sim_net,Sim_Idx,3,Sim_Scen,SelScen,Sim_N,10) -> 5.7782819
A31: =INDEX(C_Name,4) -> 신길 보라매SK뷰 84.98㎡ | B31: =SUMIFS(Sim_net,Sim_Idx,4,Sim_Scen,SelScen,Sim_N,3) -> 0.807912 | C31: =SUMIFS(Sim_net,Sim_Idx,4,Sim_Scen,SelScen,Sim_N,5) -> 2.0867334 | D31: =SUMIFS(Sim_net,Sim_Idx,4,Sim_Scen,SelScen,Sim_N,7) -> 3.5564225 | E31: =SUMIFS(Sim_net,Sim_Idx,4,Sim_Scen,SelScen,Sim_N,10) -> 6.3057173
A32: =INDEX(C_Name,5) -> 본동 래미안트윈파크 (32평형) | B32: =SUMIFS(Sim_net,Sim_Idx,5,Sim_Scen,SelScen,Sim_N,3) -> 0.97561851 | C32: =SUMIFS(Sim_net,Sim_Idx,5,Sim_Scen,SelScen,Sim_N,5) -> 2.4616512 | D32: =SUMIFS(Sim_net,Sim_Idx,5,Sim_Scen,SelScen,Sim_N,7) -> 4.2166086 | E32: =SUMIFS(Sim_net,Sim_Idx,5,Sim_Scen,SelScen,Sim_N,10) -> 7.5382518
A33: =INDEX(C_Name,6) -> 흑석 아크로리버하임 84.75㎡ | B33: =SUMIFS(Sim_net,Sim_Idx,6,Sim_Scen,SelScen,Sim_N,3) -> 1.3839202 | C33: =SUMIFS(Sim_net,Sim_Idx,6,Sim_Scen,SelScen,Sim_N,5) -> 3.2631468 | D33: =SUMIFS(Sim_net,Sim_Idx,6,Sim_Scen,SelScen,Sim_N,7) -> 5.4930507 | E33: =SUMIFS(Sim_net,Sim_Idx,6,Sim_Scen,SelScen,Sim_N,10) -> 9.6778083
A34: =INDEX(C_Name,7) -> 예시 행: 직접 입력 | B34: =SUMIFS(Sim_net,Sim_Idx,7,Sim_Scen,SelScen,Sim_N,3) -> 0.29511691 | C34: =SUMIFS(Sim_net,Sim_Idx,7,Sim_Scen,SelScen,Sim_N,5) -> 1.0514674 | D34: =SUMIFS(Sim_net,Sim_Idx,7,Sim_Scen,SelScen,Sim_N,7) -> 1.9298276 | E34: =SUMIFS(Sim_net,Sim_Idx,7,Sim_Scen,SelScen,Sim_N,10) -> 3.5342037
A37: 민감도 ③ 양도세(억) – 매도 시점별 (상승률 시나리오 = C2)
A38: 단지 | B38: 3년 | C38: 5년 | D38: 7년 | E38: 10년
A39: =INDEX(C_Name,1) -> 문래동 대단지 (단지 미특정, 입력 필요) | B39: =SUMIFS(Sim_ctax,Sim_Idx,1,Sim_Scen,SelScen,Sim_N,3) -> 0.0053560892 | C39: =SUMIFS(Sim_ctax,Sim_Idx,1,Sim_Scen,SelScen,Sim_N,5) -> 0.025371504 | D39: =SUMIFS(Sim_ctax,Sim_Idx,1,Sim_Scen,SelScen,Sim_N,7) -> 0.046963391 | E39: =SUMIFS(Sim_ctax,Sim_Idx,1,Sim_Scen,SelScen,Sim_N,10) -> 0.044013717
A40: =INDEX(C_Name,2) -> 신길삼성래미안 84㎡ | B40: =SUMIFS(Sim_ctax,Sim_Idx,2,Sim_Scen,SelScen,Sim_N,3) -> 0.0072753843 | C40: =SUMIFS(Sim_ctax,Sim_Idx,2,Sim_Scen,SelScen,Sim_N,5) -> 0.033611806 | D40: =SUMIFS(Sim_ctax,Sim_Idx,2,Sim_Scen,SelScen,Sim_N,7) -> 0.056585677 | E40: =SUMIFS(Sim_ctax,Sim_Idx,2,Sim_Scen,SelScen,Sim_N,10) -> 0.05107982
A41: =INDEX(C_Name,3) -> 신길 래미안에스티움 84㎡ | B41: =SUMIFS(Sim_ctax,Sim_Idx,3,Sim_Scen,SelScen,Sim_N,3) -> 0.057924498 | C41: =SUMIFS(Sim_ctax,Sim_Idx,3,Sim_Scen,SelScen,Sim_N,5) -> 0.16435147 | D41: =SUMIFS(Sim_ctax,Sim_Idx,3,Sim_Scen,SelScen,Sim_N,7) -> 0.25354204 | E41: =SUMIFS(Sim_ctax,Sim_Idx,3,Sim_Scen,SelScen,Sim_N,10) -> 0.1721857
A42: =INDEX(C_Name,4) -> 신길 보라매SK뷰 84.98㎡ | B42: =SUMIFS(Sim_ctax,Sim_Idx,4,Sim_Scen,SelScen,Sim_N,3) -> 0.075554736 | C42: =SUMIFS(Sim_ctax,Sim_Idx,4,Sim_Scen,SelScen,Sim_N,5) -> 0.22361882 | D42: =SUMIFS(Sim_ctax,Sim_Idx,4,Sim_Scen,SelScen,Sim_N,7) -> 0.32526561 | E42: =SUMIFS(Sim_ctax,Sim_Idx,4,Sim_Scen,SelScen,Sim_N,10) -> 0.22488125
A43: =INDEX(C_Name,5) -> 본동 래미안트윈파크 (32평형) | B43: =SUMIFS(Sim_ctax,Sim_Idx,5,Sim_Scen,SelScen,Sim_N,3) -> 0.13279079 | C43: =SUMIFS(Sim_ctax,Sim_Idx,5,Sim_Scen,SelScen,Sim_N,5) -> 0.3694961 | D43: =SUMIFS(Sim_ctax,Sim_Idx,5,Sim_Scen,SelScen,Sim_N,7) -> 0.50322175 | E43: =SUMIFS(Sim_ctax,Sim_Idx,5,Sim_Scen,SelScen,Sim_N,10) -> 0.35006079
A44: =INDEX(C_Name,6) -> 흑석 아크로리버하임 84.75㎡ | B44: =SUMIFS(Sim_ctax,Sim_Idx,6,Sim_Scen,SelScen,Sim_N,3) -> 0.21632377 | C44: =SUMIFS(Sim_ctax,Sim_Idx,6,Sim_Scen,SelScen,Sim_N,5) -> 0.5559978 | D44: =SUMIFS(Sim_ctax,Sim_Idx,6,Sim_Scen,SelScen,Sim_N,7) -> 0.72484686 | E44: =SUMIFS(Sim_ctax,Sim_Idx,6,Sim_Scen,SelScen,Sim_N,10) -> 0.5078934
A45: =INDEX(C_Name,7) -> 예시 행: 직접 입력 | B45: =SUMIFS(Sim_ctax,Sim_Idx,7,Sim_Scen,SelScen,Sim_N,3) -> 0.013425565 | C45: =SUMIFS(Sim_ctax,Sim_Idx,7,Sim_Scen,SelScen,Sim_N,5) -> 0.050105287 | D45: =SUMIFS(Sim_ctax,Sim_Idx,7,Sim_Scen,SelScen,Sim_N,7) -> 0.080158369 | E45: =SUMIFS(Sim_ctax,Sim_Idx,7,Sim_Scen,SelScen,Sim_N,10) -> 0.065215553

Sheet 단지
A1: 타깃 단지 – 매수 단계(대출·취득세·필요 자기자본)
A2: F열(매매가)이 핵심 입력입니다. '신뢰도'가 낮은 행은 국토부 실거래가·네이버 중층 매물로 교체하세요. 7번 행은 직접 입력하는 예시 행입니다.
A5: 번호 | B5: 권역 | C5: 노선 | D5: 단지 / 기준 | E5: 전용(㎡) | F5: 매매가(억) | G5: 가격 근거 | H5: 신뢰도 | I5: 전세가율 | J5: 전세가(억) | K5: 갭(억) | L5: 공시가(억) | M5: 대출 가능(억) | N5: 취득세 등(억) | O5: 매수 비용(억) | P5: 필요 자기자본(억) | Q5: 자기자본 A 충족 | R5: 자기자본 B 충족 | S5: 자기자본 C 충족 | T5: 월 원리금(만원) | U5: 필요 연소득(억) | V5: 보유세 1년차(만원)
A6: 1 | B6: 문래 | C6: 2호선 문래 | D6: 문래동 대단지 (단지 미특정, 입력 필요) | E6: 84 | F6: 12.5 | G6: 추정: 사전 구간(11~14억) 중간값. 실거래 미확인 | H6: 낮음(추정) | I6: =JeonseRate -> 0.52 | J6: =F6*I6 -> 6.5 | K6: =F6-J6 -> 6 | L6: =F6*Gongsi -> 8.625 | M6: =MIN(LTV*F6,LOOKUP(F6,LoanLo,LoanCap)) -> 5 | N6: =F6*IF(F6<=6,0.01,IF(F6<=9,(F6*2/3-3)/100,0.03))*(1+EduAcq)+IF(E6>85,F6*NongAcqRate,0) -> 0.4125 | O6: =F6*LOOKUP(F6,FeeLo,FeeR)*(1+VAT)+EtcBuy -> 0.1025 | P6: =F6-M6+N6+O6 -> 8.015 | Q6: =IF(P6<=Eq1,"가능","부족 "&TEXT(P6-Eq1,"0.0")&"억") -> 가능 | R6: =IF(P6<=Eq2,"가능","부족 "&TEXT(P6-Eq2,"0.0")&"억") -> 가능 | S6: =IF(P6<=Eq3,"가능","부족 "&TEXT(P6-Eq3,"0.0")&"억") -> 가능 | T6: =-PMT(Rm,LoanYears*12,M6)*10000 -> 238.70765 | U6: =-PMT((Rate+Stress)/12,LoanYears*12,M6)*12/DSR -> 0.99795374 | V6: =SUMIFS(Sch_Total,Sch_Idx,A6,Sch_Scen,2,Sch_Year,1)*10000 -> 214.2
A7: 2 | B7: 신길 | C7: 5호선 신길 / 1호선 | D7: 신길삼성래미안 84㎡ | E7: 84 | F7: 13 | G7: 2026.6월 실거래 13억 (네이트뉴스 보도) | H7: 중(뉴스 보도) | I7: =JeonseRate -> 0.52 | J7: =F7*I7 -> 6.76 | K7: =F7-J7 -> 6.24 | L7: =F7*Gongsi -> 8.97 | M7: =MIN(LTV*F7,LOOKUP(F7,LoanLo,LoanCap)) -> 5.2 | N7: =F7*IF(F7<=6,0.01,IF(F7<=9,(F7*2/3-3)/100,0.03))*(1+EduAcq)+IF(E7>85,F7*NongAcqRate,0) -> 0.429 | O7: =F7*LOOKUP(F7,FeeLo,FeeR)*(1+VAT)+EtcBuy -> 0.1058 | P7: =F7-M7+N7+O7 -> 8.3348 | Q7: =IF(P7<=Eq1,"가능","부족 "&TEXT(P7-Eq1,"0.0")&"억") -> 가능 | R7: =IF(P7<=Eq2,"가능","부족 "&TEXT(P7-Eq2,"0.0")&"억") -> 가능 | S7: =IF(P7<=Eq3,"가능","부족 "&TEXT(P7-Eq3,"0.0")&"억") -> 가능 | T7: =-PMT(Rm,LoanYears*12,M7)*10000 -> 248.25595 | U7: =-PMT((Rate+Stress)/12,LoanYears*12,M7)*12/DSR -> 1.0378719 | V7: =SUMIFS(Sch_Total,Sch_Idx,A7,Sch_Scen,2,Sch_Year,1)*10000 -> 225.792
A8: 3 | B8: 신길 | C8: 5호선 신길 / 1호선 | D8: 신길 래미안에스티움 84㎡ | E8: 84 | F8: 18.8 | G8: 2026.5.26 2층 18.8억 실거래 보도, 84㎡ 평균 18.66억. 중층 이상은 더 높을 수 있음(7월 18층 20.1억 거래 보도는 면적 미확인) | H8: 중(뉴스 보도) | I8: =JeonseRate -> 0.52 | J8: =F8*I8 -> 9.776 | K8: =F8-J8 -> 9.024 | L8: =F8*Gongsi -> 12.972 | M8: =MIN(LTV*F8,LOOKUP(F8,LoanLo,LoanCap)) -> 4 | N8: =F8*IF(F8<=6,0.01,IF(F8<=9,(F8*2/3-3)/100,0.03))*(1+EduAcq)+IF(E8>85,F8*NongAcqRate,0) -> 0.6204 | O8: =F8*LOOKUP(F8,FeeLo,FeeR)*(1+VAT)+EtcBuy -> 0.16476 | P8: =F8-M8+N8+O8 -> 15.58516 | Q8: =IF(P8<=Eq1,"가능","부족 "&TEXT(P8-Eq1,"0.0")&"억") -> 부족 3.6억 | R8: =IF(P8<=Eq2,"가능","부족 "&TEXT(P8-Eq2,"0.0")&"억") -> 부족 1.6억 | S8: =IF(P8<=Eq3,"가능","부족 "&TEXT(P8-Eq3,"0.0")&"억") -> 가능 | T8: =-PMT(Rm,LoanYears*12,M8)*10000 -> 190.96612 | U8: =-PMT((Rate+Stress)/12,LoanYears*12,M8)*12/DSR -> 0.79836299 | V8: =SUMIFS(Sch_Total,Sch_Idx,A8,Sch_Scen,2,Sch_Year,1)*10000 -> 441.9504
A9: 4 | B9: 신길 | C9: 5호선 신길 / 1호선 | D9: 신길 보라매SK뷰 84.98㎡ | E9: 84.98 | F9: 20.4 | G9: 2026.9.1 18층 20.4억, 2026.10.6 27층 20.9억 실거래 (시세 사이트) | H9: 중(시세 사이트) | I9: =JeonseRate -> 0.52 | J9: =F9*I9 -> 10.608 | K9: =F9-J9 -> 9.792 | L9: =F9*Gongsi -> 14.076 | M9: =MIN(LTV*F9,LOOKUP(F9,LoanLo,LoanCap)) -> 4 | N9: =F9*IF(F9<=6,0.01,IF(F9<=9,(F9*2/3-3)/100,0.03))*(1+EduAcq)+IF(E9>85,F9*NongAcqRate,0) -> 0.6732 | O9: =F9*LOOKUP(F9,FeeLo,FeeR)*(1+VAT)+EtcBuy -> 0.17708 | P9: =F9-M9+N9+O9 -> 17.25028 | Q9: =IF(P9<=Eq1,"가능","부족 "&TEXT(P9-Eq1,"0.0")&"억") -> 부족 5.3억 | R9: =IF(P9<=Eq2,"가능","부족 "&TEXT(P9-Eq2,"0.0")&"억") -> 부족 3.3억 | S9: =IF(P9<=Eq3,"가능","부족 "&TEXT(P9-Eq3,"0.0")&"억") -> 부족 1.3억 | T9: =-PMT(Rm,LoanYears*12,M9)*10000 -> 190.96612 | U9: =-PMT((Rate+Stress)/12,LoanYears*12,M9)*12/DSR -> 0.79836299 | V9: =SUMIFS(Sch_Total,Sch_Idx,A9,Sch_Scen,2,Sch_Year,1)*10000 -> 522.7632
A10: 5 | B10: 노량진(본동) | C10: 1·9호선 노량진 인근 | D10: 본동 래미안트윈파크 (32평형) | E10: 84 | F10: 24.2 | G10: 리치고 2026.9.3 시세 32평형 24.2억(AI 추정 성격, 호갱노노 수치와 상충). 노량진뉴타운 신규 분양가는 84㎡ 약 25.5억 | H10: 낮음(자료 상충) | I10: =JeonseRate -> 0.52 | J10: =F10*I10 -> 12.584 | K10: =F10-J10 -> 11.616 | L10: =F10*Gongsi -> 16.698 | M10: =MIN(LTV*F10,LOOKUP(F10,LoanLo,LoanCap)) -> 4 | N10: =F10*IF(F10<=6,0.01,IF(F10<=9,(F10*2/3-3)/100,0.03))*(1+EduAcq)+IF(E10>85,F10*NongAcqRate,0) -> 0.7986 | O10: =F10*LOOKUP(F10,FeeLo,FeeR)*(1+VAT)+EtcBuy -> 0.20634 | P10: =F10-M10+N10+O10 -> 21.20494 | Q10: =IF(P10<=Eq1,"가능","부족 "&TEXT(P10-Eq1,"0.0")&"억") -> 부족 9.2억 | R10: =IF(P10<=Eq2,"가능","부족 "&TEXT(P10-Eq2,"0.0")&"억") -> 부족 7.2억 | S10: =IF(P10<=Eq3,"가능","부족 "&TEXT(P10-Eq3,"0.0")&"억") -> 부족 5.2억 | T10: =-PMT(Rm,LoanYears*12,M10)*10000 -> 190.96612 | U10: =-PMT((Rate+Stress)/12,LoanYears*12,M10)*12/DSR -> 0.79836299 | V10: =SUMIFS(Sch_Total,Sch_Idx,A10,Sch_Scen,2,Sch_Year,1)*10000 -> 714.6936
A11: 6 | B11: 흑석 | C11: 9호선 흑석 | D11: 흑석 아크로리버하임 84.75㎡ | E11: 84.75 | F11: 28.75 | G11: KB시세 일반가 28.75억(2026.9.11). 최근 실거래 25.1억(2025.10), 호가 29.5억~ | H11: 중(KB시세) | I11: =JeonseRate -> 0.52 | J11: =F11*I11 -> 14.95 | K11: =F11-J11 -> 13.8 | L11: =F11*Gongsi -> 19.8375 | M11: =MIN(LTV*F11,LOOKUP(F11,LoanLo,LoanCap)) -> 2 | N11: =F11*IF(F11<=6,0.01,IF(F11<=9,(F11*2/3-3)/100,0.03))*(1+EduAcq)+IF(E11>85,F11*NongAcqRate,0) -> 0.94875 | O11: =F11*LOOKUP(F11,FeeLo,FeeR)*(1+VAT)+EtcBuy -> 0.241375 | P11: =F11-M11+N11+O11 -> 27.940125 | Q11: =IF(P11<=Eq1,"가능","부족 "&TEXT(P11-Eq1,"0.0")&"억") -> 부족 15.9억 | R11: =IF(P11<=Eq2,"가능","부족 "&TEXT(P11-Eq2,"0.0")&"억") -> 부족 13.9억 | S11: =IF(P11<=Eq3,"가능","부족 "&TEXT(P11-Eq3,"0.0")&"억") -> 부족 11.9억 | T11: =-PMT(Rm,LoanYears*12,M11)*10000 -> 95.483059 | U11: =-PMT((Rate+Stress)/12,LoanYears*12,M11)*12/DSR -> 0.3991815 | V11: =SUMIFS(Sch_Total,Sch_Idx,A11,Sch_Scen,2,Sch_Year,1)*10000 -> 985.365
A12: 7 | B12: (사용자 입력) | C12: (입력) | D12: 예시 행: 직접 입력 | E12: 84 | F12: 14 | G12: 예시값입니다. 실제 단지로 바꿔 쓰세요 | H12: 예시 | I12: =JeonseRate -> 0.52 | J12: =F12*I12 -> 7.28 | K12: =F12-J12 -> 6.72 | L12: =F12*Gongsi -> 9.66 | M12: =MIN(LTV*F12,LOOKUP(F12,LoanLo,LoanCap)) -> 5.6 | N12: =F12*IF(F12<=6,0.01,IF(F12<=9,(F12*2/3-3)/100,0.03))*(1+EduAcq)+IF(E12>85,F12*NongAcqRate,0) -> 0.462 | O12: =F12*LOOKUP(F12,FeeLo,FeeR)*(1+VAT)+EtcBuy -> 0.1124 | P12: =F12-M12+N12+O12 -> 8.9744 | Q12: =IF(P12<=Eq1,"가능","부족 "&TEXT(P12-Eq1,"0.0")&"억") -> 가능 | R12: =IF(P12<=Eq2,"가능","부족 "&TEXT(P12-Eq2,"0.0")&"억") -> 가능 | S12: =IF(P12<=Eq3,"가능","부족 "&TEXT(P12-Eq3,"0.0")&"억") -> 가능 | T12: =-PMT(Rm,LoanYears*12,M12)*10000 -> 267.35257 | U12: =-PMT((Rate+Stress)/12,LoanYears*12,M12)*12/DSR -> 1.1177082 | V12: =SUMIFS(Sch_Total,Sch_Idx,A12,Sch_Scen,2,Sch_Year,1)*10000 -> 283.752

Sheet 시뮬레이션
A1: 3단계 시뮬레이션 – 취득 → 보유 → 양도, 손익 (억 원)
A2: 순이익 = 시세차익 − 취득세 − 매수비용 − 매도중개 − 대출이자 − 보유세 누계 − 양도세. 양도차익에서는 취득세·중개 등을 필요경비로 공제. 주거비 절감·임대수익은 미반영.
A4: 단지번호 | B4: 단지 | C4: 시나리오 | D4: 상승률 | E4: 보유(년) | F4: 거주(년) | G4: 매수가 | H4: ① 취득세 등 | I4: 매수비용 | J4: 대출 | K4: 투자금(자기자본+비용) | L4: 매도가 | M4: 매도 중개 | N4: 대출이자 누계 | O4: 대출 잔액 | P4: ② 보유세 누계 | Q4: 필요경비 | R4: 양도차익 | S4: 과세대상 차익 | T4: 장특공 공제율 | U4: 양도소득금액 | V4: 과세표준 | W4: ③ 양도세(지방세 포함) | X4: 세금 합계(①+②+③) | Y4: 세후 순이익 | Z4: 투자금 대비 수익률 | AA4: 연환산(단순) | AB4: 매도 후 회수금 | AC4: 회수율(배) | AD4: 예금 대안수익(세후) | AE4: 초과수익(순이익−대안)
A5: 1 | B5: =INDEX(C_Name,A5) -> 문래동 대단지 (단지 미특정, 입력 필요) | C5: 1 | D5: =CHOOSE(C5,G1,G2,G3) -> 0.02 | E5: 3 | F5: =MAX(0,E5-NonRes) -> 3 | G5: =INDEX(C_Price,A5) -> 12.5 | H5: =INDEX(C_Acq,A5) -> 0.4125 | I5: =INDEX(C_Fee,A5) -> 0.1025 | J5: =INDEX(C_Loan,A5) -> 5 | K5: =G5-J5+H5+I5 -> 8.015 | L5: =G5*(1+D5)^E5 -> 13.2651 | M5: =L5*LOOKUP(L5,FeeLo,FeeR)*(1+VAT) -> 0.08754966 | N5: =-CUMIPMT(Rm,LoanYears*12,J5,1,E5*12,0) -> 0.58428381 | O5: =J5*(1+Rm)^(E5*12)-(J5*Rm/(1-(1+Rm)^(-LoanYears*12)))*((1+Rm)^(E5*12)-1)/Rm -> 4.7249363 | P5: =SUMIFS(Sch_Total,Sch_Idx,A5,Sch_Scen,C5,Sch_Year,"<="&E5) -> 0.066010392 | Q5: =H5+I5+M5 -> 0.60254966 | R5: =L5-G5-Q5 -> 0.16255034 | S5: =MAX(0,IF(F5>=2,IF(L5>Exempt,R5*(L5-Exempt)/L5,0),R5)) -> 0.015502517 | T5: =IF(F5>=2,MIN(MaxDed,MIN(0.4,HoldRate*E5)+MIN(0.4,LiveRate*F5)),IF(E5>=3,MIN(0.3,0.02*E5),0)) -> 0.24 | U5: =S5*(1-T5) -> 0.011781913 | V5: =MAX(0,U5-InitDed) -> 0 | W5: =SUMPRODUCT((V5>CLo)*(V5-CLo)*CD)*(1+LocalTax) -> 0 | X5: =H5+P5+W5 -> 0.47851039 | Y5: =(L5-G5)-H5-I5-M5-N5-P5-W5 -> -0.48774386 | Z5: =Y5/K5 -> -0.060853882 | AA5: =IF(1+Z5>0,(1+Z5)^(1/E5)-1,-1) -> -0.020710595 | AB5: =L5-O5-M5-W5 -> 8.4526141 | AC5: =AB5/K5 -> 1.0545994 | AD5: =K5*((1+DepRate*(1-DepTax))^E5-1) -> 0.62588158 | AE5: =Y5-AD5 -> -1.1136254
A6: 1 | B6: =INDEX(C_Name,A6) -> 문래동 대단지 (단지 미특정, 입력 필요) | C6: 1 | D6: =CHOOSE(C6,G1,G2,G3) -> 0.02 | E6: 5 | F6: =MAX(0,E6-NonRes) -> 5 | G6: =INDEX(C_Price,A6) -> 12.5 | H6: =INDEX(C_Acq,A6) -> 0.4125 | I6: =INDEX(C_Fee,A6) -> 0.1025 | J6: =INDEX(C_Loan,A6) -> 5 | K6: =G6-J6+H6+I6 -> 8.015 | L6: =G6*(1+D6)^E6 -> 13.80101 | M6: =L6*LOOKUP(L6,FeeLo,FeeR)*(1+VAT) -> 0.091086666 | N6: =-CUMIPMT(Rm,LoanYears*12,J6,1,E6*12,0) -> 0.95462154 | O6: =J6*(1+Rm)^(E6*12)-(J6*Rm/(1-(1+Rm)^(-LoanYears*12)))*((1+Rm)^(E6*12)-1)/Rm -> 4.5223757 | P6: =SUMIFS(Sch_Total,Sch_Idx,A6,Sch_Scen,C6,Sch_Year,"<="&E6) -> 0.11966909 | Q6: =H6+I6+M6 -> 0.60608667 | R6: =L6-G6-Q6 -> 0.69492337 | S6: =MAX(0,IF(F6>=2,IF(L6>Exempt,R6*(L6-Exempt)/L6,0),R6)) -> 0.090686404 | T6: =IF(F6>=2,MIN(MaxDed,MIN(0.4,HoldRate*E6)+MIN(0.4,LiveRate*F6)),IF(E6>=3,MIN(0.3,0.02*E6),0)) -> 0.4 | U6: =S6*(1-T6) -> 0.054411842 | V6: =MAX(0,U6-InitDed) -> 0.029411842 | W6: =SUMPRODUCT((V6>CLo)*(V6-CLo)*CD)*(1+LocalTax) -> 0.0019411816 | X6: =H6+P6+W6 -> 0.53411027 | Y6: =(L6-G6)-H6-I6-M6-N6-P6-W6 -> -0.38130844 | Z6: =Y6/K6 -> -0.047574353 | AA6: =IF(1+Z6>0,(1+Z6)^(1/E6)-1,-1) -> -0.0097012831 | AB6: =L6-O6-M6-W6 -> 9.1856065 | AC6: =AB6/K6 -> 1.146052 | AD6: =K6*((1+DepRate*(1-DepTax))^E6-1) -> 1.0700587 | AE6: =Y6-AD6 -> -1.4513671
A7: 1 | B7: =INDEX(C_Name,A7) -> 문래동 대단지 (단지 미특정, 입력 필요) | C7: 1 | D7: =CHOOSE(C7,G1,G2,G3) -> 0.02 | E7: 7 | F7: =MAX(0,E7-NonRes) -> 7 | G7: =INDEX(C_Price,A7) -> 12.5 | H7: =INDEX(C_Acq,A7) -> 0.4125 | I7: =INDEX(C_Fee,A7) -> 0.1025 | J7: =INDEX(C_Loan,A7) -> 5 | K7: =G7-J7+H7+I7 -> 8.015 | L7: =G7*(1+D7)^E7 -> 14.358571 | M7: =L7*LOOKUP(L7,FeeLo,FeeR)*(1+VAT) -> 0.094766568 | N7: =-CUMIPMT(Rm,LoanYears*12,J7,1,E7*12,0) -> 1.3081178 | O7: =J7*(1+Rm)^(E7*12)-(J7*Rm/(1-(1+Rm)^(-LoanYears*12)))*((1+Rm)^(E7*12)-1)/Rm -> 4.3029735 | P7: =SUMIFS(Sch_Total,Sch_Idx,A7,Sch_Scen,C7,Sch_Year,"<="&E7) -> 0.17610644 | Q7: =H7+I7+M7 -> 0.60976657 | R7: =L7-G7-Q7 -> 1.2488043 | S7: =MAX(0,IF(F7>=2,IF(L7>Exempt,R7*(L7-Exempt)/L7,0),R7)) -> 0.20513137 | T7: =IF(F7>=2,MIN(MaxDed,MIN(0.4,HoldRate*E7)+MIN(0.4,LiveRate*F7)),IF(E7>=3,MIN(0.3,0.02*E7),0)) -> 0.56 | U7: =S7*(1-T7) -> 0.090257804 | V7: =MAX(0,U7-InitDed) -> 0.065257804 | W7: =SUMPRODUCT((V7>CLo)*(V7-CLo)*CD)*(1+LocalTax) -> 0.0043070151 | X7: =H7+P7+W7 -> 0.59291346 | Y7: =(L7-G7)-H7-I7-M7-N7-P7-W7 -> -0.23972696 | Z7: =Y7/K7 -> -0.02990979 | AA7: =IF(1+Z7>0,(1+Z7)^(1/E7)-1,-1) -> -0.0043286345 | AB7: =L7-O7-M7-W7 -> 9.9565237 | AC7: =AB7/K7 -> 1.2422363 | AD7: =K7*((1+DepRate*(1-DepTax))^E7-1) -> 1.5370684 | AE7: =Y7-AD7 -> -1.7767953
A8: 1 | B8: =INDEX(C_Name,A8) -> 문래동 대단지 (단지 미특정, 입력 필요) | C8: 1 | D8: =CHOOSE(C8,G1,G2,G3) -> 0.02 | E8: 10 | F8: =MAX(0,E8-NonRes) -> 10 | G8: =INDEX(C_Price,A8) -> 12.5 | H8: =INDEX(C_Acq,A8) -> 0.4125 | I8: =INDEX(C_Fee,A8) -> 0.1025 | J8: =INDEX(C_Loan,A8) -> 5 | K8: =G8-J8+H8+I8 -> 8.015 | L8: =G8*(1+D8)^E8 -> 15.23743 | M8: =L8*LOOKUP(L8,FeeLo,FeeR)*(1+VAT) -> 0.11732821 | N8: =-CUMIPMT(Rm,LoanYears*12,J8,1,E8*12,0) -> 1.8036897 | O8: =J8*(1+Rm)^(E8*12)-(J8*Rm/(1-(1+Rm)^(-LoanYears*12)))*((1+Rm)^(E8*12)-1)/Rm -> 3.939198 | P8: =SUMIFS(Sch_Total,Sch_Idx,A8,Sch_Scen,C8,Sch_Year,"<="&E8) -> 0.26621926 | Q8: =H8+I8+M8 -> 0.63232821 | R8: =L8-G8-Q8 -> 2.105102 | S8: =MAX(0,IF(F8>=2,IF(L8>Exempt,R8*(L8-Exempt)/L8,0),R8)) -> 0.44726183 | T8: =IF(F8>=2,MIN(MaxDed,MIN(0.4,HoldRate*E8)+MIN(0.4,LiveRate*F8)),IF(E8>=3,MIN(0.3,0.02*E8),0)) -> 0.8 | U8: =S8*(1-T8) -> 0.089452367 | V8: =MAX(0,U8-InitDed) -> 0.064452367 | W8: =SUMPRODUCT((V8>CLo)*(V8-CLo)*CD)*(1+LocalTax) -> 0.0042538562 | X8: =H8+P8+W8 -> 0.68297311 | Y8: =(L8-G8)-H8-I8-M8-N8-P8-W8 -> 0.030939191 | Z8: =Y8/K8 -> 0.0038601611 | AA8: =IF(1+Z8>0,(1+Z8)^(1/E8)-1,-1) -> 0.00038534721 | AB8: =L8-O8-M8-W8 -> 11.17665 | AC8: =AB8/K8 -> 1.3944667 | AD8: =K8*((1+DepRate*(1-DepTax))^E8-1) -> 2.2829778 | AE8: =Y8-AD8 -> -2.2520386
A9: 1 | B9: =INDEX(C_Name,A9) -> 문래동 대단지 (단지 미특정, 입력 필요) | C9: 2 | D9: =CHOOSE(C9,G1,G2,G3) -> 0.04 | E9: 3 | F9: =MAX(0,E9-NonRes) -> 3 | G9: =INDEX(C_Price,A9) -> 12.5 | H9: =INDEX(C_Acq,A9) -> 0.4125 | I9: =INDEX(C_Fee,A9) -> 0.1025 | J9: =INDEX(C_Loan,A9) -> 5 | K9: =G9-J9+H9+I9 -> 8.015 | L9: =G9*(1+D9)^E9 -> 14.0608 | M9: =L9*LOOKUP(L9,FeeLo,FeeR)*(1+VAT) -> 0.09280128 | N9: =-CUMIPMT(Rm,LoanYears*12,J9,1,E9*12,0) -> 0.58428381 | O9: =J9*(1+Rm)^(E9*12)-(J9*Rm/(1-(1+Rm)^(-LoanYears*12)))*((1+Rm)^(E9*12)-1)/Rm -> 4.7249363 | P9: =SUMIFS(Sch_Total,Sch_Idx,A9,Sch_Scen,C9,Sch_Year,"<="&E9) -> 0.071142336 | Q9: =H9+I9+M9 -> 0.60780128 | R9: =L9-G9-Q9 -> 0.95299872 | S9: =MAX(0,IF(F9>=2,IF(L9>Exempt,R9*(L9-Exempt)/L9,0),R9)) -> 0.13967482 | T9: =IF(F9>=2,MIN(MaxDed,MIN(0.4,HoldRate*E9)+MIN(0.4,LiveRate*F9)),IF(E9>=3,MIN(0.3,0.02*E9),0)) -> 0.24 | U9: =S9*(1-T9) -> 0.10615287 | V9: =MAX(0,U9-InitDed) -> 0.081152866 | W9: =SUMPRODUCT((V9>CLo)*(V9-CLo)*CD)*(1+LocalTax) -> 0.0053560892 | X9: =H9+P9+W9 -> 0.48899843 | Y9: =(L9-G9)-H9-I9-M9-N9-P9-W9 -> 0.29221648 | Z9: =Y9/K9 -> 0.0364587 | AA9: =IF(1+Z9>0,(1+Z9)^(1/E9)-1,-1) -> 0.012008128 | AB9: =L9-O9-M9-W9 -> 9.2377064 | AC9: =AB9/K9 -> 1.1525523 | AD9: =K9*((1+DepRate*(1-DepTax))^E9-1) -> 0.62588158 | AE9: =Y9-AD9 -> -0.3336651
A10: 1 | B10: =INDEX(C_Name,A10) -> 문래동 대단지 (단지 미특정, 입력 필요) | C10: 2 | D10: =CHOOSE(C10,G1,G2,G3) -> 0.04 | E10: 5 | F10: =MAX(0,E10-NonRes) -> 5 | G10: =INDEX(C_Price,A10) -> 12.5 | H10: =INDEX(C_Acq,A10) -> 0.4125 | I10: =INDEX(C_Fee,A10) -> 0.1025 | J10: =INDEX(C_Loan,A10) -> 5 | K10: =G10-J10+H10+I10 -> 8.015 | L10: =G10*(1+D10)^E10 -> 15.208161 | M10: =L10*LOOKUP(L10,FeeLo,FeeR)*(1+VAT) -> 0.11710284 | N10: =-CUMIPMT(Rm,LoanYears*12,J10,1,E10*12,0) -> 0.95462154 | O10: =J10*(1+Rm)^(E10*12)-(J10*Rm/(1-(1+Rm)^(-LoanYears*12)))*((1+Rm)^(E10*12)-1)/Rm -> 4.5223757 | P10: =SUMIFS(Sch_Total,Sch_Idx,A10,Sch_Scen,C10,Sch_Year,"<="&E10) -> 0.12964851 | Q10: =H10+I10+M10 -> 0.63210284 | R10: =L10-G10-Q10 -> 2.0760584 | S10: =MAX(0,IF(F10>=2,IF(L10>Exempt,R10*(L10-Exempt)/L10,0),R10)) -> 0.43794448 | T10: =IF(F10>=2,MIN(MaxDed,MIN(0.4,HoldRate*E10)+MIN(0.4,LiveRate*F10)),IF(E10>=3,MIN(0.3,0.02*E10),0)) -> 0.4 | U10: =S10*(1-T10) -> 0.26276669 | V10: =MAX(0,U10-InitDed) -> 0.23776669 | W10: =SUMPRODUCT((V10>CLo)*(V10-CLo)*CD)*(1+LocalTax) -> 0.025371504 | X10: =H10+P10+W10 -> 0.56752001 | Y10: =(L10-G10)-H10-I10-M10-N10-P10-W10 -> 0.96641688 | Z10: =Y10/K10 -> 0.12057603 | AA10: =IF(1+Z10>0,(1+Z10)^(1/E10)-1,-1) -> 0.023029756 | AB10: =L10-O10-M10-W10 -> 10.543311 | AC10: =AB10/K10 -> 1.3154474 | AD10: =K10*((1+DepRate*(1-DepTax))^E10-1) -> 1.0700587 | AE10: =Y10-AD10 -> -0.10364183
A11: 1 | B11: =INDEX(C_Name,A11) -> 문래동 대단지 (단지 미특정, 입력 필요) | C11: 2 | D11: =CHOOSE(C11,G1,G2,G3) -> 0.04 | E11: 7 | F11: =MAX(0,E11-NonRes) -> 7 | G11: =INDEX(C_Price,A11) -> 12.5 | H11: =INDEX(C_Acq,A11) -> 0.4125 | I11: =INDEX(C_Fee,A11) -> 0.1025 | J11: =INDEX(C_Loan,A11) -> 5 | K11: =G11-J11+H11+I11 -> 8.015 | L11: =G11*(1+D11)^E11 -> 16.449147 | M11: =L11*LOOKUP(L11,FeeLo,FeeR)*(1+VAT) -> 0.12665843 | N11: =-CUMIPMT(Rm,LoanYears*12,J11,1,E11*12,0) -> 1.3081178 | O11: =J11*(1+Rm)^(E11*12)-(J11*Rm/(1-(1+Rm)^(-LoanYears*12)))*((1+Rm)^(E11*12)-1)/Rm -> 4.3029735 | P11: =SUMIFS(Sch_Total,Sch_Idx,A11,Sch_Scen,C11,Sch_Year,"<="&E11) -> 0.19416258 | Q11: =H11+I11+M11 -> 0.64165843 | R11: =L11-G11-Q11 -> 3.3074888 | S11: =MAX(0,IF(F11>=2,IF(L11>Exempt,R11*(L11-Exempt)/L11,0),R11)) -> 0.89460593 | T11: =IF(F11>=2,MIN(MaxDed,MIN(0.4,HoldRate*E11)+MIN(0.4,LiveRate*F11)),IF(E11>=3,MIN(0.3,0.02*E11),0)) -> 0.56 | U11: =S11*(1-T11) -> 0.39362661 | V11: =MAX(0,U11-InitDed) -> 0.36862661 | W11: =SUMPRODUCT((V11>CLo)*(V11-CLo)*CD)*(1+LocalTax) -> 0.046963391 | X11: =H11+P11+W11 -> 0.65362597 | Y11: =(L11-G11)-H11-I11-M11-N11-P11-W11 -> 1.7582451 | Z11: =Y11/K11 -> 0.21936931 | AA11: =IF(1+Z11>0,(1+Z11)^(1/E11)-1,-1) -> 0.028738604 | AB11: =L11-O11-M11-W11 -> 11.972552 | AC11: =AB11/K11 -> 1.4937682 | AD11: =K11*((1+DepRate*(1-DepTax))^E11-1) -> 1.5370684 | AE11: =Y11-AD11 -> 0.22117667
A12: 1 | B12: =INDEX(C_Name,A12) -> 문래동 대단지 (단지 미특정, 입력 필요) | C12: 2 | D12: =CHOOSE(C12,G1,G2,G3) -> 0.04 | E12: 10 | F12: =MAX(0,E12-NonRes) -> 10 | G12: =INDEX(C_Price,A12) -> 12.5 | H12: =INDEX(C_Acq,A12) -> 0.4125 | I12: =INDEX(C_Fee,A12) -> 0.1025 | J12: =INDEX(C_Loan,A12) -> 5 | K12: =G12-J12+H12+I12 -> 8.015 | L12: =G12*(1+D12)^E12 -> 18.503054 | M12: =L12*LOOKUP(L12,FeeLo,FeeR)*(1+VAT) -> 0.14247351 | N12: =-CUMIPMT(Rm,LoanYears*12,J12,1,E12*12,0) -> 1.8036897 | O12: =J12*(1+Rm)^(E12*12)-(J12*Rm/(1-(1+Rm)^(-LoanYears*12)))*((1+Rm)^(E12*12)-1)/Rm -> 3.939198 | P12: =SUMIFS(Sch_Total,Sch_Idx,A12,Sch_Scen,C12,Sch_Year,"<="&E12) -> 0.30427558 | Q12: =H12+I12+M12 -> 0.65747351 | R12: =L12-G12-Q12 -> 5.34558 | S12: =MAX(0,IF(F12>=2,IF(L12>Exempt,R12*(L12-Exempt)/L12,0),R12)) -> 1.878749 | T12: =IF(F12>=2,MIN(MaxDed,MIN(0.4,HoldRate*E12)+MIN(0.4,LiveRate*F12)),IF(E12>=3,MIN(0.3,0.02*E12),0)) -> 0.8 | U12: =S12*(1-T12) -> 0.3757498 | V12: =MAX(0,U12-InitDed) -> 0.3507498 | W12: =SUMPRODUCT((V12>CLo)*(V12-CLo)*CD)*(1+LocalTax) -> 0.044013717 | X12: =H12+P12+W12 -> 0.7607893 | Y12: =(L12-G12)-H12-I12-M12-N12-P12-W12 -> 3.193601 | Z12: =Y12/K12 -> 0.39845303 | AA12: =IF(1+Z12>0,(1+Z12)^(1/E12)-1,-1) -> 0.034105358 | AB12: =L12-O12-M12-W12 -> 14.377368 | AC12: =AB12/K12 -> 1.7938077 | AD12: =K12*((1+DepRate*(1-DepTax))^E12-1) -> 2.2829778 | AE12: =Y12-AD12 -> 0.91062326
A13: 1 | B13: =INDEX(C_Name,A13) -> 문래동 대단지 (단지 미특정, 입력 필요) | C13: 3 | D13: =CHOOSE(C13,G1,G2,G3) -> 0.06 | E13: 3 | F13: =MAX(0,E13-NonRes) -> 3 | G13: =INDEX(C_Price,A13) -> 12.5 | H13: =INDEX(C_Acq,A13) -> 0.4125 | I13: =INDEX(C_Fee,A13) -> 0.1025 | J13: =INDEX(C_Loan,A13) -> 5 | K13: =G13-J13+H13+I13 -> 8.015 | L13: =G13*(1+D13)^E13 -> 14.8877 | M13: =L13*LOOKUP(L13,FeeLo,FeeR)*(1+VAT) -> 0.09825882 | N13: =-CUMIPMT(Rm,LoanYears*12,J13,1,E13*12,0) -> 0.58428381 | O13: =J13*(1+Rm)^(E13*12)-(J13*Rm/(1-(1+Rm)^(-LoanYears*12)))*((1+Rm)^(E13*12)-1)/Rm -> 4.7249363 | P13: =SUMIFS(Sch_Total,Sch_Idx,A13,Sch_Scen,C13,Sch_Year,"<="&E13) -> 0.076360806 | Q13: =H13+I13+M13 -> 0.61325882 | R13: =L13-G13-Q13 -> 1.7744412 | S13: =MAX(0,IF(F13>=2,IF(L13>Exempt,R13*(L13-Exempt)/L13,0),R13)) -> 0.34418035 | T13: =IF(F13>=2,MIN(MaxDed,MIN(0.4,HoldRate*E13)+MIN(0.4,LiveRate*F13)),IF(E13>=3,MIN(0.3,0.02*E13),0)) -> 0.24 | U13: =S13*(1-T13) -> 0.26157707 | V13: =MAX(0,U13-InitDed) -> 0.23657707 | W13: =SUMPRODUCT((V13>CLo)*(V13-CLo)*CD)*(1+LocalTax) -> 0.025175216 | X13: =H13+P13+W13 -> 0.51403602 | Y13: =(L13-G13)-H13-I13-M13-N13-P13-W13 -> 1.0886213 | Z13: =Y13/K13 -> 0.135823 | AA13: =IF(1+Z13>0,(1+Z13)^(1/E13)-1,-1) -> 0.043366495 | AB13: =L13-O13-M13-W13 -> 10.03933 | AC13: =AB13/K13 -> 1.2525676 | AD13: =K13*((1+DepRate*(1-DepTax))^E13-1) -> 0.62588158 | AE13: =Y13-AD13 -> 0.46273976
A14: 1 | B14: =INDEX(C_Name,A14) -> 문래동 대단지 (단지 미특정, 입력 필요) | C14: 3 | D14: =CHOOSE(C14,G1,G2,G3) -> 0.06 | E14: 5 | F14: =MAX(0,E14-NonRes) -> 5 | G14: =INDEX(C_Price,A14) -> 12.5 | H14: =INDEX(C_Acq,A14) -> 0.4125 | I14: =INDEX(C_Fee,A14) -> 0.1025 | J14: =INDEX(C_Loan,A14) -> 5 | K14: =G14-J14+H14+I14 -> 8.015 | L14: =G14*(1+D14)^E14 -> 16.72782 | M14: =L14*LOOKUP(L14,FeeLo,FeeR)*(1+VAT) -> 0.12880421 | N14: =-CUMIPMT(Rm,LoanYears*12,J14,1,E14*12,0) -> 0.95462154 | O14: =J14*(1+Rm)^(E14*12)-(J14*Rm/(1-(1+Rm)^(-LoanYears*12)))*((1+Rm)^(E14*12)-1)/Rm -> 4.5223757 | P14: =SUMIFS(Sch_Total,Sch_Idx,A14,Sch_Scen,C14,Sch_Year,"<="&E14) -> 0.13996113 | Q14: =H14+I14+M14 -> 0.64380421 | R14: =L14-G14-Q14 -> 3.5840155 | S14: =MAX(0,IF(F14>=2,IF(L14>Exempt,R14*(L14-Exempt)/L14,0),R14)) -> 1.012958 | T14: =IF(F14>=2,MIN(MaxDed,MIN(0.4,HoldRate*E14)+MIN(0.4,LiveRate*F14)),IF(E14>=3,MIN(0.3,0.02*E14),0)) -> 0.4 | U14: =S14*(1-T14) -> 0.60777481 | V14: =MAX(0,U14-InitDed) -> 0.58277481 | W14: =SUMPRODUCT((V14>CLo)*(V14-CLo)*CD)*(1+LocalTax) -> 0.090492551 | X14: =H14+P14+W14 -> 0.64295368 | Y14: =(L14-G14)-H14-I14-M14-N14-P14-W14 -> 2.3989403 | Z14: =Y14/K14 -> 0.29930634 | AA14: =IF(1+Z14>0,(1+Z14)^(1/E14)-1,-1) -> 0.053761461 | AB14: =L14-O14-M14-W14 -> 11.986147 | AC14: =AB14/K14 -> 1.4954644 | AD14: =K14*((1+DepRate*(1-DepTax))^E14-1) -> 1.0700587 | AE14: =Y14-AD14 -> 1.3288816
A15: 1 | B15: =INDEX(C_Name,A15) -> 문래동 대단지 (단지 미특정, 입력 필요) | C15: 3 | D15: =CHOOSE(C15,G1,G2,G3) -> 0.06 | E15: 7 | F15: =MAX(0,E15-NonRes) -> 7 | G15: =INDEX(C_Price,A15) -> 12.5 | H15: =INDEX(C_Acq,A15) -> 0.4125 | I15: =INDEX(C_Fee,A15) -> 0.1025 | J15: =INDEX(C_Loan,A15) -> 5 | K15: =G15-J15+H15+I15 -> 8.015 | L15: =G15*(1+D15)^E15 -> 18.795378 | M15: =L15*LOOKUP(L15,FeeLo,FeeR)*(1+VAT) -> 0.14472441 | N15: =-CUMIPMT(Rm,LoanYears*12,J15,1,E15*12,0) -> 1.3081178 | O15: =J15*(1+Rm)^(E15*12)-(J15*Rm/(1-(1+Rm)^(-LoanYears*12)))*((1+Rm)^(E15*12)-1)/Rm -> 4.3029735 | P15: =SUMIFS(Sch_Total,Sch_Idx,A15,Sch_Scen,C15,Sch_Year,"<="&E15) -> 0.2141363 | Q15: =H15+I15+M15 -> 0.65972441 | R15: =L15-G15-Q15 -> 5.6356538 | S15: =MAX(0,IF(F15>=2,IF(L15>Exempt,R15*(L15-Exempt)/L15,0),R15)) -> 2.0375434 | T15: =IF(F15>=2,MIN(MaxDed,MIN(0.4,HoldRate*E15)+MIN(0.4,LiveRate*F15)),IF(E15>=3,MIN(0.3,0.02*E15),0)) -> 0.56 | U15: =S15*(1-T15) -> 0.89651911 | V15: =MAX(0,U15-InitDed) -> 0.87151911 | W15: =SUMPRODUCT((V15>CLo)*(V15-CLo)*CD)*(1+LocalTax) -> 0.16672104 | X15: =H15+P15+W15 -> 0.79335734 | Y15: =(L15-G15)-H15-I15-M15-N15-P15-W15 -> 3.9466787 | Z15: =Y15/K15 -> 0.49241157 | AA15: =IF(1+Z15>0,(1+Z15)^(1/E15)-1,-1) -> 0.058866551 | AB15: =L15-O15-M15-W15 -> 14.180959 | AC15: =AB15/K15 -> 1.7693025 | AD15: =K15*((1+DepRate*(1-DepTax))^E15-1) -> 1.5370684 | AE15: =Y15-AD15 -> 2.4096103
A16: 1 | B16: =INDEX(C_Name,A16) -> 문래동 대단지 (단지 미특정, 입력 필요) | C16: 3 | D16: =CHOOSE(C16,G1,G2,G3) -> 0.06 | E16: 10 | F16: =MAX(0,E16-NonRes) -> 10 | G16: =INDEX(C_Price,A16) -> 12.5 | H16: =INDEX(C_Acq,A16) -> 0.4125 | I16: =INDEX(C_Fee,A16) -> 0.1025 | J16: =INDEX(C_Loan,A16) -> 5 | K16: =G16-J16+H16+I16 -> 8.015 | L16: =G16*(1+D16)^E16 -> 22.385596 | M16: =L16*LOOKUP(L16,FeeLo,FeeR)*(1+VAT) -> 0.17236909 | N16: =-CUMIPMT(Rm,LoanYears*12,J16,1,E16*12,0) -> 1.8036897 | O16: =J16*(1+Rm)^(E16*12)-(J16*Rm/(1-(1+Rm)^(-LoanYears*12)))*((1+Rm)^(E16*12)-1)/Rm -> 3.939198 | P16: =SUMIFS(Sch_Total,Sch_Idx,A16,Sch_Scen,C16,Sch_Year,"<="&E16) -> 0.36408085 | Q16: =H16+I16+M16 -> 0.68736909 | R16: =L16-G16-Q16 -> 9.1982271 | S16: =MAX(0,IF(F16>=2,IF(L16>Exempt,R16*(L16-Exempt)/L16,0),R16)) -> 4.2674348 | T16: =IF(F16>=2,MIN(MaxDed,MIN(0.4,HoldRate*E16)+MIN(0.4,LiveRate*F16)),IF(E16>=3,MIN(0.3,0.02*E16),0)) -> 0.8 | U16: =S16*(1-T16) -> 0.85348696 | V16: =MAX(0,U16-InitDed) -> 0.82848696 | W16: =SUMPRODUCT((V16>CLo)*(V16-CLo)*CD)*(1+LocalTax) -> 0.15536056 | X16: =H16+P16+W16 -> 0.93194141 | Y16: =(L16-G16)-H16-I16-M16-N16-P16-W16 -> 6.875096 | Z16: =Y16/K16 -> 0.85777866 | AA16: =IF(1+Z16>0,(1+Z16)^(1/E16)-1,-1) -> 0.063896541 | AB16: =L16-O16-M16-W16 -> 18.118669 | AC16: =AB16/K16 -> 2.260595 | AD16: =K16*((1+DepRate*(1-DepTax))^E16-1) -> 2.2829778 | AE16: =Y16-AD16 -> 4.5921182
A17: 2 | B17: =INDEX(C_Name,A17) -> 신길삼성래미안 84㎡ | C17: 1 | D17: =CHOOSE(C17,G1,G2,G3) -> 0.02 | E17: 3 | F17: =MAX(0,E17-NonRes) -> 3 | G17: =INDEX(C_Price,A17) -> 13 | H17: =INDEX(C_Acq,A17) -> 0.429 | I17: =INDEX(C_Fee,A17) -> 0.1058 | J17: =INDEX(C_Loan,A17) -> 5.2 | K17: =G17-J17+H17+I17 -> 8.3348 | L17: =G17*(1+D17)^E17 -> 13.795704 | M17: =L17*LOOKUP(L17,FeeLo,FeeR)*(1+VAT) -> 0.091051646 | N17: =-CUMIPMT(Rm,LoanYears*12,J17,1,E17*12,0) -> 0.60765516 | O17: =J17*(1+Rm)^(E17*12)-(J17*Rm/(1-(1+Rm)^(-LoanYears*12)))*((1+Rm)^(E17*12)-1)/Rm -> 4.9139337 | P17: =SUMIFS(Sch_Total,Sch_Idx,A17,Sch_Scen,C17,Sch_Year,"<="&E17) -> 0.076211451 | Q17: =H17+I17+M17 -> 0.62585165 | R17: =L17-G17-Q17 -> 0.16985235 | S17: =MAX(0,IF(F17>=2,IF(L17>Exempt,R17*(L17-Exempt)/L17,0),R17)) -> 0.022108662 | T17: =IF(F17>=2,MIN(MaxDed,MIN(0.4,HoldRate*E17)+MIN(0.4,LiveRate*F17)),IF(E17>=3,MIN(0.3,0.02*E17),0)) -> 0.24 | U17: =S17*(1-T17) -> 0.016802583 | V17: =MAX(0,U17-InitDed) -> 0 | W17: =SUMPRODUCT((V17>CLo)*(V17-CLo)*CD)*(1+LocalTax) -> 0 | X17: =H17+P17+W17 -> 0.50521145 | Y17: =(L17-G17)-H17-I17-M17-N17-P17-W17 -> -0.51401426 | Z17: =Y17/K17 -> -0.061670857 | AA17: =IF(1+Z17>0,(1+Z17)^(1/E17)-1,-1) -> -0.020994643 | AB17: =L17-O17-M17-W17 -> 8.7907186 | AC17: =AB17/K17 -> 1.0547006 | AD17: =K17*((1+DepRate*(1-DepTax))^E17-1) -> 0.65085438 | AE17: =Y17-AD17 -> -1.1648686
A18: 2 | B18: =INDEX(C_Name,A18) -> 신길삼성래미안 84㎡ | C18: 1 | D18: =CHOOSE(C18,G1,G2,G3) -> 0.02 | E18: 5 | F18: =MAX(0,E18-NonRes) -> 5 | G18: =INDEX(C_Price,A18) -> 13 | H18: =INDEX(C_Acq,A18) -> 0.429 | I18: =INDEX(C_Fee,A18) -> 0.1058 | J18: =INDEX(C_Loan,A18) -> 5.2 | K18: =G18-J18+H18+I18 -> 8.3348 | L18: =G18*(1+D18)^E18 -> 14.35305 | M18: =L18*LOOKUP(L18,FeeLo,FeeR)*(1+VAT) -> 0.094730133 | N18: =-CUMIPMT(Rm,LoanYears*12,J18,1,E18*12,0) -> 0.9928064 | O18: =J18*(1+Rm)^(E18*12)-(J18*Rm/(1-(1+Rm)^(-LoanYears*12)))*((1+Rm)^(E18*12)-1)/Rm -> 4.7032707 | P18: =SUMIFS(Sch_Total,Sch_Idx,A18,Sch_Scen,C18,Sch_Year,"<="&E18) -> 0.13262129 | Q18: =H18+I18+M18 -> 0.62953013 | R18: =L18-G18-Q18 -> 0.72352031 | S18: =MAX(0,IF(F18>=2,IF(L18>Exempt,R18*(L18-Exempt)/L18,0),R18)) -> 0.11861449 | T18: =IF(F18>=2,MIN(MaxDed,MIN(0.4,HoldRate*E18)+MIN(0.4,LiveRate*F18)),IF(E18>=3,MIN(0.3,0.02*E18),0)) -> 0.4 | U18: =S18*(1-T18) -> 0.071168695 | V18: =MAX(0,U18-InitDed) -> 0.046168695 | W18: =SUMPRODUCT((V18>CLo)*(V18-CLo)*CD)*(1+LocalTax) -> 0.0030471339 | X18: =H18+P18+W18 -> 0.56466843 | Y18: =(L18-G18)-H18-I18-M18-N18-P18-W18 -> -0.40495452 | Z18: =Y18/K18 -> -0.048585992 | AA18: =IF(1+Z18>0,(1+Z18)^(1/E18)-1,-1) -> -0.0099117459 | AB18: =L18-O18-M18-W18 -> 9.5520025 | AC18: =AB18/K18 -> 1.1460386 | AD18: =K18*((1+DepRate*(1-DepTax))^E18-1) -> 1.1127543 | AE18: =Y18-AD18 -> -1.5177088
A19: 2 | B19: =INDEX(C_Name,A19) -> 신길삼성래미안 84㎡ | C19: 1 | D19: =CHOOSE(C19,G1,G2,G3) -> 0.02 | E19: 7 | F19: =MAX(0,E19-NonRes) -> 7 | G19: =INDEX(C_Price,A19) -> 13 | H19: =INDEX(C_Acq,A19) -> 0.429 | I19: =INDEX(C_Fee,A19) -> 0.1058 | J19: =INDEX(C_Loan,A19) -> 5.2 | K19: =G19-J19+H19+I19 -> 8.3348 | L19: =G19*(1+D19)^E19 -> 14.932914 | M19: =L19*LOOKUP(L19,FeeLo,FeeR)*(1+VAT) -> 0.09855723 | N19: =-CUMIPMT(Rm,LoanYears*12,J19,1,E19*12,0) -> 1.3604425 | O19: =J19*(1+Rm)^(E19*12)-(J19*Rm/(1-(1+Rm)^(-LoanYears*12)))*((1+Rm)^(E19*12)-1)/Rm -> 4.4750925 | P19: =SUMIFS(Sch_Total,Sch_Idx,A19,Sch_Scen,C19,Sch_Year,"<="&E19) -> 0.19192094 | Q19: =H19+I19+M19 -> 0.63335723 | R19: =L19-G19-Q19 -> 1.2995564 | S19: =MAX(0,IF(F19>=2,IF(L19>Exempt,R19*(L19-Exempt)/L19,0),R19)) -> 0.25524067 | T19: =IF(F19>=2,MIN(MaxDed,MIN(0.4,HoldRate*E19)+MIN(0.4,LiveRate*F19)),IF(E19>=3,MIN(0.3,0.02*E19),0)) -> 0.56 | U19: =S19*(1-T19) -> 0.11230589 | V19: =MAX(0,U19-InitDed) -> 0.087305895 | W19: =SUMPRODUCT((V19>CLo)*(V19-CLo)*CD)*(1+LocalTax) -> 0.005762189 | X19: =H19+P19+W19 -> 0.62668313 | Y19: =(L19-G19)-H19-I19-M19-N19-P19-W19 -> -0.25856918 | Z19: =Y19/K19 -> -0.031022841 | AA19: =IF(1+Z19>0,(1+Z19)^(1/E19)-1,-1) -> -0.0044919153 | AB19: =L19-O19-M19-W19 -> 10.353502 | AC19: =AB19/K19 -> 1.2422016 | AD19: =K19*((1+DepRate*(1-DepTax))^E19-1) -> 1.5983977 | AE19: =Y19-AD19 -> -1.8569669
A20: 2 | B20: =INDEX(C_Name,A20) -> 신길삼성래미안 84㎡ | C20: 1 | D20: =CHOOSE(C20,G1,G2,G3) -> 0.02 | E20: 10 | F20: =MAX(0,E20-NonRes) -> 10 | G20: =INDEX(C_Price,A20) -> 13 | H20: =INDEX(C_Acq,A20) -> 0.429 | I20: =INDEX(C_Fee,A20) -> 0.1058 | J20: =INDEX(C_Loan,A20) -> 5.2 | K20: =G20-J20+H20+I20 -> 8.3348 | L20: =G20*(1+D20)^E20 -> 15.846927 | M20: =L20*LOOKUP(L20,FeeLo,FeeR)*(1+VAT) -> 0.12202134 | N20: =-CUMIPMT(Rm,LoanYears*12,J20,1,E20*12,0) -> 1.8758373 | O20: =J20*(1+Rm)^(E20*12)-(J20*Rm/(1-(1+Rm)^(-LoanYears*12)))*((1+Rm)^(E20*12)-1)/Rm -> 4.0967659 | P20: =SUMIFS(Sch_Total,Sch_Idx,A20,Sch_Scen,C20,Sch_Year,"<="&E20) -> 0.28654547 | Q20: =H20+I20+M20 -> 0.65682134 | R20: =L20-G20-Q20 -> 2.1901061 | S20: =MAX(0,IF(F20>=2,IF(L20>Exempt,R20*(L20-Exempt)/L20,0),R20)) -> 0.53166012 | T20: =IF(F20>=2,MIN(MaxDed,MIN(0.4,HoldRate*E20)+MIN(0.4,LiveRate*F20)),IF(E20>=3,MIN(0.3,0.02*E20),0)) -> 0.8 | U20: =S20*(1-T20) -> 0.10633202 | V20: =MAX(0,U20-InitDed) -> 0.081332024 | W20: =SUMPRODUCT((V20>CLo)*(V20-CLo)*CD)*(1+LocalTax) -> 0.0053679136 | X20: =H20+P20+W20 -> 0.72091338 | Y20: =(L20-G20)-H20-I20-M20-N20-P20-W20 -> 0.022355412 | Z20: =Y20/K20 -> 0.0026821774 | AA20: =IF(1+Z20>0,(1+Z20)^(1/E20)-1,-1) -> 0.00026789455 | AB20: =L20-O20-M20-W20 -> 11.622772 | AC20: =AB20/K20 -> 1.3944872 | AD20: =K20*((1+DepRate*(1-DepTax))^E20-1) -> 2.374069 | AE20: =Y20-AD20 -> -2.3517136
A21: 2 | B21: =INDEX(C_Name,A21) -> 신길삼성래미안 84㎡ | C21: 2 | D21: =CHOOSE(C21,G1,G2,G3) -> 0.04 | E21: 3 | F21: =MAX(0,E21-NonRes) -> 3 | G21: =INDEX(C_Price,A21) -> 13 | H21: =INDEX(C_Acq,A21) -> 0.429 | I21: =INDEX(C_Fee,A21) -> 0.1058 | J21: =INDEX(C_Loan,A21) -> 5.2 | K21: =G21-J21+H21+I21 -> 8.3348 | L21: =G21*(1+D21)^E21 -> 14.623232 | M21: =L21*LOOKUP(L21,FeeLo,FeeR)*(1+VAT) -> 0.096513331 | N21: =-CUMIPMT(Rm,LoanYears*12,J21,1,E21*12,0) -> 0.60765516 | O21: =J21*(1+Rm)^(E21*12)-(J21*Rm/(1-(1+Rm)^(-LoanYears*12)))*((1+Rm)^(E21*12)-1)/Rm -> 4.9139337 | P21: =SUMIFS(Sch_Total,Sch_Idx,A21,Sch_Scen,C21,Sch_Year,"<="&E21) -> 0.078253597 | Q21: =H21+I21+M21 -> 0.63131333 | R21: =L21-G21-Q21 -> 0.99191867 | S21: =MAX(0,IF(F21>=2,IF(L21>Exempt,R21*(L21-Exempt)/L21,0),R21)) -> 0.17793828 | T21: =IF(F21>=2,MIN(MaxDed,MIN(0.4,HoldRate*E21)+MIN(0.4,LiveRate*F21)),IF(E21>=3,MIN(0.3,0.02*E21),0)) -> 0.24 | U21: =S21*(1-T21) -> 0.1352331 | V21: =MAX(0,U21-InitDed) -> 0.1102331 | W21: =SUMPRODUCT((V21>CLo)*(V21-CLo)*CD)*(1+LocalTax) -> 0.0072753843 | X21: =H21+P21+W21 -> 0.51452898 | Y21: =(L21-G21)-H21-I21-M21-N21-P21-W21 -> 0.29873452 | Z21: =Y21/K21 -> 0.035841835 | AA21: =IF(1+Z21>0,(1+Z21)^(1/E21)-1,-1) -> 0.011807317 | AB21: =L21-O21-M21-W21 -> 9.6055096 | AC21: =AB21/K21 -> 1.1524583 | AD21: =K21*((1+DepRate*(1-DepTax))^E21-1) -> 0.65085438 | AE21: =Y21-AD21 -> -0.35211985
A22: 2 | B22: =INDEX(C_Name,A22) -> 신길삼성래미안 84㎡ | C22: 2 | D22: =CHOOSE(C22,G1,G2,G3) -> 0.04 | E22: 5 | F22: =MAX(0,E22-NonRes) -> 5 | G22: =INDEX(C_Price,A22) -> 13 | H22: =INDEX(C_Acq,A22) -> 0.429 | I22: =INDEX(C_Fee,A22) -> 0.1058 | J22: =INDEX(C_Loan,A22) -> 5.2 | K22: =G22-J22+H22+I22 -> 8.3348 | L22: =G22*(1+D22)^E22 -> 15.816488 | M22: =L22*LOOKUP(L22,FeeLo,FeeR)*(1+VAT) -> 0.12178696 | N22: =-CUMIPMT(Rm,LoanYears*12,J22,1,E22*12,0) -> 0.9928064 | O22: =J22*(1+Rm)^(E22*12)-(J22*Rm/(1-(1+Rm)^(-LoanYears*12)))*((1+Rm)^(E22*12)-1)/Rm -> 4.7032707 | P22: =SUMIFS(Sch_Total,Sch_Idx,A22,Sch_Scen,C22,Sch_Year,"<="&E22) -> 0.13970482 | Q22: =H22+I22+M22 -> 0.65658696 | R22: =L22-G22-Q22 -> 2.1599008 | S22: =MAX(0,IF(F22>=2,IF(L22>Exempt,R22*(L22-Exempt)/L22,0),R22)) -> 0.52117986 | T22: =IF(F22>=2,MIN(MaxDed,MIN(0.4,HoldRate*E22)+MIN(0.4,LiveRate*F22)),IF(E22>=3,MIN(0.3,0.02*E22),0)) -> 0.4 | U22: =S22*(1-T22) -> 0.31270791 | V22: =MAX(0,U22-InitDed) -> 0.28770791 | W22: =SUMPRODUCT((V22>CLo)*(V22-CLo)*CD)*(1+LocalTax) -> 0.033611806 | X22: =H22+P22+W22 -> 0.60231662 | Y22: =(L22-G22)-H22-I22-M22-N22-P22-W22 -> 0.99377775 | Z22: =Y22/K22 -> 0.11923234 | AA22: =IF(1+Z22>0,(1+Z22)^(1/E22)-1,-1) -> 0.022784294 | AB22: =L22-O22-M22-W22 -> 10.957818 | AC22: =AB22/K22 -> 1.3147068 | AD22: =K22*((1+DepRate*(1-DepTax))^E22-1) -> 1.1127543 | AE22: =Y22-AD22 -> -0.1189765
A23: 2 | B23: =INDEX(C_Name,A23) -> 신길삼성래미안 84㎡ | C23: 2 | D23: =CHOOSE(C23,G1,G2,G3) -> 0.04 | E23: 7 | F23: =MAX(0,E23-NonRes) -> 7 | G23: =INDEX(C_Price,A23) -> 13 | H23: =INDEX(C_Acq,A23) -> 0.429 | I23: =INDEX(C_Fee,A23) -> 0.1058 | J23: =INDEX(C_Loan,A23) -> 5.2 | K23: =G23-J23+H23+I23 -> 8.3348 | L23: =G23*(1+D23)^E23 -> 17.107113 | M23: =L23*LOOKUP(L23,FeeLo,FeeR)*(1+VAT) -> 0.13172477 | N23: =-CUMIPMT(Rm,LoanYears*12,J23,1,E23*12,0) -> 1.3604425 | O23: =J23*(1+Rm)^(E23*12)-(J23*Rm/(1-(1+Rm)^(-LoanYears*12)))*((1+Rm)^(E23*12)-1)/Rm -> 4.4750925 | P23: =SUMIFS(Sch_Total,Sch_Idx,A23,Sch_Scen,C23,Sch_Year,"<="&E23) -> 0.20740425 | Q23: =H23+I23+M23 -> 0.66652477 | R23: =L23-G23-Q23 -> 3.4405884 | S23: =MAX(0,IF(F23>=2,IF(L23>Exempt,R23*(L23-Exempt)/L23,0),R23)) -> 1.0271443 | T23: =IF(F23>=2,MIN(MaxDed,MIN(0.4,HoldRate*E23)+MIN(0.4,LiveRate*F23)),IF(E23>=3,MIN(0.3,0.02*E23),0)) -> 0.56 | U23: =S23*(1-T23) -> 0.4519435 | V23: =MAX(0,U23-InitDed) -> 0.4269435 | W23: =SUMPRODUCT((V23>CLo)*(V23-CLo)*CD)*(1+LocalTax) -> 0.056585677 | X23: =H23+P23+W23 -> 0.69298993 | Y23: =(L23-G23)-H23-I23-M23-N23-P23-W23 -> 1.8161559 | Z23: =Y23/K23 -> 0.21790036 | AA23: =IF(1+Z23>0,(1+Z23)^(1/E23)-1,-1) -> 0.028561469 | AB23: =L23-O23-M23-W23 -> 12.44371 | AC23: =AB23/K23 -> 1.4929825 | AD23: =K23*((1+DepRate*(1-DepTax))^E23-1) -> 1.5983977 | AE23: =Y23-AD23 -> 0.21775824
A24: 2 | B24: =INDEX(C_Name,A24) -> 신길삼성래미안 84㎡ | C24: 2 | D24: =CHOOSE(C24,G1,G2,G3) -> 0.04 | E24: 10 | F24: =MAX(0,E24-NonRes) -> 10 | G24: =INDEX(C_Price,A24) -> 13 | H24: =INDEX(C_Acq,A24) -> 0.429 | I24: =INDEX(C_Fee,A24) -> 0.1058 | J24: =INDEX(C_Loan,A24) -> 5.2 | K24: =G24-J24+H24+I24 -> 8.3348 | L24: =G24*(1+D24)^E24 -> 19.243176 | M24: =L24*LOOKUP(L24,FeeLo,FeeR)*(1+VAT) -> 0.14817245 | N24: =-CUMIPMT(Rm,LoanYears*12,J24,1,E24*12,0) -> 1.8758373 | O24: =J24*(1+Rm)^(E24*12)-(J24*Rm/(1-(1+Rm)^(-LoanYears*12)))*((1+Rm)^(E24*12)-1)/Rm -> 4.0967659 | P24: =SUMIFS(Sch_Total,Sch_Idx,A24,Sch_Scen,C24,Sch_Year,"<="&E24) -> 0.3255508 | Q24: =H24+I24+M24 -> 0.68297245 | R24: =L24-G24-Q24 -> 5.5602033 | S24: =MAX(0,IF(F24>=2,IF(L24>Exempt,R24*(L24-Exempt)/L24,0),R24)) -> 2.0928733 | T24: =IF(F24>=2,MIN(MaxDed,MIN(0.4,HoldRate*E24)+MIN(0.4,LiveRate*F24)),IF(E24>=3,MIN(0.3,0.02*E24),0)) -> 0.8 | U24: =S24*(1-T24) -> 0.41857466 | V24: =MAX(0,U24-InitDed) -> 0.39357466 | W24: =SUMPRODUCT((V24>CLo)*(V24-CLo)*CD)*(1+LocalTax) -> 0.05107982 | X24: =H24+P24+W24 -> 0.80563062 | Y24: =(L24-G24)-H24-I24-M24-N24-P24-W24 -> 3.3077353 | Z24: =Y24/K24 -> 0.39685839 | AA24: =IF(1+Z24>0,(1+Z24)^(1/E24)-1,-1) -> 0.03398738 | AB24: =L24-O24-M24-W24 -> 14.947158 | AC24: =AB24/K24 -> 1.7933433 | AD24: =K24*((1+DepRate*(1-DepTax))^E24-1) -> 2.374069 | AE24: =Y24-AD24 -> 0.93366631
A25: 2 | B25: =INDEX(C_Name,A25) -> 신길삼성래미안 84㎡ | C25: 3 | D25: =CHOOSE(C25,G1,G2,G3) -> 0.06 | E25: 3 | F25: =MAX(0,E25-NonRes) -> 3 | G25: =INDEX(C_Price,A25) -> 13 | H25: =INDEX(C_Acq,A25) -> 0.429 | I25: =INDEX(C_Fee,A25) -> 0.1058 | J25: =INDEX(C_Loan,A25) -> 5.2 | K25: =G25-J25+H25+I25 -> 8.3348 | L25: =G25*(1+D25)^E25 -> 15.483208 | M25: =L25*LOOKUP(L25,FeeLo,FeeR)*(1+VAT) -> 0.1192207 | N25: =-CUMIPMT(Rm,LoanYears*12,J25,1,E25*12,0) -> 0.60765516 | O25: =J25*(1+Rm)^(E25*12)-(J25*Rm/(1-(1+Rm)^(-LoanYears*12)))*((1+Rm)^(E25*12)-1)/Rm -> 4.9139337 | P25: =SUMIFS(Sch_Total,Sch_Idx,A25,Sch_Scen,C25,Sch_Year,"<="&E25) -> 0.080322438 | Q25: =H25+I25+M25 -> 0.6540207 | R25: =L25-G25-Q25 -> 1.8291873 | S25: =MAX(0,IF(F25>=2,IF(L25>Exempt,R25*(L25-Exempt)/L25,0),R25)) -> 0.41150644 | T25: =IF(F25>=2,MIN(MaxDed,MIN(0.4,HoldRate*E25)+MIN(0.4,LiveRate*F25)),IF(E25>=3,MIN(0.3,0.02*E25),0)) -> 0.24 | U25: =S25*(1-T25) -> 0.3127449 | V25: =MAX(0,U25-InitDed) -> 0.2877449 | W25: =SUMPRODUCT((V25>CLo)*(V25-CLo)*CD)*(1+LocalTax) -> 0.033617908 | X25: =H25+P25+W25 -> 0.54294035 | Y25: =(L25-G25)-H25-I25-M25-N25-P25-W25 -> 1.1075918 | Z25: =Y25/K25 -> 0.13288763 | AA25: =IF(1+Z25>0,(1+Z25)^(1/E25)-1,-1) -> 0.042466908 | AB25: =L25-O25-M25-W25 -> 10.416436 | AC25: =AB25/K25 -> 1.2497523 | AD25: =K25*((1+DepRate*(1-DepTax))^E25-1) -> 0.65085438 | AE25: =Y25-AD25 -> 0.45673741
A26: 2 | B26: =INDEX(C_Name,A26) -> 신길삼성래미안 84㎡ | C26: 3 | D26: =CHOOSE(C26,G1,G2,G3) -> 0.06 | E26: 5 | F26: =MAX(0,E26-NonRes) -> 5 | G26: =INDEX(C_Price,A26) -> 13 | H26: =INDEX(C_Acq,A26) -> 0.429 | I26: =INDEX(C_Fee,A26) -> 0.1058 | J26: =INDEX(C_Loan,A26) -> 5.2 | K26: =G26-J26+H26+I26 -> 8.3348 | L26: =G26*(1+D26)^E26 -> 17.396933 | M26: =L26*LOOKUP(L26,FeeLo,FeeR)*(1+VAT) -> 0.13395638 | N26: =-CUMIPMT(Rm,LoanYears*12,J26,1,E26*12,0) -> 0.9928064 | O26: =J26*(1+Rm)^(E26*12)-(J26*Rm/(1-(1+Rm)^(-LoanYears*12)))*((1+Rm)^(E26*12)-1)/Rm -> 4.7032707 | P26: =SUMIFS(Sch_Total,Sch_Idx,A26,Sch_Scen,C26,Sch_Year,"<="&E26) -> 0.14707157 | Q26: =H26+I26+M26 -> 0.66875638 | R26: =L26-G26-Q26 -> 3.7281761 | S26: =MAX(0,IF(F26>=2,IF(L26>Exempt,R26*(L26-Exempt)/L26,0),R26)) -> 1.1565668 | T26: =IF(F26>=2,MIN(MaxDed,MIN(0.4,HoldRate*E26)+MIN(0.4,LiveRate*F26)),IF(E26>=3,MIN(0.3,0.02*E26),0)) -> 0.4 | U26: =S26*(1-T26) -> 0.69394009 | V26: =MAX(0,U26-InitDed) -> 0.66894009 | W26: =SUMPRODUCT((V26>CLo)*(V26-CLo)*CD)*(1+LocalTax) -> 0.11324018 | X26: =H26+P26+W26 -> 0.68931176 | Y26: =(L26-G26)-H26-I26-M26-N26-P26-W26 -> 2.475058 | Z26: =Y26/K26 -> 0.29695469 | AA26: =IF(1+Z26>0,(1+Z26)^(1/E26)-1,-1) -> 0.053379739 | AB26: =L26-O26-M26-W26 -> 12.446465 | AC26: =AB26/K26 -> 1.493313 | AD26: =K26*((1+DepRate*(1-DepTax))^E26-1) -> 1.1127543 | AE26: =Y26-AD26 -> 1.3623037
A27: 2 | B27: =INDEX(C_Name,A27) -> 신길삼성래미안 84㎡ | C27: 3 | D27: =CHOOSE(C27,G1,G2,G3) -> 0.06 | E27: 7 | F27: =MAX(0,E27-NonRes) -> 7 | G27: =INDEX(C_Price,A27) -> 13 | H27: =INDEX(C_Acq,A27) -> 0.429 | I27: =INDEX(C_Fee,A27) -> 0.1058 | J27: =INDEX(C_Loan,A27) -> 5.2 | K27: =G27-J27+H27+I27 -> 8.3348 | L27: =G27*(1+D27)^E27 -> 19.547193 | M27: =L27*LOOKUP(L27,FeeLo,FeeR)*(1+VAT) -> 0.15051339 | N27: =-CUMIPMT(Rm,LoanYears*12,J27,1,E27*12,0) -> 1.3604425 | O27: =J27*(1+Rm)^(E27*12)-(J27*Rm/(1-(1+Rm)^(-LoanYears*12)))*((1+Rm)^(E27*12)-1)/Rm -> 4.4750925 | P27: =SUMIFS(Sch_Total,Sch_Idx,A27,Sch_Scen,C27,Sch_Year,"<="&E27) -> 0.22656053 | Q27: =H27+I27+M27 -> 0.68531339 | R27: =L27-G27-Q27 -> 5.86188 | S27: =MAX(0,IF(F27>=2,IF(L27>Exempt,R27*(L27-Exempt)/L27,0),R27)) -> 2.2632785 | T27: =IF(F27>=2,MIN(MaxDed,MIN(0.4,HoldRate*E27)+MIN(0.4,LiveRate*F27)),IF(E27>=3,MIN(0.3,0.02*E27),0)) -> 0.56 | U27: =S27*(1-T27) -> 0.99584252 | V27: =MAX(0,U27-InitDed) -> 0.97084252 | W27: =SUMPRODUCT((V27>CLo)*(V27-CLo)*CD)*(1+LocalTax) -> 0.20393437 | X27: =H27+P27+W27 -> 0.8594949 | Y27: =(L27-G27)-H27-I27-M27-N27-P27-W27 -> 4.0709426 | Z27: =Y27/K27 -> 0.48842715 | AA27: =IF(1+Z27>0,(1+Z27)^(1/E27)-1,-1) -> 0.058462239 | AB27: =L27-O27-M27-W27 -> 14.717653 | AC27: =AB27/K27 -> 1.7658076 | AD27: =K27*((1+DepRate*(1-DepTax))^E27-1) -> 1.5983977 | AE27: =Y27-AD27 -> 2.4725449
A28: 2 | B28: =INDEX(C_Name,A28) -> 신길삼성래미안 84㎡ | C28: 3 | D28: =CHOOSE(C28,G1,G2,G3) -> 0.06 | E28: 10 | F28: =MAX(0,E28-NonRes) -> 10 | G28: =INDEX(C_Price,A28) -> 13 | H28: =INDEX(C_Acq,A28) -> 0.429 | I28: =INDEX(C_Fee,A28) -> 0.1058 | J28: =INDEX(C_Loan,A28) -> 5.2 | K28: =G28-J28+H28+I28 -> 8.3348 | L28: =G28*(1+D28)^E28 -> 23.28102 | M28: =L28*LOOKUP(L28,FeeLo,FeeR)*(1+VAT) -> 0.17926385 | N28: =-CUMIPMT(Rm,LoanYears*12,J28,1,E28*12,0) -> 1.8758373 | O28: =J28*(1+Rm)^(E28*12)-(J28*Rm/(1-(1+Rm)^(-LoanYears*12)))*((1+Rm)^(E28*12)-1)/Rm -> 4.0967659 | P28: =SUMIFS(Sch_Total,Sch_Idx,A28,Sch_Scen,C28,Sch_Year,"<="&E28) -> 0.38859406 | Q28: =H28+I28+M28 -> 0.71406385 | R28: =L28-G28-Q28 -> 9.5669562 | S28: =MAX(0,IF(F28>=2,IF(L28>Exempt,R28*(L28-Exempt)/L28,0),R28)) -> 4.6357515 | T28: =IF(F28>=2,MIN(MaxDed,MIN(0.4,HoldRate*E28)+MIN(0.4,LiveRate*F28)),IF(E28>=3,MIN(0.3,0.02*E28),0)) -> 0.8 | U28: =S28*(1-T28) -> 0.92715031 | V28: =MAX(0,U28-InitDed) -> 0.90215031 | W28: =SUMPRODUCT((V28>CLo)*(V28-CLo)*CD)*(1+LocalTax) -> 0.17748787 | X28: =H28+P28+W28 -> 0.99508193 | Y28: =(L28-G28)-H28-I28-M28-N28-P28-W28 -> 7.1250369 | Z28: =Y28/K28 -> 0.85485398 | AA28: =IF(1+Z28>0,(1+Z28)^(1/E28)-1,-1) -> 0.063728934 | AB28: =L28-O28-M28-W28 -> 18.827502 | AC28: =AB28/K28 -> 2.2589027 | AD28: =K28*((1+DepRate*(1-DepTax))^E28-1) -> 2.374069 | AE28: =Y28-AD28 -> 4.7509679
A29: 3 | B29: =INDEX(C_Name,A29) -> 신길 래미안에스티움 84㎡ | C29: 1 | D29: =CHOOSE(C29,G1,G2,G3) -> 0.02 | E29: 3 | F29: =MAX(0,E29-NonRes) -> 3 | G29: =INDEX(C_Price,A29) -> 18.8 | H29: =INDEX(C_Acq,A29) -> 0.6204 | I29: =INDEX(C_Fee,A29) -> 0.16476 | J29: =INDEX(C_Loan,A29) -> 4 | K29: =G29-J29+H29+I29 -> 15.58516 | L29: =G29*(1+D29)^E29 -> 19.95071 | M29: =L29*LOOKUP(L29,FeeLo,FeeR)*(1+VAT) -> 0.15362047 | N29: =-CUMIPMT(Rm,LoanYears*12,J29,1,E29*12,0) -> 0.46742705 | O29: =J29*(1+Rm)^(E29*12)-(J29*Rm/(1-(1+Rm)^(-LoanYears*12)))*((1+Rm)^(E29*12)-1)/Rm -> 3.779949 | P29: =SUMIFS(Sch_Total,Sch_Idx,A29,Sch_Scen,C29,Sch_Year,"<="&E29) -> 0.1383204 | Q29: =H29+I29+M29 -> 0.93878047 | R29: =L29-G29-Q29 -> 0.21192993 | S29: =MAX(0,IF(F29>=2,IF(L29>Exempt,R29*(L29-Exempt)/L29,0),R29)) -> 0.08445782 | T29: =IF(F29>=2,MIN(MaxDed,MIN(0.4,HoldRate*E29)+MIN(0.4,LiveRate*F29)),IF(E29>=3,MIN(0.3,0.02*E29),0)) -> 0.24 | U29: =S29*(1-T29) -> 0.064187943 | V29: =MAX(0,U29-InitDed) -> 0.039187943 | W29: =SUMPRODUCT((V29>CLo)*(V29-CLo)*CD)*(1+LocalTax) -> 0.0025864042 | X29: =H29+P29+W29 -> 0.76130681 | Y29: =(L29-G29)-H29-I29-M29-N29-P29-W29 -> -0.39640393 | Z29: =Y29/K29 -> -0.025434704 | AA29: =IF(1+Z29>0,(1+Z29)^(1/E29)-1,-1) -> -0.0085511483 | AB29: =L29-O29-M29-W29 -> 16.014555 | AC29: =AB29/K29 -> 1.0275515 | AD29: =K29*((1+DepRate*(1-DepTax))^E29-1) -> 1.2170262 | AE29: =Y29-AD29 -> -1.6134301
A30: 3 | B30: =INDEX(C_Name,A30) -> 신길 래미안에스티움 84㎡ | C30: 1 | D30: =CHOOSE(C30,G1,G2,G3) -> 0.02 | E30: 5 | F30: =MAX(0,E30-NonRes) -> 5 | G30: =INDEX(C_Price,A30) -> 18.8 | H30: =INDEX(C_Acq,A30) -> 0.6204 | I30: =INDEX(C_Fee,A30) -> 0.16476 | J30: =INDEX(C_Loan,A30) -> 4 | K30: =G30-J30+H30+I30 -> 15.58516 | L30: =G30*(1+D30)^E30 -> 20.756719 | M30: =L30*LOOKUP(L30,FeeLo,FeeR)*(1+VAT) -> 0.15982674 | N30: =-CUMIPMT(Rm,LoanYears*12,J30,1,E30*12,0) -> 0.76369723 | O30: =J30*(1+Rm)^(E30*12)-(J30*Rm/(1-(1+Rm)^(-LoanYears*12)))*((1+Rm)^(E30*12)-1)/Rm -> 3.6179005 | P30: =SUMIFS(Sch_Total,Sch_Idx,A30,Sch_Scen,C30,Sch_Year,"<="&E30) -> 0.24034984 | Q30: =H30+I30+M30 -> 0.94498674 | R30: =L30-G30-Q30 -> 1.0117324 | S30: =MAX(0,IF(F30>=2,IF(L30>Exempt,R30*(L30-Exempt)/L30,0),R30)) -> 0.42682353 | T30: =IF(F30>=2,MIN(MaxDed,MIN(0.4,HoldRate*E30)+MIN(0.4,LiveRate*F30)),IF(E30>=3,MIN(0.3,0.02*E30),0)) -> 0.4 | U30: =S30*(1-T30) -> 0.25609412 | V30: =MAX(0,U30-InitDed) -> 0.23109412 | W30: =SUMPRODUCT((V30>CLo)*(V30-CLo)*CD)*(1+LocalTax) -> 0.024270529 | X30: =H30+P30+W30 -> 0.88502037 | Y30: =(L30-G30)-H30-I30-M30-N30-P30-W30 -> -0.016585242 | Z30: =Y30/K30 -> -0.0010641689 | AA30: =IF(1+Z30>0,(1+Z30)^(1/E30)-1,-1) -> -0.00021292443 | AB30: =L30-O30-M30-W30 -> 16.954721 | AC30: =AB30/K30 -> 1.087876 | AD30: =K30*((1+DepRate*(1-DepTax))^E30-1) -> 2.0807282 | AE30: =Y30-AD30 -> -2.0973134
A31: 3 | B31: =INDEX(C_Name,A31) -> 신길 래미안에스티움 84㎡ | C31: 1 | D31: =CHOOSE(C31,G1,G2,G3) -> 0.02 | E31: 7 | F31: =MAX(0,E31-NonRes) -> 7 | G31: =INDEX(C_Price,A31) -> 18.8 | H31: =INDEX(C_Acq,A31) -> 0.6204 | I31: =INDEX(C_Fee,A31) -> 0.16476 | J31: =INDEX(C_Loan,A31) -> 4 | K31: =G31-J31+H31+I31 -> 15.58516 | L31: =G31*(1+D31)^E31 -> 21.595291 | M31: =L31*LOOKUP(L31,FeeLo,FeeR)*(1+VAT) -> 0.16628374 | N31: =-CUMIPMT(Rm,LoanYears*12,J31,1,E31*12,0) -> 1.0464942 | O31: =J31*(1+Rm)^(E31*12)-(J31*Rm/(1-(1+Rm)^(-LoanYears*12)))*((1+Rm)^(E31*12)-1)/Rm -> 3.4423788 | P31: =SUMIFS(Sch_Total,Sch_Idx,A31,Sch_Scen,C31,Sch_Year,"<="&E31) -> 0.35060268 | Q31: =H31+I31+M31 -> 0.95144374 | R31: =L31-G31-Q31 -> 1.8438468 | S31: =MAX(0,IF(F31>=2,IF(L31>Exempt,R31*(L31-Exempt)/L31,0),R31)) -> 0.81926408 | T31: =IF(F31>=2,MIN(MaxDed,MIN(0.4,HoldRate*E31)+MIN(0.4,LiveRate*F31)),IF(E31>=3,MIN(0.3,0.02*E31),0)) -> 0.56 | U31: =S31*(1-T31) -> 0.3604762 | V31: =MAX(0,U31-InitDed) -> 0.3354762 | W31: =SUMPRODUCT((V31>CLo)*(V31-CLo)*CD)*(1+LocalTax) -> 0.041493572 | X31: =H31+P31+W31 -> 1.0124962 | Y31: =(L31-G31)-H31-I31-M31-N31-P31-W31 -> 0.40525634 | Z31: =Y31/K31 -> 0.026002706 | AA31: =IF(1+Z31>0,(1+Z31)^(1/E31)-1,-1) -> 0.0036739302 | AB31: =L31-O31-M31-W31 -> 17.945134 | AC31: =AB31/K31 -> 1.1514245 | AD31: =K31*((1+DepRate*(1-DepTax))^E31-1) -> 2.988828 | AE31: =Y31-AD31 -> -2.5835717
